Workbook

Sheet LSTK
A1: ORDER NO. | B1: SERIAL NO | C1: SIZE | D1: TYPE | E1: MAT NO. | F1: RECIVED | G1: FROM | H1: Origional MAT Level | I1: NEW TYPE | J1: STATUS | K1: FINAL | L1: Upper Section Replacement | M1: Build up | N1: Brazer | O1: Spinner | P1: Tip Grinding by | Q1: QC | R1: Thread Cleaning / Machining | S1: Body Cleaning / Machining | T1: Erosion sleeve | U1: Rework | V1: ACCOMPLISHED DATE | W1: REMARKS | X1: Job Name | Y1: Issues report | Z1: PDC Production Days | AA1: Lost Cutter | AB1: ITEM NUMBER | AC1: MJ # | AD1: Production Order Number | AE1: TRANSFER ORDER | AF1: Quotation | AG1: RAF
A2: 20161255 | C2: 6 1/8" | D2: FMD44 | E2: 702617 | J2: HOLD | V2: _ | W2: OLD MAT | AF2: =IFERROR(IF($AA$1<>0,IF($AA$1=VALUE(#REF!),AG2,""),""),"")
A3: 20171007 | B3: 12721812R2 | C3: 6 1/8" | D3: MMD63 | E3: 952071 | F3: 42737 | J3: Repair | V3: _ | W3: we changed the upper Section | AF3: =IFERROR(IF($AA$1<>0,IF($AA$1=VALUE(#REF!),AG3,""),""),"")
A4: 20171057 | B4: 12652742R | C4: 6 1/8" | D4: MMG64H | E4: 953042 | F4: 42757 | J4: HOLD | V4: _ | W4: 12665 $ | AF4: =IFERROR(IF($AA$1<>0,IF($AA$1=VALUE(#REF!),AG4,""),""),"")
A5: 20171089 | B5: 12679502R | C5: 6 1/8" | D5: MMG64H | E5: 953042 | J5: HOLD | V5: _ | W5: 13098 $ | AF5: =IFERROR(IF($AA$1<>0,IF($AA$1=VALUE(#REF!),AG5,""),""),"")
A6: 20171162 | B6: 12693583R1 | C6: 6 1/8" | D6: MME63 | E6: 965530 | F6: 42807 | J6: HOLD | V6: _ | W6: Thread and Blade damage. 13098 $ AND NEED RECLAIM CUTTERS [ 752294, 1010 CT82 .018 | AF6: =IFERROR(IF($AA$1<>0,IF($AA$1=VALUE(#REF!),AG6,""),""),"")
A7: 20171168 | B7: 12733371R2 | C7: 6 1/8" | D7: MMG64H | E7: 953042 | J7: HOLD | T7: =IFERROR(SMALL($AF$2:$AF$549,ROWS(L$2:$AF7)),"") | V7: _ | W7: Saved body | AF7: =IFERROR(IF($AA$1<>0,IF($AA$1=VALUE(#REF!),AG7,""),""),"")
A8: 20171170 | B8: 12694312R2 | C8: 6 1/8" | D8: MMG64H | E8: 953042 | J8: HOLD | T8: =IFERROR(SMALL($AF$2:$AF$549,ROWS(L$2:$AF8)),"") | V8: _ | W8: Saved body | AF8: =IFERROR(IF($AA$1<>0,IF($AA$1=VALUE(#REF!),AG8,""),""),"")
A9: 20171182 | B9: 12733370R1 | C9: 6 1/8" | D9: MMG64H | E9: 953042 | J9: HOLD | T9: =IFERROR(SMALL($AF$2:$AF$549,ROWS(L$2:$AF9)),"") | V9: _ | W9: Saved body | AF9: =IFERROR(IF($AA$1<>0,IF($AA$1=VALUE(#REF!),AG9,""),""),"")
A10: 20171462 | B10: 12877927 | C10: 12 1/4" | D10: MMD76H | E10: 952533 | F10: 43097 | J10: Repair | T10: =IFERROR(SMALL($AF$2:$AF$549,ROWS(L$2:$AF10)),"") | V10: _ | AF10: =IFERROR(IF($AA$1<>0,IF($AA$1=VALUE(#REF!),AG10,""),""),"")
A11: 20171464 | B11: 12847522 | C11: 6 1/8" | D11: MMD54H | E11: 986403 | F11: 43100 | J11: Repair | T11: =IFERROR(SMALL($AF$2:$AF$549,ROWS(L$2:$AF11)),"") | V11: _ | AF11: =IFERROR(IF($AA$1<>0,IF($AA$1=VALUE(#REF!),AG11,""),""),"")
A12: 20181003 | B12: 12529832R3 | C12: 8 1/2" | D12: MMD65H | E12: 791578 | F12: 43102 | J12: Repair | T12: =IFERROR(SMALL($AF$2:$AF$549,ROWS(L$2:$AF12)),"") | V12: _ | AF12: =IFERROR(IF($AA$1<>0,IF($AA$1=VALUE(#REF!),AG12,""),""),"")
A13: 20181007 | B13: 12924919R1 | C13: 8 1/2" | D13: MMD65H | E13: 1011366 | F13: 43108 | J13: Repair | T13: =IFERROR(SMALL($AF$2:$AF$549,ROWS(L$2:$AF13)),"") | V13: _ | W13: Cruzer | AF13: =IFERROR(IF($AA$1<>0,IF($AA$1=VALUE(#REF!),AG13,""),""),"")
A14: 20181012 | B14: 12680226R2 | C14: 6 1/8" | D14: MMD63 | E14: 952071 | F14: 43116 | J14: Repair | T14: =IFERROR(SMALL($AF$2:$AF$549,ROWS(L$2:$AF14)),"") | V14: _ | AF14: =IFERROR(IF($AA$1<>0,IF($AA$1=VALUE(#REF!),AG14,""),""),"")
A15: 20181013 | B15: 12800691R3 | C15: 6 1/8" | D15: MMD54H | E15: 986403 | F15: 43116 | J15: Repair | T15: =IFERROR(SMALL($AF$2:$AF$549,ROWS(L$2:$AF15)),"") | V15: _ | AF15: =IFERROR(IF($AA$1<>0,IF($AA$1=VALUE(#REF!),AG15,""),""),"")
A16: 20181014 | B16: 12847522R | C16: 6 1/8" | D16: MMD54H | E16: 986403 | F16: 43116 | J16: Repair | T16: =IFERROR(SMALL($AF$2:$AF$549,ROWS(L$2:$AF16)),"") | V16: _ | AF16: =IFERROR(IF($AA$1<>0,IF($AA$1=VALUE(#REF!),AG16,""),""),"")
A17: 20181018 | B17: 12529832R4 | C17: 8 1/2" | D17: MMD65H | E17: 791578 | F17: 43121 | J17: Repair | T17: =IFERROR(SMALL($AF$2:$AF$549,ROWS(L$2:$AF17)),"") | V17: _ | AF17: =IFERROR(IF($AA$1<>0,IF($AA$1=VALUE(#REF!),AG17,""),""),"")
A18: 20181019 | B18: 12652181R | C18: 12 1/4" | D18: MMD76H | E18: 952533 | F18: 43121 | J18: Repair | T18: =IFERROR(SMALL($AF$2:$AF$549,ROWS(L$2:$AF18)),"") | V18: _ | AF18: =IFERROR(IF($AA$1<>0,IF($AA$1=VALUE(#REF!),AG18,""),""),"")
A19: 20181025 | B19: 12847522R2 | C19: 6 1/8" | D19: MMD54H | E19: 986403 | F19: 43128 | J19: Repair | T19: =IFERROR(SMALL($AF$2:$AF$549,ROWS(L$2:$AF19)),"") | V19: _ | AF19: =IFERROR(IF($AA$1<>0,IF($AA$1=VALUE(#REF!),AG19,""),""),"")
A20: 20181029 | B20: 12667067R2 | C20: 6 1/8" | D20: MMG64H | E20: 953042 | F20: 43131 | J20: Repair | T20: =IFERROR(SMALL($AF$2:$AF$549,ROWS(L$2:$AF20)),"") | V20: _ | AF20: =IFERROR(IF($AA$1<>0,IF($AA$1=VALUE(#REF!),AG20,""),""),"")
A21: 20181034 | B21: 12584328R3 | C21: 6 1/8" | D21: MMD63 | E21: 859588 | F21: 43143 | J21: Repair | T21: =IFERROR(SMALL($AF$2:$AF$549,ROWS(L$2:$AF21)),"") | V21: _ | AF21: =IFERROR(IF($AA$1<>0,IF($AA$1=VALUE(#REF!),AG21,""),""),"")
A22: 20181037 | B22: 12800691R4 | C22: 6 1/8" | D22: MMD54H | E22: 986403M | F22: 43144 | J22: Repair | T22: =IFERROR(SMALL($AF$2:$AF$549,ROWS(L$2:$AF22)),"") | V22: _ | AF22: =IFERROR(IF($AA$1<>0,IF($AA$1=VALUE(#REF!),AG22,""),""),"")
A23: 20181039 | B23: 12667067R3 | C23: 6 1/8" | D23: MMG64H | E23: 953042 | F23: 43147 | J23: Repair | T23: =IFERROR(SMALL($AF$2:$AF$549,ROWS(L$2:$AF23)),"") | V23: _ | AF23: =IFERROR(IF($AA$1<>0,IF($AA$1=VALUE(#REF!),AG23,""),""),"")
A24: 20181040 | B24: 12847522R3 | C24: 6 1/8" | D24: MMD54H | E24: 986403 | F24: 43147 | J24: Repair | T24: =IFERROR(SMALL($AF$2:$AF$549,ROWS(L$2:$AF24)),"") | V24: _ | AF24: =IFERROR(IF($AA$1<>0,IF($AA$1=VALUE(#REF!),AG24,""),""),"")
A25: 20181042 | B25: 12877927R | C25: 12 1/4" | D25: MMD76H | E25: 952533 | F25: 43144 | J25: HOLD | T25: =IFERROR(SMALL($AF$2:$AF$549,ROWS(L$2:$AF25)),"") | V25: _ | W25: Saved body | AF25: =IFERROR(IF($AA$1<>0,IF($AA$1=VALUE(#REF!),AG25,""),""),"")
A26: 20181045 | B26: 12652181R2 | C26: 12 1/4" | D26: MMD76H | E26: 952533M | F26: 43150 | J26: HOLD | T26: =IFERROR(SMALL($AF$2:$AF$549,ROWS(L$2:$AF26)),"") | V26: _ | AF26: =IFERROR(IF($AA$1<>0,IF($AA$1=VALUE(#REF!),AG26,""),""),"")
A27: 20181047 | B27: 12847523 | C27: 6 1/8" | D27: MMD54H | E27: 986403 | F27: 43151 | J27: Repair | V27: _ | AF27: =IFERROR(IF($AA$1<>0,IF($AA$1=VALUE(#REF!),AG27,""),""),"")
A28: 20181050 | B28: 12529832R5 | C28: 8 1/2" | D28: MMD65H | E28: 791578 | F28: 43156 | J28: Repair | V28: _ | AF28: =IFERROR(IF($AA$1<>0,IF($AA$1=VALUE(#REF!),AG28,""),""),"")
A29: 20181052 | B29: 12934734 | C29: 3 7/8" | D29: SF53 | E29: 1025815 | F29: 43157 | J29: Repair | V29: _ | AF29: =IFERROR(IF($AA$1<>0,IF($AA$1=VALUE(#REF!),AG29,""),""),"")
A30: 20181054 | B30: 12762915R2 | C30: 12 1/4" | D30: SFD66CH | E30: 870474 | F30: 43158 | J30: HOLD | V30: _ | AF30: =IFERROR(IF($AA$1<>0,IF($AA$1=VALUE(#REF!),AG30,""),""),"")
A31: 20181056 | B31: 13010775 | C31: 12 1/4" | D31: MMD76H | E31: 952533M | F31: 43164 | J31: Repair | V31: _ | W31: Thread Damage [ unaccepetale ] replace the uper section( After cleaned, abdul decided to accept ) . IA build up [ B1( I5), B2 (I5), B3 (I7),B5 (I8),B6 (I5), B7 (I4)]. Reclaim cutters [ 12 cutters 1913 ,0.010'] &[ 5 cutters 1913, 0.018] . [ 8 cutters new cutters 1913, 0.010' ] | AF31: =IFERROR(IF($AA$1<>0,IF($AA$1=VALUE(#REF!),AG31,""),""),"")
A32: 20181057 | B32: 12978769 | C32: 6 1/8" | D32: MMD64H | E32: 1032847 | F32: 43165 | J32: Repair | V32: _ | AF32: =IFERROR(IF($AA$1<>0,IF($AA$1=VALUE(#REF!),AG32,""),""),"")
A33: 20181060 | B33: 12800691R5 | C33: 6 1/8" | D33: MMD54H | E33: 986403M | F33: 3/11/2018 | J33: Repair | V33: _ | AF33: =IFERROR(IF($AA$1<>0,IF($AA$1=VALUE(#REF!),AG33,""),""),"")
A34: 20181065 | B34: 12680225R2 | C34: 6 1/8" | D34: MMD63 | E34: 952071 | F34: 43173 | J34: Repair | V34: _ | AF34: =IFERROR(IF($AA$1<>0,IF($AA$1=VALUE(#REF!),AG34,""),""),"")
A35: 20181068 | B35: 12978769R1 | C35: 6 1/8" | D35: MMD64H | E35: 1032847 | F35: 43177 | J35: Repair | V35: _ | AF35: =IFERROR(IF($AA$1<>0,IF($AA$1=VALUE(#REF!),AG35,""),""),"")
A36: 20181069 | B36: 12584328R4 | C36: 6 1/8" | D36: MMD63 | E36: 859588 | F36: 43177 | J36: Repair | V36: _ | W36: Not approved | AF36: =IFERROR(IF($AA$1<>0,IF($AA$1=VALUE(#REF!),AG36,""),""),"")
A37: 20181071 | B37: 12934734R | C37: 3 7/8" | D37: SF53 | E37: 1025815 | F37: 43179 | J37: Repair | V37: _ | AF37: =IFERROR(IF($AA$1<>0,IF($AA$1=VALUE(#REF!),AG37,""),""),"")
A38: 20181075 | B38: 13010775R1 | C38: 12 1/4" | D38: MMD76H | E38: 952533M | F38: 43188 | J38: Repair | V38: _ | W38: Mixed cutters. | AF38: =IFERROR(IF($AA$1<>0,IF($AA$1=VALUE(#REF!),AG38,""),""),"")
A39: 20181077 | B39: 11848664R2 | C39: 8 1/2" | D39: FXD65 | E39: 639070 | F39: 43192 | J39: Repair | V39: _ | AF39: =IFERROR(IF($AA$1<>0,IF($AA$1=VALUE(#REF!),AG39,""),""),"")
A40: 20181078 | B40: 12847523R | C40: 6 1/8" | D40: MMD54H | E40: 986403 | F40: 43192 | J40: Repair | V40: _ | AF40: =IFERROR(IF($AA$1<>0,IF($AA$1=VALUE(#REF!),AG40,""),""),"")
...

Sheet UR
A1: ORDER NO. | B1: SERIAL NO | C1: SIZE | D1: TYPE | E1: MAT NO. | F1: RECIVED | G1: FROM | H1: Origional MAT Level | I1: NEW TYPE | J1: STATUS | K1: FINAL | L1: Upper Section Replacement | M1: Build up | N1: Brazer | O1: Spinner | P1: Tip Grinding by | Q1: QC | R1: Thread Cleaning / Machining | S1: Body Cleaning / Machining | T1: Erosion sleeve | U1: Rework | V1: ACCOMPLISHED DATE | W1: REMARKS | X1: Job Name | Y1: Issues report | Z1: PDC Production Days | AA1: Lost Cutter | AB1: ITEM NUMBER | AC1: MJ # | AD1: Production Order Number | AE1: Quotation | AF1: RAF
A2: 2024-UR-1001 | B2: 14144633 | C2: 8 1/2" | D2: GT65RHs | E2: 1267829 | F2: 45551 | G2: UR | J2: Repair | K2: 610 | X2: =A2&"-"&B2 -> 2024-UR-1001-14144633 | Z2: =IF(AND(ISBLANK(F2), ISBLANK(V2)), "", NETWORKDAYS.INTL(F2, IF(V2="", TODAY(), V2), "0000110", DATA!$B$2:$B$200)) -> 349
A3: 2024-UR-1002 | B3: 14211929 | C3: 8 1/2" | D3: GT65RHs-1 | E3: 1276939 | F3: 45566 | G3: UR | J3: Repair | K3: 868.47 | V3: 45568 | X3: =A3&"-"&B3 -> 2024-UR-1002-14211929 | Z3: =IF(AND(ISBLANK(F3), ISBLANK(V3)), "", NETWORKDAYS.INTL(F3, IF(V3="", TODAY(), V3), "0000110", DATA!$B$2:$B$200)) -> 3
A4: 2024-UR-1003 | B4: 14228470 | C4: 8 1/2" | D4: GT65RHs-1 | E4: 1276939 | F4: 45566 | G4: UR | J4: Repair | K4: 703.45 | V4: 45568 | X4: =A4&"-"&B4 -> 2024-UR-1003-14228470 | Z4: =IF(AND(ISBLANK(F4), ISBLANK(V4)), "", NETWORKDAYS.INTL(F4, IF(V4="", TODAY(), V4), "0000110", DATA!$B$2:$B$200)) -> 3
A5: 2024-UR-1004 | B5: 14199937 | C5: 8 1/2" | D5: GT65RHs-1 | E5: 1276939 | F5: 45566 | G5: UR | J5: Repair | K5: 1273 | V5: 45574 | X5: =A5&"-"&B5 -> 2024-UR-1004-14199937 | Z5: =IF(AND(ISBLANK(F5), ISBLANK(V5)), "", NETWORKDAYS.INTL(F5, IF(V5="", TODAY(), V5), "0000110", DATA!$B$2:$B$200)) -> 7
A6: 2024-UR-1005 | B6: 14199925 | C6: 8 1/2'' | D6: HD65D | E6: 1254762 | F6: 45572 | G6: UR | J6: Repair | K6: 1713 | V6: 45575 | X6: =A6&"-"&B6 -> 2024-UR-1005-14199925 | Z6: =IF(AND(ISBLANK(F6), ISBLANK(V6)), "", NETWORKDAYS.INTL(F6, IF(V6="", TODAY(), V6), "0000110", DATA!$B$2:$B$200)) -> 4
A7: 2024-UR-1006 | B7: 14144633R1 | C7: 8 1/2" | D7: GT65RHs | E7: 1267829 | F7: 45574 | G7: UR | J7: Scrap | V7: =F7 -> 45574 | W7: Jabbar mail on Tue 10/15/2024 (Pin face erosion) | X7: =A7&"-"&B7 -> 2024-UR-1006-14144633R1 | Z7: =IF(AND(ISBLANK(F7), ISBLANK(V7)), "", NETWORKDAYS.INTL(F7, IF(V7="", TODAY(), V7), "0000110", DATA!$B$2:$B$200)) -> 1
A8: 2024-UR-1007 | B8: 13896633 | C8: 8 1/2" | D8: HD65O | E8: 1240803M | F8: 45575 | G8: UR | J8: Repair | K8: 2527 | W8: Shifted from ARDT to UR | X8: =A8&"-"&B8 -> 2024-UR-1007-13896633 | Z8: =IF(AND(ISBLANK(F8), ISBLANK(V8)), "", NETWORKDAYS.INTL(F8, IF(V8="", TODAY(), V8), "0000110", DATA!$B$2:$B$200)) -> 331
A9: 2024-UR-1008 | B9: 14228471 | C9: 8 1/2'' | D9: GT65RHs-1 | E9: 1276939 | F9: 45585 | G9: UR | J9: Repair | K9: 1362 | V9: 45592 | X9: =A9&"-"&B9 -> 2024-UR-1008-14228471 | Z9: =IF(AND(ISBLANK(F9), ISBLANK(V9)), "", NETWORKDAYS.INTL(F9, IF(V9="", TODAY(), V9), "0000110", DATA!$B$2:$B$200)) -> 6
A10: 2024-UR-1009 | B10: 14199925R1 | C10: 8 1/2'' | D10: HD65D | E10: 1254762 | F10: 45588 | G10: UR | J10: Repair | K10: 842 | V10: 45594 | X10: =A10&"-"&B10 -> 2024-UR-1009-14199925R1 | Z10: =IF(AND(ISBLANK(F10), ISBLANK(V10)), "", NETWORKDAYS.INTL(F10, IF(V10="", TODAY(), V10), "0000110", DATA!$B$2:$B$200)) -> 5
A11: 2024-UR-1010 | B11: 14247230 | C11: 8 1/2'' | D11: GT65RHs | E11: 1276939 | F11: 45592 | G11: UR | J11: Repair | K11: 727 | V11: 45596 | X11: =A11&"-"&B11 -> 2024-UR-1010-14247230 | Z11: =IF(AND(ISBLANK(F11), ISBLANK(V11)), "", NETWORKDAYS.INTL(F11, IF(V11="", TODAY(), V11), "0000110", DATA!$B$2:$B$200)) -> 5
A12: 2024-UR-1011 | B12: 13994928 | C12: 8.5 | D12: HD65O | E12: 1255267M | F12: 45595 | G12: UR | J12: Repair | K12: 4965 | V12: 45635 | X12: =A12&"-"&B12 -> 2024-UR-1011-13994928 | Z12: =IF(AND(ISBLANK(F12), ISBLANK(V12)), "", NETWORKDAYS.INTL(F12, IF(V12="", TODAY(), V12), "0000110", DATA!$B$2:$B$200)) -> 29
A13: 2024-UR-1012 | B13: 14228472 | C13: 8.5 | D13: GT65RHs-1 | E13: 1276939 | F13: 45599 | G13: UR | J13: Scrap | V13: =F13 -> 45599 | W13: As per Murtadha_11/04/2024_Rin out | X13: =A13&"-"&B13 -> 2024-UR-1012-14228472 | Z13: =IF(AND(ISBLANK(F13), ISBLANK(V13)), "", NETWORKDAYS.INTL(F13, IF(V13="", TODAY(), V13), "0000110", DATA!$B$2:$B$200)) -> 1
A14: 2024-UR-1013 | B14: 14247229 | C14: 8.5 | D14: GT65RHs-1 | E14: 1276939 | F14: 45600 | G14: UR | J14: Repair | K14: 523 | V14: 45607 | X14: =A14&"-"&B14 -> 2024-UR-1013-14247229 | Z14: =IF(AND(ISBLANK(F14), ISBLANK(V14)), "", NETWORKDAYS.INTL(F14, IF(V14="", TODAY(), V14), "0000110", DATA!$B$2:$B$200)) -> 6
A15: 2024-UR-1014 | B15: 14137157 | C15: 8.5 | D15: GT65RHs | E15: 1267829 | F15: 45600 | G15: UR | J15: Repair | K15: 950 | V15: 45607 | X15: =A15&"-"&B15 -> 2024-UR-1014-14137157 | Z15: =IF(AND(ISBLANK(F15), ISBLANK(V15)), "", NETWORKDAYS.INTL(F15, IF(V15="", TODAY(), V15), "0000110", DATA!$B$2:$B$200)) -> 6
A16: 2024-UR-1015 | B16: 14211929R1 | C16: 8 1/2" | D16: GT65RHs-1 | E16: 1276939 | F16: 45607 | G16: UR | J16: Repair | K16: 2258 | V16: 45614 | X16: =A16&"-"&B16 -> 2024-UR-1015-14211929R1 | Z16: =IF(AND(ISBLANK(F16), ISBLANK(V16)), "", NETWORKDAYS.INTL(F16, IF(V16="", TODAY(), V16), "0000110", DATA!$B$2:$B$200)) -> 6
A17: 2024-UR-1016 | B17: 14247230R1 | C17: 8 1/2'' | D17: GT65RHs-1 | E17: 1276939 | F17: 45615 | G17: UR | J17: Repair | K17: 749 | V17: 45623 | X17: =A17&"-"&B17 -> 2024-UR-1016-14247230R1 | Z17: =IF(AND(ISBLANK(F17), ISBLANK(V17)), "", NETWORKDAYS.INTL(F17, IF(V17="", TODAY(), V17), "0000110", DATA!$B$2:$B$200)) -> 7
A18: 2024-UR-1017 | B18: 14247229R1 | C18: 8.5 | D18: GT65RHs-1 | E18: 1276939 | F18: 45618 | G18: UR | J18: Repair | K18: 2239 | V18: 45629 | X18: =A18&"-"&B18 -> 2024-UR-1017-14247229R1 | Z18: =IF(AND(ISBLANK(F18), ISBLANK(V18)), "", NETWORKDAYS.INTL(F18, IF(V18="", TODAY(), V18), "0000110", DATA!$B$2:$B$200)) -> 8
A19: 2024-UR-1018 | B19: 14228471R1 | C19: 8 1/2'' | D19: GT65RHs-1 | E19: 1276939 | F19: 45618 | G19: UR | J19: Repair | K19: 1852 | V19: 45631 | X19: =A19&"-"&B19 -> 2024-UR-1018-14228471R1 | Z19: =IF(AND(ISBLANK(F19), ISBLANK(V19)), "", NETWORKDAYS.INTL(F19, IF(V19="", TODAY(), V19), "0000110", DATA!$B$2:$B$200)) -> 10
A20: 2024-UR-1019 | B20: 14228470R1 | C20: 8 1/2" | D20: GT65RHs-1 | E20: 1276939 | F20: 45623 | G20: UR | J20: Repair | K20: 2159 | V20: 45631 | X20: =A20&"-"&B20 -> 2024-UR-1019-14228470R1 | Z20: =IF(AND(ISBLANK(F20), ISBLANK(V20)), "", NETWORKDAYS.INTL(F20, IF(V20="", TODAY(), V20), "0000110", DATA!$B$2:$B$200)) -> 7
A21: 2024-UR-1020 | B21: 14137157R1 | C21: 8.5 | D21: GT65RHs | E21: 1267829 | F21: 45627 | G21: UR | J21: Repair | K21: 2495 | V21: 45637 | X21: =A21&"-"&B21 -> 2024-UR-1020-14137157R1 | Z21: =IF(AND(ISBLANK(F21), ISBLANK(V21)), "", NETWORKDAYS.INTL(F21, IF(V21="", TODAY(), V21), "0000110", DATA!$B$2:$B$200)) -> 9
A22: 2024-UR-1021 | B22: 14144629 | C22: 8.5 | D22: GT65RHs | E22: 1267829 | F22: 45632 | G22: UR | J22: Repair | K22: 663 | V22: 45637 | X22: =A22&"-"&B22 -> 2024-UR-1021-14144629 | Z22: =IF(AND(ISBLANK(F22), ISBLANK(V22)), "", NETWORKDAYS.INTL(F22, IF(V22="", TODAY(), V22), "0000110", DATA!$B$2:$B$200)) -> 4
A23: 2024-UR-1022 | B23: 14211929R2 | C23: 8 1/2" | D23: GT65RHs-1 | E23: 1276939 | F23: 45632 | G23: UR | J23: Scrap | V23: =F23 -> 45632 | W23: As per (Jabbar email) 12/9/2024_Junk Slot Cracks | X23: =A23&"-"&B23 -> 2024-UR-1022-14211929R2 | Z23: =IF(AND(ISBLANK(F23), ISBLANK(V23)), "", NETWORKDAYS.INTL(F23, IF(V23="", TODAY(), V23), "0000110", DATA!$B$2:$B$200)) -> 0
A24: 2024-UR-1023 | B24: 14247230R2 | C24: 8 1/2'' | D24: GT65RHs-1 | E24: 1276939 | F24: 45642 | G24: UR | J24: Repair | K24: 1314 | V24: 45646 | X24: =A24&"-"&B24 -> 2024-UR-1023-14247230R2 | Z24: =IF(AND(ISBLANK(F24), ISBLANK(V24)), "", NETWORKDAYS.INTL(F24, IF(V24="", TODAY(), V24), "0000110", DATA!$B$2:$B$200)) -> 4
A25: 2024-UR-1024 | B25: 14228470R2 | C25: 8 1/2" | D25: GT65RHs-1 | E25: 1276939 | F25: 45642 | G25: UR | J25: Repair | K25: 3160 | V25: 45646 | X25: =A25&"-"&B25 -> 2024-UR-1024-14228470R2 | Z25: =IF(AND(ISBLANK(F25), ISBLANK(V25)), "", NETWORKDAYS.INTL(F25, IF(V25="", TODAY(), V25), "0000110", DATA!$B$2:$B$200)) -> 4
A26: 2024-UR-1025 | B26: 14228471R2 | C26: 8 1/2'' | D26: GT65RHs-1 | E26: 1276939 | F26: 45652 | G26: UR | J26: Repair | K26: 1037 | V26: 45656 | X26: =A26&"-"&B26 -> 2024-UR-1025-14228471R2 | Z26: =IF(AND(ISBLANK(F26), ISBLANK(V26)), "", NETWORKDAYS.INTL(F26, IF(V26="", TODAY(), V26), "0000110", DATA!$B$2:$B$200)) -> 3
A27: 2024-UR-1026 | B27: 14247229R2 | C27: 8 1/2'' | D27: GT65RHs-1 | E27: 1276939 | F27: 45652 | G27: UR | J27: Repair | K27: 1311 | V27: 45657 | X27: =A27&"-"&B27 -> 2024-UR-1026-14247229R2 | Z27: =IF(AND(ISBLANK(F27), ISBLANK(V27)), "", NETWORKDAYS.INTL(F27, IF(V27="", TODAY(), V27), "0000110", DATA!$B$2:$B$200)) -> 4
A28: 2024-UR-1027 | B28: 14199937R1 | C28: 8 1/2" | D28: GT65RHs-1 | E28: 1276939 | F28: 45655 | G28: UR | J28: Repair | K28: 1749 | N28: Showaiki | O28: Redwan | V28: 45659 | X28: =A28&"-"&B28 -> 2024-UR-1027-14199937R1 | Z28: =IF(AND(ISBLANK(F28), ISBLANK(V28)), "", NETWORKDAYS.INTL(F28, IF(V28="", TODAY(), V28), "0000110", DATA!$B$2:$B$200)) -> 5
A29: 2025-UR-1001 | B29: 14160196 | C29: 8 1/2" | D29: HD65O | E29: 1255267M | F29: 45663 | G29: UR | J29: Repair | K29: 604 | N29: Showaiki | O29: Wasmi | V29: 45665 | X29: =A29&"-"&B29 -> 2025-UR-1001-14160196 | Z29: =IF(AND(ISBLANK(F29), ISBLANK(V29)), "", NETWORKDAYS.INTL(F29, IF(V29="", TODAY(), V29), "0000110", DATA!$B$2:$B$200)) -> 3
A30: 2025-UR-1002 | B30: 14247230R3 | C30: 8 1/2" | D30: GT65RHs-1 | E30: 1276939 | F30: 45663 | G30: UR | J30: Repair | K30: 2698 | N30: Showaiki | O30: Wasmi | U30: RP 2025-005 & RP 2025-006 _ Rework | V30: 45676 | W30: Pockets Build up. Rework | X30: =A30&"-"&B30 -> 2025-UR-1002-14247230R3 | Z30: =IF(AND(ISBLANK(F30), ISBLANK(V30)), "", NETWORKDAYS.INTL(F30, IF(V30="", TODAY(), V30), "0000110", DATA!$B$2:$B$200)) -> 10
A31: 2025-UR-1003 | B31: 14199937R2 | C31: 8 1/2" | D31: GT65RHs-1 | E31: 1276939 | F31: 45676 | G31: UR | J31: Repair | K31: 1558 | N31: Showaiki | O31: Mohana | V31: 45679 | X31: =A31&"-"&B31 -> 2025-UR-1003-14199937R2 | Z31: =IF(AND(ISBLANK(F31), ISBLANK(V31)), "", NETWORKDAYS.INTL(F31, IF(V31="", TODAY(), V31), "0000110", DATA!$B$2:$B$200)) -> 4
A32: 2025-UR-1004 | B32: 14247229R3 | C32: 8 1/2" | D32: GT65RHs-1 | E32: 1276939 | F32: 45678 | G32: UR | J32: Repair | K32: 1805 | N32: Showaiki | O32: Mohana | U32: RP-2025-007 _ Rework | V32: 45685 | W32: Pockets Build up. Rework | X32: =A32&"-"&B32 -> 2025-UR-1004-14247229R3 | Z32: =IF(AND(ISBLANK(F32), ISBLANK(V32)), "", NETWORKDAYS.INTL(F32, IF(V32="", TODAY(), V32), "0000110", DATA!$B$2:$B$200)) -> 6
A33: 2025-UR-1005 | B33: 14144629R1 | C33: 8 1/2" | D33: GT65RHs | E33: 1267829 | F33: 45678 | G33: UR | J33: Repair | K33: 1621 | N33: Showaiki | O33: Mohana | V33: 45684 | X33: =A33&"-"&B33 -> 2025-UR-1005-14144629R1 | Z33: =IF(AND(ISBLANK(F33), ISBLANK(V33)), "", NETWORKDAYS.INTL(F33, IF(V33="", TODAY(), V33), "0000110", DATA!$B$2:$B$200)) -> 5
A34: 2025-UR-1006 | B34: 14254502 | C34: 8 1/2" | D34: GT65RHS-1 | E34: 1276939M1 | F34: 45679 | G34: UR | J34: Repair | K34: 1642 | N34: Showaiki | O34: Mohana | V34: 45686 | W34: Pockets Build up | X34: =A34&"-"&B34 -> 2025-UR-1006-14254502 | Z34: =IF(AND(ISBLANK(F34), ISBLANK(V34)), "", NETWORKDAYS.INTL(F34, IF(V34="", TODAY(), V34), "0000110", DATA!$B$2:$B$200)) -> 6
A35: 2025-UR-1007 | B35: 14228470R3 | C35: 8 1/2" | D35: GT65RHs-1 | E35: 1276939 | F35: 45679 | G35: UR | J35: Repair | K35: 2536 | N35: Showaiki | O35: Mohana | U35: RP-2025-012 & RP-2025-014 _ Rework | V35: 45697 | W35: Pockets Build up. Rework | X35: =A35&"-"&B35 -> 2025-UR-1007-14228470R3 | Z35: =IF(AND(ISBLANK(F35), ISBLANK(V35)), "", NETWORKDAYS.INTL(F35, IF(V35="", TODAY(), V35), "0000110", DATA!$B$2:$B$200)) -> 13
A36: 2025-UR-1008 | B36: 14254498 | C36: 8 1/2" | D36: GT65RHS-1 | E36: 1276939M1 | F36: 45683 | G36: UR | J36: Repair | K36: 3599 | N36: Showaiki | O36: Mohana | U36: RP-2025-010 | V36: 45690 | W36: Pockets Build up | X36: =A36&"-"&B36 -> 2025-UR-1008-14254498 | Z36: =IF(AND(ISBLANK(F36), ISBLANK(V36)), "", NETWORKDAYS.INTL(F36, IF(V36="", TODAY(), V36), "0000110", DATA!$B$2:$B$200)) -> 6
A37: 2025-UR-1009 | B37: 14204332 | C37: 8 1/2" | D37: GT65RHs | E37: 1267829 | F37: 45683 | G37: UR | J37: Repair | K37: 2536 | N37: Showaiki | O37: Mohana | U37: Rework | V37: 45690 | W37: Pockets Build up. Rework | X37: =A37&"-"&B37 -> 2025-UR-1009-14204332 | Z37: =IF(AND(ISBLANK(F37), ISBLANK(V37)), "", NETWORKDAYS.INTL(F37, IF(V37="", TODAY(), V37), "0000110", DATA!$B$2:$B$200)) -> 6
A38: 2025-UR-1010 | B38: 14228471R3 | C38: 8 1/2'' | D38: GT65RHs-1 | E38: 1276939 | F38: 45686 | G38: UR | J38: Repair | K38: 2372 | N38: Showaiki | O38: Mohana | U38: RP-2025-013 & RP-2025-015 | V38: 45700 | W38: Pockets Build up | X38: =A38&"-"&B38 -> 2025-UR-1010-14228471R3 | Z38: =IF(AND(ISBLANK(F38), ISBLANK(V38)), "", NETWORKDAYS.INTL(F38, IF(V38="", TODAY(), V38), "0000110", DATA!$B$2:$B$200)) -> 11
A39: 2025-UR-1011 | B39: 14190171 | C39: 8.5 | D39: GT65RHS-1 | E39: 1276939 | F39: 45690 | G39: UR | J39: Repair | K39: 1684 | N39: Wasmi | O39: Mohana | U39: RP 2025-009 | V39: 45694 | W39: Pockets Build up | X39: =A39&"-"&B39 -> 2025-UR-1011-14190171 | Z39: =IF(AND(ISBLANK(F39), ISBLANK(V39)), "", NETWORKDAYS.INTL(F39, IF(V39="", TODAY(), V39), "0000110", DATA!$B$2:$B$200)) -> 5
A40: 2025-UR-1012 | B40: 14247230R4 | C40: 8 1/2" | D40: GT65RHs-1 | E40: 1276939 | F40: 45690 | G40: UR | J40: Repair | K40: 2240 | N40: Wasmi | O40: Mohana | U40: RP-2025-016 _ Rework | V40: 45700 | W40: Pockets Build up. Rework | X40: =A40&"-"&B40 -> 2025-UR-1012-14247230R4 | Z40: =IF(AND(ISBLANK(F40), ISBLANK(V40)), "", NETWORKDAYS.INTL(F40, IF(V40="", TODAY(), V40), "0000110", DATA!$B$2:$B$200)) -> 9
...

Sheet WIP
A1: ORDER NO. | B1: SEREAL NO. | C1: SIZE | D1: TYPE | E1: LV5 MAT NO. | F1: RECIVED | G1: FROM | H1: STATUS | I1: Build Up | J1: Pocket Grinding | K1: Braze | L1: Final grinding | M1: Tip Grinding | N1: 1st check | O1: Rework | P1: Thread Cleaning / Machining | Q1: Body Cleaning / Machining | R1: USR | S1: Final Inspection | T1: Remarks | U1: Acomplish | V1: Inspection Group
A2: 20261002 | B2: 14273126R2 | C2: 3.875 | D2: SF53 | E2: 1252149 | F2: 46023 | G2: LSTK | I2: - | J2: - | K2: 46031 | L2: Needed
A3: 20261003 | B3: 14254494R3 | C3: 6.125 | D3: HD54 | E3: 1251085M2 | F3: 45911 | G3: LSTK
A4: 20261004 | B4: 14304769R1 | C4: 6.125 | D4: HD54 | E4: 1251085M2 | F4: 45980 | G4: LSTK | K4: 46043
A5: 20261005 | B5: 14320851R4 | C5: 3.875 | D5: SF53 | E5: 1252149 | F5: 45858 | G5: LSTK
A6: 20261006 | B6: 14304771R2 | C6: 6.125 | D6: HD54X | E6: 1137349 | F6: 46035 | G6: LSTK
A7: 2025-AR-063 | B7: 13670338 | C7: 16" | D7: MM85DH | E7: 1033011 | I7: Done | J7: - | K7: 46032 | T7: Scrap- Reclaim | U7: 46036 | V7: 2025-01
A8: 2025-AR-064 | B8: 13670127 | C8: 16" | D8: MMD85DH-1 | E8: 1058252 | I8: - | J8: - | K8: Done | L8: Done | M8: Done | N8: Done | O8: Done | P8: Done | Q8: Machinning | R8: USR | T8: Machinning, and replace upper section within the weekend as per Ranjith. | U8: 46036 | V8: 2025-01
A9: 2025-AR-066 | B9: 13867749 | C9: 16" | D9: MMD85DH-1 | E9: 1058252 | I9: Done | J9: - | K9: Done | L9: 46032 | M9: Needed | T9: Finalizing | U9: 46036 | V9: 2025-01
A10: 2025-AR-067 | B10: 13719634 | C10: 12" | D10: GT86DH | E10: 1005462M | I10: Done | K10: 46035 | L10: Needed | O10: Needed | V10: 2025-01
A11: 2025-AR-069 | B11: 12947677R | C11: 12" | D11: GT86DH | E11: 1005462 | I11: - | J11: - | K11: 46042 | R11: USR | T11: Braze | V11: 2025-01
A12: 2025-AR-070 | B12: 13655960 | C12: 12" | D12: GT86DH | E12: 1005462M | I12: Done | J12: Done | K12: 46039 | T12: Braze | V12: 2025-01
A13: 2025-AR-072 | B13: 14178471 | C13: 8 1/2" | D13: GT65RHS-1 | E13: 1276939 | I13: Done | J13: Done | K13: Done | L13: Done | M13: Done | N13: Done | O13: Done | P13: Done | Q13: Done | R13: Done | S13: Final Ins. | T13: Final Inspection | U13: 46036 | V13: 2025-01
A14: 2025-AR-073 | B14: 14211932 | C14: 8 1/2" | D14: GT65RHS-1 | E14: 1276939 | I14: 46033 | J14: Done | K14: 46037 | T14: Braze | V14: 2025-01
A15: 2025-AR-074 | B15: 14190172 | C15: 8 1/2" | D15: GT65RHS-1 | E15: 1276939 | I15: 46033 | J15: Done | K15: 46037 | T15: Braze | V15: 2025-01
A16: 2025-AR-075 | B16: 14211930 | C16: 8 1/2" | D16: GT65RHS-1 | E16: 1276939 | I16: 46033 | J16: Needed | K16: 46041 | T16: Needs Pocket Build up | V16: 2025-01
A17: 2025-AR-076 | B17: 13521409 | C17: 8 3/8" | D17: GT75DH | E17: 1056029 | I17: - | J17: - | K17: 46036 | L17: Done | M17: Done | U17: 46037 | V17: 2025-01
A18: 2025-AR-077 | B18: 13064090R | C18: 8 3/8" | D18: MM65DH | E18: 882281M | I18: - | J18: - | K18: 46032 | U18: 46036 | V18: 2025-01
A19: 2025-AR-078 | B19: 13080019R | C19: 8 3/8" | D19: MM65DH | E19: 882281 | I19: - | J19: - | K19: 46032 | O19: Done | V19: 2025-01
A20: 2025-AR-080 | B20: 13186638R | C20: 8 3/8" | D20: MM65DH | E20: 882281 | I20: 46033 | K20: 45673 | O20: 46043 | T20: Braze | V20: 2025-01
A21: 2025-AR-081 | B21: 13870635 | C21: 8 3/8" | D21: MM65DH | E21: 1061407 | I21: Done | J21: Done | K21: 45673 | T21: Braze | V21: 2025-01
A22: 2025-AR-082 | B22: 13862293 | C22: 8 3/8" | D22: MM65DH | E22: 1061407 | I22: 46041 | J22: 46041 | K22: 46042 | T22: Braze | V22: 2025-01
A23: 2025-AR-083 | B23: 13739196 | C23: 8 3/8" | D23: MM65DH | E23: 1176919 | I23: 46041 | J23: 46041 | K23: 46043 | T23: Braze delayed | V23: 2025-01
A24: 2025-AR-084 | B24: 13044609R | C24: 8 3/8" | D24: MM65DH-1 | E24: 1005293 | I24: 46041 | J24: 46041 | K24: 46043 | T24: Braze delayed due tobrocken pocket | V24: 2025-01
A25: 2025-AR-085 | B25: 13172301R | C25: 8 3/8" | D25: MM65DH-1 | E25: 1080537 | I25: - | J25: - | K25: Done | L25: Done | M25: Done | N25: Done | O25: Done | P25: Done | Q25: Done | R25: Done | S25: Final Ins. | T25: Final Inspection | U25: 46036 | V25: 2025-01
A26: 2025-AR-086 | B26: 13283019R | C26: 8 3/8" | D26: MM65DH-1 | E26: 1080537 | I26: - | J26: - | K26: Done | L26: 46031 | M26: Done | N26: Done | O26: 46043 | P26: - | Q26: Needed | T26: Finalizing | V26: 2025-01
A27: 2025-AR-087 | B27: 13685072 | C27: 6 1/8" | D27: MMD54H | E27: 1137349M | I27: Done | J27: - | K27: Done | L27: Needed | R27: USR | T27: Finalizing, needs upper section | V27: 2025-01
A28: 2025-AR-088 | B28: 13685074 | C28: 6 1/8" | D28: MMD54H | E28: 1137349M | I28: - | J28: - | K28: 46031 | L28: Done | U28: 46037 | V28: 2025-01
A29: 2025-AR-089 | B29: 13685073 | C29: 6 1/8" | D29: MMD54H | E29: 1137349M | I29: Done | J29: - | K29: Done | L29: 46031 | T29: Finalizing | U29: 46036 | V29: 2025-01
A30: 2025-AR-090 | B30: 13719614 | C30: 6 1/8" | D30: MMD54H | E30: 1137349 | I30: - | J30: - | K30: Done | L30: Done | M30: Done | N30: Done | O30: Done | P30: - | Q30: - | R30: - | S30: - | T30: - | U30: 46037 | V30: 2025-01
A31: 2025-ARDT-041 | B31: 13405946 | C31: 6.125 | D31: GT64DH | E31: 1133653 | F31: 46019 | G31: ARDT | I31: - | J31: - | K31: - | L31: - | M31: - | N31: - | O31: - | P31: - | Q31: - | R31: - | S31: - | T31: De-braze 1/11/2026 cutters need to be send to store | U31: 46033
A32: 2025-ARDT-LV4-196 | B32: 14492190 | C32: 8.375 | D32: EM65D | E32: 1283630 | F32: 46022 | G32: LV4 | I32: - | J32: - | O32: 46030 | P32: Rotor Cutters | T32: 46027
A33: 2025-UR-1141 | B33: 14369051R2 | C33: 8.5 | D33: GT65RHS-1 | E33: 1276939M2 | F33: 46019 | G33: UR | I33: - | J33: - | K33: Done | L33: Done | M33: 46032 | U33: 46036
A34: 2026-ARDT-001 | B34: 14073969 | C34: 16 | D34: HD75DOS | E34: 1254482M | F34: 46035 | G34: ARDT | K34: 46037 | V34: Retrofit
A35: 2026-ARDT-LV3-002 | B35: 14418427 | C35: 3.625 | D35: MMD53DH | E35: 2025595 | F35: 46028 | G35: LV3 | K35: 46035 | T35: 46035
A36: 2026-ARDT-LV3-003 | B36: 14431434 | C36: 6.125 | D36: HD54 | E36: 1251085M2 | F36: 46036 | G36: ARDT-LV3 | K36: 46043
A37: 2026-ARDT-LV4-002 | B37: 14462156 | C37: 8.5 | D37: HXI65Ds | E37: 2016764M | F37: 46026 | G37: LV4 | K37: 46034 | T37: 46030
A38: 2026-ARDT-LV4-003 | B38: 14386456 | C38: 12.25 | D38: HD65Os | E38: 2008912 | F38: 46029 | G38: LV4 | I38: - | J38: - | L38: Needed | T38: Due Date 1/12/2026
A39: 2026-ARDT-LV4-004 | B39: 14476928 | C39: 8.375 | D39: HD65DK | E39: 2025815M | F39: 46030 | G39: LV4 | K39: 46034 | M39: Needed | T39: 46036
A40: 2026-ARDT-LV4-005 | B40: 14488518 | C40: 8.5 | D40: GT65RHs | E40: 1276939M2 | F40: 46030 | G40: LV4 | K40: 46036 | T40: 46037
...

Sheet Sheet2
B6: ORDER NO. | C6: SEREAL NO. | D6: SIZE | E6: TYPE | F6: LV5 MAT NO. | G6: Build Up | H6: Pocket Grinding | I6: Braze | J6: Remark
B7: 2026-ARDT-LV4-013 | C7: 14487986 | D7: 8.5 | E7: GT65RHs | F7: 1276939M2 | H7: 46048 | I7: 46048 | J7: Done
B8: 2026-ARDT-LV4-014 | C8: 14487985 | D8: 8.5 | E8: GT65RHs | F8: 1276939M2 | H8: 46048 | I8: 46048 | J8: Done
B9: 2026-ARDT-LV4-015 | C9: 14488519 | D9: 8.5 | E9: GT65RHs | F9: 1276939M2 | H9: 46048 | I9: 46049 | J9: Brazed
B10: 2026-ARDT-LV4-016 | C10: 14488520 | D10: 8.5 | E10: GT65RHs | F10: 1276939M2 | H10: 46049 | I10: 46049 | J10: Brazed
B16: Business Unit | C16: MAT Number | D16: Bit Size | E16: Bit Type | F16: New / Repair | G16: Serial (* Required for repair) | H16: DueDate | I16: Release Date | J16: Updated Due Date
B17: UR Rental - Sperry | C17: 1158011 | D17: 8.5 | E17: GT65RHs | F17: New | G17: 14353144 | H17: 46050 | J17: 46051
A22: ORDER NO. | B22: SERIAL NO | C22: SIZE | D22: TYPE | E22: MAT NO. | F22: RECIVED | G22: FROM | H22: STATUS | I22: FINAL | J22: Upper Section Replacement | K22: Build up | L22: Brazer | M22: Spinner | N22: Tip Grinding by | O22: QC | P22: Thread Cleaning / Machining | Q22: Body Cleaning / Machining | R22: Erosion sleeve | S22: Rework | T22: ACCOMPLISHED DATE | U22: REMARKS | V22: Job Name | W22: Issues report | X22: PDC Production Days | Y22: Lost Cutter | Z22: ITEM NUMBER | AA22: MJ # | AB22: Production Order Number | AC22: Quotation | AD22: RAF
A23: 2026-UR-1006 | B23: 14340871R3 | C23: 8.5 | D23: GT65RHs-1 | E23: 1276939 | F23: 46029 | G23: UR | H23: Scrap | V23: 2026-UR-1006-14340871R3
A24: 2026-UR-1008 | B24: 14414023R2 | C24: 8.5 | D24: GT65RHs-1 | E24: 1276939M2 | F24: 46040 | G24: UR | H24: Scrap | V24: 2026-UR-1008-14414023R2
A25: 2026-UR-1011 | B25: 14462152 | C25: 8.5 | D25: GT65RHs-1 | E25: 1276939M2 | F25: 46044 | G25: UR | H25: Scrap | V25: 2026-UR-1011-14462152

Sheet L3
A1: ORDER NO. | B1: SEREAL NO. | C1: SIZE | D1: TYPE | E1: LV5 MAT NO. | F1: RECIVED | G1: FROM | H1: LV3 MAT NO. | I1: NEW TYPE | J1: STATUS | K1: FINAL | L1: Upper Section Replacement | M1: Build up | N1: Brazer | O1: Spinner | P1: Tip Grinding by | Q1: QC | R1: Thread Cleaning / Machining | S1: Body Cleaning / Machining | T1: Erosion sleeve | U1: Rework | V1: ACCOMPLISHED DATE | W1: REMARKS | X1: Job Name | Y1: Issues report | Z1: PDC Production Days | AA1: Lost Cutters | AB1: Item Number | AC1: MJ # | AD1: Production Order Number | AE1: TRANSFER ORDER | AF1: Quotation | AG1: RAF
A2: 2019-ARDT-LV3-01 | B2: 13274302 | C2: 12.25 | D2: GT76H | E2: 1113064M | F2: 43674 | G2: ARDT-LV3 | H2: 1113064 | W2: LV 3 BIT MAT#1112857 NEEDS TO BE CUTTER INSTALLED AS PER ATTACHED EMAIL INSTRUCTION , DATED 07/28/2019 FROM ROHAN. CUTTER INSTALLATION SHOULD BE DONE ACCORDING TO BOM ASSY #1113064.
A3: 2019-ARDT-LV3-02 | B3: 13274303 | C3: 12.25 | D3: GT76H | E3: 1126138 | F3: 43692 | G3: ARDT-LV3 | W3: Level 3 bit cutter instalation as per Subhi email.
A4: 2019-ARDT-LV3-03 | B4: 13383209 | C4: 12.25 | D4: GT76H | E4: 1112857 | F4: 43809 | G4: ARDT-LV3 | W4: Level 3 bit cutter instalation as per Subhi email.
A5: 2019-ARDT-LV3-04 | B5: 13383208 | C5: 12.25 | D5: GT76H | E5: 1112857M | F5: 43817 | G5: ARDT-LV3 | W5: Level 3 bit cutter installation modified as per Saad email.
A6: 2020-ARDT-LV3-01 | B6: 13383207 | C6: 12.25 | D6: GT76H | E6: 1112857 | F6: 43849 | G6: ARDT-LV3 | V6: 43874
A7: 2020-ARDT-LV3-02 | B7: 13443519 | C7: 8.375 | D7: GT65DH | E7: 1092981 | F7: 43920 | G7: ARDT-LV3 | V7: 43922 | W7: LEVEL 3 BIT FOR BRAZING
A8: 2020-ARDT-LV3-03 | B8: 13443523 | C8: 8.375 | D8: GT65DH | E8: 1092981 | F8: 43920 | G8: ARDT-LV3 | V8: 43922 | W8: LEVEL 3 BIT FOR BRAZING
A9: 2020-ARDT-LV3-04 | B9: 13433561 | C9: 12.25 | D9: GT76H | E9: 1142907 | F9: 43926 | G9: ARDT-LV3 | V9: 43929 | W9: BRAZING FOR LEVEL 3 BIT
A10: 2020-ARDT-LV3-05 | B10: 13433563 | C10: 12.25 | D10: GT76H | E10: 1142907 | F10: 43927 | G10: ARDT-LV3 | V10: 43929 | W10: BRAZING FOR LEVEL 3 BIT
A11: 2020-ARDT-LV3-06 | B11: 13433562 | C11: 12.25 | D11: GT76H | E11: 1054398M | F11: 43927 | G11: ARDT-LV3 | V11: 43934 | W11: BRAZING FOR LEVEL 3 BIT
A12: 2020-ARDT-LV3-07 | B12: 13433564 | C12: 12.25 | D12: GT76H | E12: 1054398M | F12: 43928 | G12: ARDT-LV3 | V12: 43933 | W12: BRAZING FOR LEVEL 3 BIT
A13: 2020-ARDT-LV3-08 | B13: 13443518 | C13: 8.375 | D13: GT65DH | E13: 1092981 | F13: 43935 | G13: ARDT-LV3 | V13: 43940 | W13: LEVEL 3 BIT BRAZING
A14: 2020-ARDT-LV3-09 | B14: 13443520 | C14: 8.375 | D14: GT65DH | E14: 1092981 | F14: 43935 | G14: ARDT-LV3 | V14: 43940 | W14: LEVEL 3 BIT BRAZING
A15: 2020-ARDT-LV3-10 | B15: 13443517 | C15: 8.375 | D15: GT65DH | E15: 1083564M | F15: 43940 | G15: ARDT-LV3 | V15: 43943 | W15: LEVEL 3 BIT BRAZING
A16: 2020-ARDT-LV3-11 | B16: 13443522 | C16: 8.375 | D16: GT65DH | E16: 1083564M | F16: 43940 | G16: ARDT-LV3 | V16: 43943 | W16: LEVEL 3 BIT BRAZING
A17: 2020-ARDT-LV3-12 | B17: 13448033 | C17: 8.375 | D17: MM65DH | E17: 1080537 | F17: 43941 | G17: ARDT-LV3 | V17: 43942 | W17: LEVEL 3 BIT BRAZING
A18: 2020-ARDT-LV3-13 | B18: 13443521 | C18: 8.375 | D18: GT65DH | E18: 1083564M | F18: 43941 | G18: ARDT-LV3 | H18: 1083564M | V18: 43944 | W18: LEVEL 3 BIT BRAZING, MAT: 1083564M will change
A19: 2020-ARDT-LV3-14 | B19: 13448032 | C19: 8.375 | D19: MM65DH | E19: 1080537 | F19: 0420/2020 | G19: ARDT-LV3 | V19: 43943 | W19: LEVEL 3 BIT BRAZING
A20: 2020-ARDT-LV3-15 | B20: 13448034 | C20: 8.375 | D20: MM65DH | E20: 1080537 | F20: 43942 | G20: ARDT-LV3 | V20: 43944 | W20: LEVEL 3 BIT BRAZING
A21: 2020-ARDT-LV3-16 | B21: 13448266 | C21: 12.25 | D21: GT76H | E21: 1142907 | F21: 43943 | G21: ARDT-LV3 | V21: 43949 | W21: LEVEL 3 BIT BRAZING
A22: 2020-ARDT-LV3-17 | B22: 13448267 | C22: 12.25 | D22: GT76H | E22: 1142907 | F22: 43944 | G22: ARDT-LV3 | H22: 1112857 | V22: 43988 | W22: LEVEL 3 BIT BRAZING ( Level 3 material number was 1112857 )
A23: 2020-ARDT-LV3-18 | B23: 13448035 | C23: 8.375 | D23: MM65DH | E23: 1080537 | F23: 43944 | G23: ARDT-LV3 | H23: 1080537 | V23: 43968 | W23: LEVEL 3 BIT BRAZING ( level 5 material number will be 1080537)
A24: 2020-ARDT-LV3-19 | B24: 13448036 | C24: 8.375 | D24: MM65DH | E24: 1080537 | F24: 04/26/200 | G24: ARDT-LV3 | H24: 1140080 | V24: 43988 | W24: LEVEL 3 BIT BRAZING ( level 3 material number WAS 1140080)
A25: 2020-ARDT-LV3-20 | B25: 13461214 | C25: 8.375 | D25: GT65DH | E25: 1147796M | F25: 43972 | G25: ARDT-LV3 | H25: 1141517 | V25: 43988 | W25: As per Saad AND Rami's email, the L3 MAT was 1141517.
A26: 2020-ARDT-LV3-21 | B26: 13448037 | C26: 8.375 | D26: MM65DH | E26: 1080537 | F26: 43984 | G26: ARDT-LV3 | H26: 1140080 | V26: 43988 | W26: LEVEL 3 BIT BRAZING ( level 3 material number WAS 1140080)
A27: 2020-ARDT-LV3-22 | B27: 13448040 | C27: 8.375 | D27: MM65DH | E27: 1080537 | F27: 43984 | G27: ARDT-LV3 | H27: 1140080 | V27: 43998 | W27: LEVEL 3 BIT BRAZING ( level 3 material number WAS 1140080)
A28: 2020-ARDT-LV3-23 | B28: 13461211 | C28: 8.375 | D28: GT65DH | E28: 1083564 | F28: 44001 | G28: ARDT-LV3 | H28: 1141517 | V28: 44003 | W28: LEVEL 3 BIT BRAZING ( level 3 material number WAS 1141517)
A29: 2020-ARDT-LV3-24 | B29: 13467575 | C29: 6.125 | D29: MM64R | E29: 965522 | F29: 44003 | G29: ARDT-LV3 | H29: 1146317M | V29: 44007 | W29: LEVEL 3 BIT BRAZING ( level 3 material number WAS1146317M)
A30: 2020-ARDT-LV3-25 | B30: 13448039 | C30: 8.375 | D30: MM65DH | E30: 1080537 | F30: 44004 | G30: ARDT-LV3 | H30: 1140080M | V30: 44005 | W30: LEVEL 3 BIT BRAZING ( level 3 material number WAS1140080M)
A31: 2020-ARDT-LV3-26 | B31: 13448041 | C31: 8.375 | D31: MM65DH | E31: 1080537 | F31: 44004 | G31: ARDT-LV3 | H31: 1140080M | V31: 44005 | W31: LEVEL 3 BIT BRAZING ( level 3 material number WAS1140080M)
A32: 2020-ARDT-LV3-27 | B32: 13461210 | C32: 8.375 | D32: GT65DH | E32: 1083564 | F32: 44005 | G32: ARDT-LV3 | H32: 1141517 | V32: 44006 | W32: LEVEL 3 BIT BRAZING ( level 5 material number will be1141517)
A33: 2020-ARDT-LV3-28 | B33: 13460777 | C33: 8.375 | D33: MM65DH | E33: 1080537 | F33: 44006 | G33: ARDT-LV3 | H33: 1140080 | V33: 44010 | W33: LEVEL 3 BIT BRAZING ( level 3 material number was 1140080)
A34: 2020-ARDT-LV3-29 | B34: 13460778 | C34: 8.375 | D34: MM65DH | E34: 1080537 | F34: 44006 | G34: ARDT-LV3 | H34: 1140080 | V34: 44010 | W34: LEVEL 5 BIT BRAZING ( level 3material number was 1140080)
A35: 2020-ARDT-LV3-30 | B35: 13460776 | C35: 8.375 | D35: MM65DH | E35: 1080537 | F35: 44007 | G35: ARDT-LV3 | H35: 1140080 | V35: 44010 | W35: LEVEL 3 BIT BRAZING ( level 3 material number was 1140080)
A36: 2020-ARDT-LV3-31 | B36: 13461212 | C36: 8.375 | D36: GT65DH | E36: 1083564 | F36: 44010 | G36: ARDT-LV3 | H36: 1141517 | V36: 44012 | W36: LEVEL 3 BIT BRAZING ( level 3 material number was 1141517)
A37: 2020-ARDT-LV3-32 | B37: 13460779 | C37: 8.375 | D37: MM65DH | E37: 1080537 | F37: 44013 | G37: ARDT-LV3 | H37: 1140080 | V37: 44019 | W37: LEVEL 3 BIT BRAZING ( level 3 material number was1140080)
A38: 2020-ARDT-LV3-33 | B38: 13448038 | C38: 8.375 | D38: MM65DH | E38: 1080537 | F38: 44014 | G38: ARDT-LV3 | H38: 1140080 | V38: 44019 | W38: Level 3 Bit Brazing(Level 3 Material Number was 1140080)
A39: 2020-ARDT-LV3-34 | B39: 13448042 | C39: 8.375 | D39: MM65DH | E39: 1080537 | F39: 44017 | G39: ARDT-LV3 | H39: 1140080 | V39: 44020 | W39: Level 3 Bit Brazing(Level 3 Material Number was 1140080)
A40: 2020-ARDT-LV3-35 | B40: 13448043 | C40: 8.375 | D40: MM65DH | E40: 1080537 | F40: 44017 | G40: ARDT-LV3 | H40: 1140080 | V40: 44020 | W40: Level 3 Bit Brazing(Level 3 Material Number was 1140080)
...

Sheet L4
A1: ORDER NO. | B1: SEREAL NO. | C1: SIZE | D1: TYPE | E1: LV5 MAT NO. | F1: RECIVED | G1: FROM | H1: LV4 MAT NO. | I1: NEW TYPE | J1: STATUS | K1: FINAL | L1: Upper Section Replacement | M1: Build up | N1: Brazer | O1: Spinner | P1: Tip Grinding by | Q1: QC | R1: Thread Cleaning / Machining | S1: Body Cleaning / Machining | T1: Erosion sleeve | U1: Rework | V1: ACCOMPLISHED DATE | W1: REMARKS | X1: Job Name | Y1: Issues report | Z1: PDC Production Days | AA1: Lost Cutters | AB1: ITEM NUMBER | AC1: MJ # | AD1: Production Order Number | AE1: TRANSFER ORDER | AF1: Quotation | AG1: RAF
A2: 2020-ARDT-LV4-01 | B2: 13482809 | C2: 6.125 | D2: GTD64HO | E2: 1137348 | F2: 44054 | G2: ARDT-LV4 | H2: 1149944 | W2: LEVEL 4 BIT BRAZING ( level 4 material number was 1149944)
A3: 2020-ARDT-LV4-02 | B3: 13482810 | C3: 6.125 | D3: GTD64HO | E3: 1137348 | F3: 44054 | G3: ARDT-LV4 | H3: 1149944 | W3: LEVEL 4 BIT BRAZING ( level 4 material number was 1149944)
A4: 2020-ARDT-LV4-03 | B4: 13479539 | C4: 3.625 | D4: MMD53DH | E4: 1084341 | F4: 44054 | G4: ARDT-LV4 | H4: 1145821 | W4: LEVEL 4 BIT BRAZING ( level 4 material number was 1145821)
A5: 2020-ARDT-LV4-04 | B5: 13479540 | C5: 3.625 | D5: MMD53DH | E5: 1084341 | F5: 44054 | G5: ARDT-LV4 | H5: 1145821 | W5: LEVEL 4 BIT BRAZING ( level 4 material number was 1145821)
A6: 2020-ARDT-LV4-05 | B6: 13490645 | C6: 6.125 | D6: GTD54HO | E6: 1137349 | F6: 44075 | G6: ARDT-LV4 | H6: 1150007 | W6: Level 4 Bit Brazing(level 4 material was 1150007)
A7: 2020-ARDT-LV4-06 | B7: 13490646 | C7: 6.125 | D7: GTD54HO | E7: 1137349 | F7: 44075 | G7: ARDT-LV4 | H7: 1150007 | W7: Level 4 Bit Brazing(level 4 material was 1150007)
A8: 2020-ARDT-LV4-07 | B8: 13509986 | C8: 6.125 | D8: GTD64HO | E8: 1162241 | F8: 44129 | G8: ARDT-LV4 | W8: LEVEL 4 BIT BRAZING(1313-CT427 0.010 – 1145493, 1313-CT418 0.010 - 1100696), THE mat NO. STILL NOT RECIVED- REMIND AZIM
A9: 2020-ARDT-LV4-08 | B9: 13517595 | C9: 3.625 | D9: MMD53DH | E9: 1084341 | F9: 44137 | G9: ARDT-LV4 | H9: 1145821 | W9: LEVEL 5 BIT BRAZING ( level 4 material number was 1145821)
A10: 2020-ARDT-LV4-09 | B10: 13517596 | C10: 3.625 | D10: MMD53DH | E10: 1084341 | F10: 44151 | G10: ARDT-LV4 | H10: 1145821 | W10: LEVEL 5 BIT BRAZING ( level 4 material number was 1145821)
A11: 2020-ARDT-LV4-10 | B11: 13517597 | C11: 3.625 | D11: MMD53DH | E11: 1084341 | F11: 44151 | G11: ARDT-LV4 | H11: 1145821 | W11: LEVEL 5 BIT BRAZING ( level 4 material number was 1145821)
A12: 2020-ARDT-LV4-11 | B12: 13518299 | C12: 3.625 | D12: MMD53DH | E12: 1084341 | F12: 44168 | G12: ARDT-LV4 | H12: 1145821 | W12: LEVEL 5 BIT BRAZING ( level 4 material number was 1145821)
A13: 2020-ARDT-LV4-12 | B13: 13517598 | C13: 3.625 | D13: MMD53DH | E13: 1084341 | F13: 44171 | G13: ARDT-LV4 | H13: 1145821 | W13: LEVEL 5 BIT BRAZING ( level 4 material number was 1145821)
A14: 2021-ARDT-LV4-01 | B14: 13537087 | C14: 3.625 | D14: MMD53DH | E14: 1084341 | F14: 44206 | G14: ARDT-LV4 | H14: 1145821 | V14: 44207 | W14: LEVEL 5 BIT BRAZING ( level 4 material number was 1145821)
A15: 2021-ARDT-LV4-02 | B15: 13537090 | C15: 3.625 | D15: MMD53DH | E15: 1084341 | F15: 44206 | G15: ARDT-LV4 | H15: 1145821 | V15: 44207 | W15: LEVEL 5 BIT BRAZING ( level 4 material number was 1145821)
A16: 2021-ARDT-LV4-03 | B16: 13537088 | C16: 3.625 | D16: MMD53DH | E16: 1084341 | F16: 44207 | G16: ARDT-LV4 | H16: 1145821 | V16: 44208 | W16: LEVEL 5 BIT BRAZING ( level 4 material number was 1145821)
A17: 2021-ARDT-LV4-04 | B17: 13537089 | C17: 3.625 | D17: MMD53DH | E17: 1084341 | F17: 44209 | G17: ARDT-LV4 | H17: 1145821 | V17: 44210 | W17: LEVEL 5 BIT BRAZING ( level 4 material number was 1145821)
A18: 2021-ARDT-LV4-05 | B18: 13537091 | C18: 3.625 | D18: MMD53DH | E18: 1084341 | F18: 44209 | G18: ARDT-LV4 | H18: 1145821 | V18: 44210 | W18: LEVEL 5 BIT BRAZING ( level 4 material number was 1145821)
A19: 2021-ARDT-LV4-06 | B19: 13538473 | C19: 3.625 | D19: MMD53DH | E19: 1084341 | F19: 44229 | G19: ARDT-LV4 | H19: 1145821 | V19: 44231 | W19: LEVEL 5 BIT BRAZING ( level 4 material number was 1145821)
A20: 2021-ARDT-LV4-07 | B20: 13538474 | C20: 3.625 | D20: MMD53DH | E20: 1084341 | F20: 44229 | G20: ARDT-LV4 | H20: 1145821 | V20: 44236 | W20: LEVEL 5 BIT BRAZING ( level 4 material number was 1145821)
A21: 2021-ARDT-LV4-08 | B21: 13538475 | C21: 3.625 | D21: MMD53DH | E21: 1084341 | F21: 44236 | G21: ARDT-LV4 | H21: 1145821 | V21: 44238 | W21: LEVEL 4 BIT BRAZING ( level 4 material number was 1145821)
A22: 2021-ARDT-LV4-09 | B22: 13537092 | C22: 3.625 | D22: MMD53DH | E22: 1084341 | F22: 44236 | G22: ARDT-LV4 | H22: 1145821 | V22: 44238 | W22: LEVEL 4 BIT BRAZING ( level 4 material number was 1145821)
A23: 2021-ARDT-LV4-10 | B23: 13490647 | C23: 6.125 | D23: GTD54HO | E23: 1150007M | F23: 44237 | G23: ARDT-LV4 | H23: 1150007M | V23: 44238 | W23: LEVEL 4 BIT BRAZING ( level 5 material number will be 1150007M)-Check with Azim to change to new MAT No. instead of this L4 MAT No.
A24: 2021-ARDT-LV4-11 | B24: 13538476 | C24: 3.625 | D24: MMD53DH | E24: 1084341 | F24: 44256 | G24: ARDT-LV4 | H24: 1145821 | V24: 44257 | W24: LEVEL 4 BIT BRAZING ( level 4 material number was 1145821 )
A25: 2021-ARDT-LV4-12 | B25: 13538477 | C25: 3.625 | D25: MMD53DH | E25: 1084341 | F25: 44257 | G25: ARDT-LV4 | H25: 1145821 | V25: 44258 | W25: LEVEL 4 BIT BRAZING ( level 4 material number was 1145821)
A26: 2021-ARDT-LV4-13 | B26: 13538478 | C26: 3.625 | D26: MMD53DH | E26: 1084341 | F26: 44257 | G26: ARDT-LV4 | H26: 1145821 | V26: 44259 | W26: LEVEL 4 BIT BRAZING ( level 4 material number was 1145821)
A27: 2021-ARDT-LV4-14 | B27: 13538479 | C27: 3.625 | D27: MMD53DH | E27: 1084341 | F27: 44267 | G27: ARDT-LV4 | H27: 1145821 | V27: 44267 | W27: LEVEL 4 BIT BRAZING ( level 4 material number was 1145821)
A28: 2021-ARDT-LV4-15 | B28: 13538480 | C28: 3.625 | D28: MMD53DH | E28: 1084341 | F28: 44278 | G28: ARDT-LV4 | H28: 1145821 | V28: 44280 | W28: LEVEL 4 BIT BRAZING ( level 4 material number was 1145821)
A29: 2021-ARDT-LV4-16 | B29: 13558472 | C29: 3.625 | D29: MMD53DH | E29: 1084341 | F29: 44293 | G29: ARDT-LV4 | H29: 1145821 | V29: 44294 | W29: LEVEL 4 BIT BRAZING ( level 4 material number was 1145821)
A30: 2021-ARDT-LV4-17 | B30: 13558474 | C30: 3.625 | D30: MMD53DH | E30: 1084341 | F30: 44304 | G30: ARDT-LV4 | H30: 1145821 | V30: 44308 | W30: LEVEL 4 BIT BRAZING ( level 4 material number was 1145821)
A31: 2021-ARDT-LV4-18 | B31: 13516789 | C31: 6.125 | D31: GTD54HO | E31: 1170939M | F31: 44312 | G31: ARDT-LV4 | H31: 1150007 | V31: 44318 | W31: LEVEL 4 BIT BRAZING ( level 3 material number was 1150007)
A32: 2021-ARDT-LV4-19 | B32: 13558461 | C32: 6.125 | D32: GTD64HO | E32: 1162241M | F32: 44325 | G32: ARDT-LV4 | H32: 1162241M | V32: 44329 | W32: LEVEL 4 BIT BRAZING ( Use attached cutter map and change CT418 to CT427. Assign mat#1162241M as per saad mail)
A33: 2021-ARDT-LV4-20 | B33: 13567170 | C33: 3.625 | D33: MMD53DH | E33: 1096183 | F33: 44326 | G33: ARDT-LV4 | H33: 1145821 | V33: 44335 | W33: LEVEL 4 BIT BRAZING ( level 4 material number was 1145821 )
A34: 2021-ARDT-LV4-21 | B34: 13567168 | C34: 3.625 | D34: MMD53DH | E34: 1084341 | F34: 44326 | G34: ARDT-LV4 | H34: 1145821 | V34: 44330 | W34: LEVEL 4 BIT BRAZING ( level 4 material number was 1145821 )
A35: 2021-ARDT-LV4-22 | B35: 13567171 | C35: 3.625 | D35: MMD53DH | E35: 1096183 | F35: 44369 | G35: ARDT-LV4 | H35: 1145821 | V35: 44376 | W35: LEVEL 4 BIT BRAZING ( level 4 material number was 1145821 )
A36: 2021-ARDT-LV4-23 | B36: 13558473 | C36: 3.625 | D36: MMD53DH | E36: 1084341M | F36: 44381 | G36: ARDT-LV4 | H36: 1145821 | V36: 44388 | W36: LEVEL 4 BIT BRAZING ( level 4 material number was 1145821)
A37: 2021-ARDT-LV4-24 | B37: 13593349 | C37: 6.125 | D37: GTD64HO | E37: 1149944M | F37: 44440 | G37: ARDT-LV4 | V37: 44441 | W37: LEVEL 4 BIT BRAZING ( need to install CT427 cutters in the subject bit)
A38: 2021-ARDT-LV4-25 | B38: 13567173 | C38: 3.625 | D38: MMD53DH | E38: 1096183 | F38: 44444 | G38: ARDT-LV4 | H38: 1145821 | V38: 44446 | W38: LEVEL 4 BIT BRAZING ( Level 4 material number was 1145821)
A39: 2021-ARDT-LV4-26 | B39: 13567174 | C39: 3.625 | D39: MMD53DH | E39: 1096183 | F39: 44444 | G39: ARDT-LV4 | H39: 1145821 | V39: 44446 | W39: LEVEL 4 BIT BRAZING ( Level 4 material number was 1145821)
A40: 2021-ARDT-LV4-27 | B40: 13593126 | C40: 6.125 | D40: GTD54HO | E40: 1174282 | F40: 44451 | G40: ARDT-LV4 | H40: 1150007 | V40: 44452 | W40: LEVEL 4 BIT BRAZING ( Level 4 material number was 1150007)
...

Sheet Brazers Count
E4: Brazer | F4: Spinner | S4: Brazer | T4: Spinner | U4: Tip Grinding by | V4: QC | W4: Thread Cleaning / Machining | X4: Body Cleaning / Machining | Y4: Erosion sleeve | Z4: Rework
D5: 1 | E5: Mohana | F5: Showaiki | S5: Showaiki | T5: Wasmi | Z5: RP-2025-032
D6: 1 | E6: Mohana | F6: Showaiki | S6: Mohana | T6: Showaiki | Z6: RP-2025-034
D7: 1 | E7: Mohana | F7: Showaiki | S7: Mohana | T7: Showaiki | Z7: RP-2025-035
D8: 1 | E8: Showaiki | F8: Mohana | S8: Showaiki | T8: Wasmi | Z8: RP-2025-039
D9: 1 | E9: Showaiki | F9: Mohana | S9: Showaiki | T9: Mohana | Z9: RP-2025-041
D10: 1 | E10: Showaiki | F10: Mohana | S10: Wasmi | T10: Mohana | Z10: RP-2025-031
D11: 1 | E11: Showaiki | F11: Mohana | S11: Showaiki | T11: Wasmi | Z11: RP-2025-033
D12: 1 | E12: Showaiki | F12: Mohana | S12: Showaiki | T12: Mohana | Z12: RP-2025-036
D13: 1 | E13: Showaiki | F13: Mohana | S13: Showaiki | T13: Mohana | Z13: RP-2025-038
D14: 1 | E14: Showaiki | F14: Mohana | S14: Showaiki | T14: Mohana | Z14: RP-2025-040
D15: 1 | E15: Showaiki | F15: Mohana | S15: Mohana | T15: Showaiki | Z15: PR-2025-028
D16: 1 | E16: Showaiki | F16: Mohana | S16: Showaiki | T16: Mohana | Z16: RP-2025-037
D17: 1 | E17: Mohana | F17: Showaiki
D18: 1 | E18: Mohana | F18: Showaiki
D19: 1 | E19: Mohana | F19: Showaiki
D20: 1 | E20: Mohana | F20: Showaiki
D21: 1 | E21: Showaiki | F21: Mohana
D22: 1 | E22: Showaiki | F22: Mohana
D23: 1 | E23: Showaiki | F23: Mohana | R23: 1 | S23: Showaiki | T23: Mohana | Z23: RP-2025-032
D24: 1 | E24: Showaiki | F24: Mohana | R24: 1 | S24: Showaiki | T24: Mohana | Z24: RP-2025-034
D25: 1 | E25: Showaiki | F25: Mohana | R25: 1 | S25: Mohana | T25: Showaiki | Z25: RP-2025-035
D26: 1 | E26: Showaiki | F26: Mohana | R26: 1 | S26: Mohana | T26: Showaiki | Z26: RP-2025-039
D27: 1 | E27: Showaiki | F27: Mohana | R27: 1 | S27: Showaiki | T27: Mohana | Z27: RP-2025-041
D28: 1 | E28: Showaiki | F28: Mohana | R28: 1 | S28: Showaiki | T28: Wasmi | Z28: FC 2025-007, 008, 011
D29: 1 | E29: Showaiki | F29: Mohana | R29: 1 | S29: Showaiki | T29: Mohana | Z29: FC 2025-007, 008, 011
D30: 1 | E30: Showaiki | F30: Mohana | R30: 1 | S30: Showaiki | T30: Mohana | Z30: FC 2025-009
D31: 1 | E31: Showaiki | F31: Mohana | R31: 1 | S31: Showaiki | T31: Mohana | Z31: FC 2025-010
D32: 1 | E32: Showaiki | F32: Mohana | R32: 1 | S32: Showaiki | T32: Mohana | Z32: RP-2025-037
D33: 1 | E33: Showaiki | F33: Mohana | K33: operator | L33: Rework count | M33: Bits count | N33: Percent | R33: 1 | S33: Mohana | T33: Showaiki | Z33: RP-2025-031
D34: 1 | E34: Showaiki | F34: Mohana | K34: Showaiki | L34: =SUMIF($T$23:$T$50,K34,$R$23:$R$50)+SUMIF($S$23:$S$50,K34,$R$23:$R$50) -> 19 | M34: =SUMIF($F$5:$F$208,K34,$D$5:$D$214)+SUMIF($E$5:$E$208,K34,$D$5:$D$214) -> 102 | N34: =(M34-L34)/M34 -> 0.81372549 | R34: 1 | S34: Mohana | T34: Showaiki | Z34: RP-2025-033
D35: 1 | E35: Showaiki | F35: Mohana | K35: Wasmi | L35: =SUMIF($T$23:$T$50,K35,$R$23:$R$50)+SUMIF($S$23:$S$50,K35,$R$23:$R$50) -> 1 | M35: =SUMIF($F$5:$F$208,K35,$D$5:$D$214)+SUMIF($E$5:$E$208,K35,$D$5:$D$214) -> 7 | N35: =(M35-L35)/M35 -> 0.85714286 | R35: 1 | S35: Showaiki | T35: Mohana | Z35: RP-2025-036
D36: 1 | E36: Showaiki | F36: Mohana | K36: Mohana | L36: =SUMIF($T$23:$T$50,K36,$R$23:$R$50)+SUMIF($S$23:$S$50,K36,$R$23:$R$50) -> 18 | M36: =SUMIF($F$5:$F$208,K36,$D$5:$D$214)+SUMIF($E$5:$E$208,K36,$D$5:$D$214) -> 101 | N36: =(M36-L36)/M36 -> 0.82178218 | R36: 1 | S36: Showaiki | T36: Mohana | Z36: RP-2025-038
D37: 1 | E37: Showaiki | F37: Mohana | R37: 1 | S37: Mohana | T37: Showaiki | Z37: RP-2025-040
D38: 1 | E38: Showaiki | F38: Mohana | R38: 1 | S38: Mohana | T38: Showaiki
D39: 1 | E39: Showaiki | F39: Mohana | R39: 1 | S39: Mohana | T39: Showaiki
D40: 1 | E40: Showaiki | F40: Mohana | R40: 1 | S40: Mohana | T40: Showaiki
D41: 1 | E41: Showaiki | F41: Mohana | R41: 1 | S41: Mohana | T41: Showaiki
D42: 1 | E42: Showaiki | F42: Mohana
D43: 1 | E43: Showaiki | F43: Mohana | L43: Operator | M43: Percent
...

Sheet ARAMCO Q1-2026 Repair Prep.
A1: Item no | B1: Serial No | C1: ORDER NO. | D1: Bit Size | E1: Bit Type | F1: LV5 MAT NO. | G1: RECIVED | H1: FROM | I1: LV3/4 MAT NO. | J1: IADC | K1: Manufacture | L1: Description | O1: Bit Size | P1: Bit Type | Q1: count
A2: 1 | B2: 13971110 | C2: =IFERROR(VLOOKUP(B2,#REF!,2,FALSE),"Brazed In USA") -> Brazed In USA | D2: 5-7/8" | E2: EM65D | J2: 999 | K2: SECURITY | L2: 5-7/8" PDC BIT / R/P Q4-2024 | O2: 8-3/8" | P2: GT75DH | Q2: 1
A3: 9 | B3: 14211858 | C3: =IFERROR(VLOOKUP(B3,#REF!,2,FALSE),"Brazed In USA") -> Brazed In USA | D3: 5-7/8" | E3: EM65D | F3: 1235768 | G3: 45519 | H3: ARDT-LV4 | I3: 1262047 | J3: M425 | K3: SECURITY | L3: R/P Q4-2024 | O3: 12-1/4" | P3: HD75WF | Q3: 2
A4: 8 | B4: 14167828 | C4: =IFERROR(VLOOKUP(B4,#REF!,2,FALSE),"Brazed In USA") -> Brazed In USA | D4: 5-7/8" | E4: EM65D | F4: 1235768 | G4: 45453 | H4: ARDT-LV4 | I4: 1262047 | J4: M425 | K4: SECURITY | L4: R/P Q4-2024 | O4: 12" | P4: MM65DH-1 | Q4: 2 | W4: Ser# | X4: Size | Y4: Bit type | Z4: type | AA4: IADC | AB4: MFG | AC4: DRSS | AD4: WBS
A5: 9 | B5: 14144625 | C5: =IFERROR(VLOOKUP(B5,#REF!,2,FALSE),"Brazed In USA") -> Brazed In USA | D5: 5-7/8" | E5: EM65D | F5: 1235768 | G5: 45446 | H5: ARDT-LV4 | I5: 1262047 | J5: M425 | K5: SECURITY | L5: 5-7/8" 'REPAIR Q2, Q3-2024' | O5: 16" | P5: MM85DH | Q5: 4 | T5: 13770623 | U5: =VLOOKUP(T5,W:AD,7,0) -> 1004761397 | W5: 12947677 | X5: 12" | Y5: DBIT | Z5: GT86DH | AA5: M423 | AB5: SECURITY | AC5: 1004758789 | AD5: 87-24541-8360
A6: 7 | B6: 14144624 | C6: =IFERROR(VLOOKUP(B6,#REF!,2,FALSE),"Brazed In USA") -> Brazed In USA | D6: 5-7/8" | E6: EM65D | F6: 1235768 | G6: 45446 | H6: ARDT-LV4 | I6: 1262047 | J6: M425 | K6: SECURITY | L6: REPAIR Q4-2024 | O6: 12" | P6: GT86DH | Q6: 7 | T6: 13886505 | U6: =VLOOKUP(T6,W:AD,7,0) -> 1004761400 | W6: 13655960 | X6: 12" | Y6: DBIT | Z6: GT86DH | AA6: 999 | AB6: SECURITY | AC6: 1004758789 | AD6: 87-24541-8360
A7: 7 | B7: 14144621 | C7: =IFERROR(VLOOKUP(B7,#REF!,2,FALSE),"Brazed In USA") -> Brazed In USA | D7: 5-7/8" | E7: EM65D | F7: 1235768 | G7: 45412 | H7: ARDT-LV4 | I7: 1262047 | J7: M425 | K7: SECURITY | L7: R/P Q4-2024 | O7: 8-1/2" | P7: GT65RHS-1 | Q7: 8 | T7: 13923839 | U7: =VLOOKUP(T7,W:AD,7,0) -> 1004761400 | W7: 13719634 | X7: 12" | Y7: DBIT | Z7: GT86DH | AA7: 999 | AB7: SECURITY | AC7: 1004758789 | AD7: 87-24541-8360
A8: 8 | B8: 14127551 | C8: =IFERROR(VLOOKUP(B8,#REF!,2,FALSE),"Brazed In USA") -> Brazed In USA | D8: 5-7/8" | E8: EM65D | F8: 1235768 | G8: 45347 | H8: ARDT-LV4 | I8: 1262047 | J8: M425 | K8: SECURITY | L8: R/P Q4-2024 | O8: 6-1/8" | P8: MMD54H | Q8: 8 | T8: 14093083 | U8: =VLOOKUP(T8,W:AD,7,0) -> 1004761403 | W8: 13719636 | X8: 12" | Y8: DBIT | Z8: GT86DH | AA8: 999 | AB8: SECURITY | AC8: 1004758789 | AD8: 87-24541-8360
A9: 10 | B9: 14104605 | C9: =IFERROR(VLOOKUP(B9,#REF!,2,FALSE),"Brazed In USA") -> Brazed In USA | D9: 5-7/8" | E9: EM65D | F9: 1235768 | G9: 45327 | H9: ARDT-LV4 | I9: 1262047 | J9: M425 | K9: SECURITY | L9: R/P Q1-2024 | O9: 8-3/8" | P9: GT65DH-1 | Q9: 10 | T9: 13740200 | U9: =VLOOKUP(T9,W:AD,7,0) -> 1004761387 | W9: 13712066 | X9: 12" | Y9: DBIT | Z9: GTD86DH | AA9: 999 | AB9: SECURITY | AC9: 1004758789 | AD9: 87-24541-8360
A10: 9 | B10: 14073989 | C10: =IFERROR(VLOOKUP(B10,#REF!,2,FALSE),"Brazed In USA") -> Brazed In USA | D10: 5-7/8" | E10: EM65D | F10: 1235768 | G10: 45320 | H10: ARDT-LV4 | I10: 1262047 | J10: M425 | K10: SECURITY | L10: R/P Q4-2024 | O10: 12" | P10: GTD86DH | Q10: 10 | T10: 13719632 | U10: =VLOOKUP(T10,W:AD,7,0) -> 1004761387 | W10: 13740200 | X10: 12" | Y10: DBIT | Z10: GT86DH | AA10: 999 | AB10: SECURITY | AC10: 1004761387 | AD10: 83-24710-8370
A11: 8 | B11: 14109676 | C11: =IFERROR(VLOOKUP(B11,#REF!,2,FALSE),"Brazed In USA") -> Brazed In USA | D11: 5-7/8" | E11: EM65D | F11: 1235768 | G11: 45312 | H11: ARDT-LV4 | I11: 1262047 | J11: M425 | K11: SECURITY | L11: R/P Q4-2024 | O11: 8-3/8" | P11: MM65DH-1 | Q11: 11 | T11: 13860646 | U11: =VLOOKUP(T11,W:AD,7,0) -> 1004761390 | W11: 13719632 | X11: 12" | Y11: DBIT | Z11: GT86DH | AA11: 999 | AB11: SECURITY | AC11: 1004761387 | AD11: 83-24710-8370
A12: 4 | B12: 14104599 | C12: =IFERROR(VLOOKUP(B12,#REF!,2,FALSE),"Brazed In USA") -> Brazed In USA | D12: 5-7/8" | E12: EM65D | F12: 1235768 | G12: 45286 | H12: ARDT-LV4 | I12: 1262047 | J12: M425 | K12: SECURITY | L12: R/P Q4-2024 | O12: 16" | P12: MMD85DH-1 | Q12: 11 | T12: 13845939 | U12: =VLOOKUP(T12,W:AD,7,0) -> 1004761390 | W12: 13740204 | X12: 12" | Y12: DBIT | Z12: GT86DH | AA12: 999 | AB12: SECURITY | AC12: 1004761387 | AD12: 83-24710-8370
A13: 1 | B13: 14056700 | C13: =IFERROR(VLOOKUP(B13,#REF!,2,FALSE),"Brazed In USA") -> Brazed In USA | D13: 5-7/8" | E13: EM65D | F13: 1235768 | G13: 45222 | H13: ARDT-LV4 | I13: 1262047 | J13: 999 | K13: SECURITY | L13: R/P | O13: 5-7/8" | P13: EM65D | Q13: 12 | T13: 13912279 | U13: =VLOOKUP(T13,W:AD,7,0) -> 1004761390 | W13: 13739190 | X13: 12" | Y13: DBIT | Z13: GTD86DH | AA13: 999 | AB13: SECURITY | AC13: 1004761387 | AD13: 83-24710-8370
A14: 7 | B14: 14198201 | C14: =IFERROR(VLOOKUP(B14,#REF!,2,FALSE),"Brazed In USA") -> Brazed In USA | D14: 8-3/8" | E14: GT65DH-1 | F14: 1246020 | G14: 45449 | H14: ARDT-LV3 | I14: 1246020 | J14: M443 | K14: SECURITY | L14: R/P Q4-2024 | O14: 8-3/8" | P14: MM65DH | Q14: 15 | T14: 13846594 | U14: =VLOOKUP(T14,W:AD,7,0) -> 1004761390 | W14: 13754554 | X14: 12" | Y14: DBIT | Z14: GTD86DH | AA14: 999 | AB14: SECURITY | AC14: 1004761387 | AD14: 83-24710-8370
A15: 7 | B15: 14178488 | C15: =IFERROR(VLOOKUP(B15,#REF!,2,FALSE),"Brazed In USA") -> Brazed In USA | D15: 8-3/8" | E15: GT65DH-1 | F15: 1246020 | G15: 45438 | H15: ARDT-LV3 | I15: 1246020 | J15: M443 | K15: SECURITY | L15: R/P Q4-2024 | T15: 14199938 | U15: =VLOOKUP(T15,W:AD,7,0) -> 1004762122 | W15: 13860646 | X15: 12" | Y15: DBIT | Z15: GTD86DH | AA15: 999 | AB15: SECURITY | AC15: 1004761390 | AD15: 83-24710-8368
A16: 7 | B16: 14178487 | C16: =IFERROR(VLOOKUP(B16,#REF!,2,FALSE),"Brazed In USA") -> Brazed In USA | D16: 8-3/8" | E16: GT65DH-1 | F16: 1246020M | G16: 45419 | H16: ARDT-LV3 | I16: 1246020 | J16: M443 | K16: SECURITY | L16: R/P Q4-2024 | T16: 14228469 | U16: =VLOOKUP(T16,W:AD,7,0) -> 1004762122 | W16: 13845939 | X16: 12" | Y16: DBIT | Z16: GTD86DH | AA16: 999 | AB16: SECURITY | AC16: 1004761390 | AD16: 83-24710-8368
A17: 13 | B17: 14081143 | C17: =IFERROR(VLOOKUP(B17,#REF!,2,FALSE),"Brazed In USA") -> Brazed In USA | D17: 8-3/8" | E17: GT65DH-1 | F17: 1239176M | G17: 45270 | H17: ARDT-LV4 | I17: 1239176 | J17: M443 | K17: SECURITY | L17: R/P Q4-2024 | T17: 13566945 | U17: =VLOOKUP(T17,W:AD,7,0) -> 1004762151 | W17: 13739180 | X17: 12" | Y17: DBIT | Z17: MM65DH-1 | AA17: 999 | AB17: SECURITY | AC17: 1004761390 | AD17: 83-24710-8368
A18: 1 | B18: 13685075 | C18: =IFERROR(VLOOKUP(B18,#REF!,2,FALSE),"Brazed In USA") -> Brazed In USA | D18: 8-3/8" | E18: GT65DH-1 | F18: 1092981M | G18: 44675 | H18: ARDT-LV3 | I18: 1141517 | J18: 999 | K18: SECURITY | L18: R/P | T18: 13697072 | U18: =VLOOKUP(T18,W:AD,7,0) -> 1004762155 | W18: 13846594 | X18: 12" | Y18: DBIT | Z18: MM65DH-1 | AA18: 999 | AB18: SECURITY | AC18: 1004761390 | AD18: 83-24710-8368
A19: 1 | B19: 13711524 | C19: =IFERROR(VLOOKUP(B19,#REF!,2,FALSE),"Brazed In USA") -> Brazed In USA | D19: 8-3/8" | E19: GT65DH-1 | F19: 1083564M | G19: 44649 | H19: ARDT-LV3 | I19: 1141517 | J19: 999 | K19: SECURITY | L19: R/P | T19: 13753277 | U19: =VLOOKUP(T19,W:AD,7,0) -> 1004762156 | W19: 13912279 | X19: 12" | Y19: DBIT | Z19: GTD86DH | AA19: 999 | AB19: SECURITY | AC19: 1004761390 | AD19: 83-24710-8368
A20: 5 | B20: 13695797 | C20: =IFERROR(VLOOKUP(B20,#REF!,2,FALSE),"Brazed In USA") -> Brazed In USA | D20: 8-3/8" | E20: GT65DH-1 | F20: 1083564M | G20: 44595 | H20: ARDT-LV3 | I20: 1141517 | J20: 999 | K20: SECURITY | L20: R/P | T20: 13712055 | U20: =VLOOKUP(T20,W:AD,7,0) -> 1004762156 | W20: 13884776 | X20: 12" | Y20: DBIT | Z20: GTD86DH | AA20: M423 | AB20: SECURITY | AC20: 1004761393 | AD20: 83-24710-8224
