Workbook
Name BLADE1: TRANSPOSE!$C$4:$AJ$4
Name BLADE10: TRANSPOSE!$C$13:$AJ$13
Name BLADE11: TRANSPOSE!$C$14:$AJ$14
Name BLADE12: TRANSPOSE!$C$15:$AJ$15
Name BLADE2: TRANSPOSE!$C$5:$AJ$5
Name BLADE3: TRANSPOSE!$C$6:$AJ$6
Name BLADE4: TRANSPOSE!$C$7:$AJ$7
Name BLADE5: TRANSPOSE!$C$8:$AJ$8
Name BLADE6: TRANSPOSE!$C$9:$AJ$9
Name BLADE7: TRANSPOSE!$C$10:$AJ$10
Name BLADE8: TRANSPOSE!$C$11:$AJ$11
Name BLADE9: TRANSPOSE!$C$12:$AJ$12
Name TRANS2B1: TRANSPOSE!$AO$64:$AO$97
Name TRANS2B10: TRANSPOSE!$AX$64:$AX$97
Name TRANS2B11: TRANSPOSE!$AY$64:$AY$97
Name TRANS2B12: TRANSPOSE!$AZ$64:$AZ$97
Name TRANS2B2: TRANSPOSE!$AP$64:$AP$97
Name TRANS2B3: TRANSPOSE!$AQ$64:$AQ$97
Name TRANS2B4: TRANSPOSE!$AR$64:$AR$97
Name TRANS2B5: TRANSPOSE!$AS$64:$AS$97
Name TRANS2B6: TRANSPOSE!$AT$64:$AT$97
Name TRANS2B7: TRANSPOSE!$AU$64:$AU$97
Name TRANS2B8: TRANSPOSE!$AV$64:$AV$97
Name TRANS2B9: TRANSPOSE!$AW$64:$AW$97
Name TRAS1B1: TRANSPOSE!$O$64:$O$97
Name TRAS1B10: TRANSPOSE!$X$64:$X$97
Name TRAS1B11: TRANSPOSE!$Y$64:$Y$97
Name TRAS1B12: TRANSPOSE!$Z$64:$Z$97
Name TRAS1B2: TRANSPOSE!$P$64:$P$97
Name TRAS1B3: TRANSPOSE!$Q$64:$Q$97
Name TRAS1B4: TRANSPOSE!$R$64:$R$97
Name TRAS1B5: TRANSPOSE!$S$64:$S$97
Name TRAS1B6: TRANSPOSE!$T$64:$T$97
Name TRAS1B7: TRANSPOSE!$U$64:$U$97
Name TRAS1B8: TRANSPOSE!$V$64:$V$97
Name TRAS1B9: TRANSPOSE!$W$64:$W$97

Sheet Data
A1: ARDT Work Order No | B1: 2025-AR-105 | D1: Data Entry for Bits | L1: Qty | N1: PRICES | DB1: FOR THE DROP IN LIST | DD1: No | DE1: SAP No | DF1: Description | DG1: Description | DH1: Cutter Size mm | DI1: Cutter size | DJ1: Type | DK1: More Description | DL1: Chamfer | DM1: Book Stock | DN1: Re-Claimed | DO1: LSTK prices | DP1: BPS | DQ1: for 37/8" | DS1: ARDT REGIONAL PRICES | DT1: Woodland price | DU1: Corehead price | DV1: Category BPS | DW1: Service Number | DX1: ARAMCO Item Number | DY1: ARAMCO Description | DZ1: Size | EA1: PerUOM | EB1: Unit | EC1: ARAMCO Price (USD) | EE1: Cutters Qty | EF1: ROWS | EG1: FIND X1 IN ROWS | EH1: BRING X1 UP | EJ1: FIND X2 IN ROWS | EK1: BRING X2UP | EM1: FIND X3 IN ROWS | EN1: BRING X3 UP | EP1: FIND X4 IN ROWS | EQ1: BRING X4 UP | ES1: FIND X5IN ROWS | ET1: BRING X5UP | EV1: FIND X6 IN ROWS | EW1: BRING X6 UP | EY1: FIND X7 IN ROWS | EZ1: BRING X7 UP | FB1: FIND X8 IN ROWS | FC1: BRING X8 UP | FE1: FIND X9 IN ROWS | FF1: BRING X9 UP | FH1: FIND X10 IN ROWS | FI1: BRING X10 UP | FK1: FIND X11 IN ROWS | FL1: BRING X11 UP | FN1: FIND X12 IN ROWS | FO1: BRING X12 UP | FQ1: FIND X13 IN ROWS | FR1: BRING X13 UP | FT1: FIND X14 IN ROWS | FU1: BRING X14 UP | FW1: FIND X15 IN ROWS | FX1: BRING X15 UP | FZ1: FIND X16 IN ROWS | GA1: BRING X16 UP | GC1: FIND X17 IN ROWS | GD1: BRING X17 UP | GG1: SAP No | GH1: Description | GI1: Description | GJ1: Cutter Size mm | GK1: Cutter size | GL1: Type | GM1: More Description | GN1: Chamfer | GO1: Book Stock | GP1: Re-Claimed | GQ1: Price | GR1: BPS | GS1: for 37/8" | GU1: ARDT REGIONAL PRICES | GV1: Woodland price | GW1: Corehead price | GX1: Category BPS | GY1: ARAMCO Product Name | GZ1: ARAMCO UID | HA1: ARAMCO Supplier Part Number | HB1: ARAMCO Contract Price | HC1: Size | HD1: ARAMCO Service Type
A2: Serial Number | B2: 13753277 | C2: =IF(COUNTIF(Instructions!$L$1,"*WFD*"),"WFD","") | D2: Modified cutters | I2: Rerun by ARDT | N2: ARDT | O2: {=IF(AND('Eng. Cutter Entry'!C4="",COUNTIF(B7,"SAUDI ARAMCO")),'Eval & Quot-AR'!Z56:AB56,IF(OR(Data!B7="ARDTS",Data!B7="Halliburton Reg.",Data!B7="Halliburton"),'Qut. HALL.'!AD54,IF('ARDT Cutter Entry'!AS111<>0,'ARDT Cutter Entry'!AS111," ")))} -> 15192 | P2: 0 | Q2: 0 | DB2: Add the cutter in list | DD2: 0 | DE2: 1165785 | DF2: 1608 PMT 0.018" | DG2: 1608 PMT 0.018" | DH2: 16 | DI2: 1608 | DJ2: PMT | DL2: 0.018" | DR2: =DI2 & " " & DJ2 & " " & DK2 -> 1608 PMT | EF2: =ROWS($DE$2:DE2) -> 1 | EG2: =IF($CY$60<>0,IF($CY$60=DE2,EF2,""),"") | EH2: =IFERROR(SMALL(EG2:EG500,ROWS($EG$2:EG2)),"") -> 9 | EJ2: =IF($CY$61<>0,IF($CY$61=DE2,EF2,""),"") | EK2: =IFERROR(SMALL(EJ2:EJ500,ROWS($EJ$2:EJ2)),"") -> 164 | EM2: =IF($CY$62<>0,IF($CY$62=DE2,EF2,""),"") | EN2: =IFERROR(SMALL(EM2:EM500,ROWS($EM$2:EM2)),"") -> 15 | EP2: =IF($CY$63<>0,IF($CY$63=DE2,EF2,""),"") | EQ2: =IFERROR(SMALL(EP2:EP500,ROWS($EP$2:EP2)),"") -> 192 | ES2: =IF($CY$64<>0,IF($CY$64=DE2,EF2,""),"") | ET2: =IFERROR(SMALL(ES2:ES500,ROWS($ES$2:ES2)),"") -> 261 | EV2: =IF($CY$65<>0,IF($CY$65=DE2,EF2,""),"") | EW2: =IFERROR(SMALL(EV2:EV500,ROWS($EV$2:EV2)),"") | EY2: =IF($CY$66<>0,IF($CY$66=DE2,EF2,""),"") | EZ2: =IFERROR(SMALL(EY2:EY500,ROWS($EY$2:EY2)),"") | FB2: =IF($CY$67<>0,IF($CY$67=DE2,EF2,""),"") | FC2: =IFERROR(SMALL(FB2:FB500,ROWS($FB$2:FB2)),"") | FE2: =IF($CY$68<>0,IF($CY$68=DE2,EF2,""),"") | FF2: =IFERROR(SMALL(FE2:FE500,ROWS($FE$2:FE2)),"") | FH2: =IF($CY$69<>0,IF($CY$69=DE2,EF2,""),"") | FI2: =IFERROR(SMALL(FH2:FH500,ROWS($FH$2:FH2)),"") | FK2: =IF($CY$70<>0, IF($CY$70=DE2, EF2, ""), "") | FL2: =IFERROR(SMALL(FK2:FK500,ROWS($FK$2:FK2)),"") | FN2: =IF($CY$71<>0, IF($CY$71=DE2, EF2, ""), "") | FO2: =IFERROR(SMALL(FN2:FN500,ROWS($FN$2:FN2)),"") | FQ2: =IF($CY$72<>0, IF($CY$72=DE2, EF2, ""), "") | FR2: =IFERROR(SMALL(FQ2:FQ500,ROWS($FQ$2:FQ2)),"") | FT2: =IF($CY$73<>0, IF($CY$73=DE2, EF2, ""), "") | FU2: =IFERROR(SMALL(FT2:FT500,ROWS($FT$2:FT2)),"") | FW2: =IF($CY$74<>0, IF($CY$74=DE2, EF2, ""), "") | FX2: =IFERROR(SMALL(FW2:FW500,ROWS($FW$2:FW2)),"") | FZ2: =IF($CY$75<>0, IF($CY$75=DE2, EF2, ""), "") | GA2: =IFERROR(SMALL(FZ2:FZ500,ROWS($FZ$2:FZ2)),"") | GC2: =IF($CY$76<>0, IF($CY$76=DE2, EF2, ""), "") | GD2: =IFERROR(SMALL(GC2:GC500,ROWS($GC$2:GC2)),"") | GG2: =IFERROR(INDEX($DE$2:$DR$500,$EH2,COLUMNS($GF$2:GF2)),"") -> 1039060 | GH2: =IFERROR(INDEX($DE$2:$DR$500,$EH2,COLUMNS($GF$2:GG2)),"") -> 1613 CT138 0.018 | GI2: =IFERROR(INDEX($DE$2:$DR$500,$EH2,COLUMNS($GF$2:GH2)),"") -> 1613 CT138 0.018" | GJ2: =IFERROR(INDEX($DE$2:$DR$500,$EH2,COLUMNS($GF$2:GI2)),"") -> 16 | GK2: =IFERROR(INDEX($DE$2:$DR$500,$EH2,COLUMNS($GF$2:GJ2)),"") -> 1613 | GL2: =IFERROR(INDEX($DE$2:$DR$500,$EH2,COLUMNS($GF$2:GK2)),"") -> CT138 | GM2: =IFERROR(INDEX($DE$2:$DR$500,$EH2,COLUMNS($GF$2:GL2)),"") -> 0 | GN2: =IFERROR(INDEX($DE$2:$DR$500,$EH2,COLUMNS($GF$2:GM2)),"") -> 0.018" | ... GP2: =IFERROR(INDEX($DE$2:$DR$500,$EH2,COLUMNS($GF$2:GO2)),"") -> 0 | GQ2: =IF($B$29=1,IFERROR(INDEX($DE$2:$DU$300,$EH2,COLUMNS($GF$2:GT2)),""),IF($B$29=2,IFERROR(INDEX($DE$2:$DU$300,$EH2,COLUMNS($GF$2:GV2)),""),IF($B$29=3,IFERROR(INDEX($DE$2:$DU$300,$EH2,COLUMNS($GF$2:GU2)),""),IF($B$29="",IFERROR(INDEX($DE$2:$DU$300,$EH2,COLUMNS($GF$2:GP2)),""),"")))) -> 497 | GR2: =IFERROR(INDEX($DE$2:$DR$500,$EH2,COLUMNS($GF$2:GQ2)),"") -> 0 | GS2: =IFERROR(INDEX($DE$2:$DR$500,$EH2,COLUMNS($GF$2:GR2)),"") -> 0 | GT2: =IFERROR(INDEX($DE$2:$EC$300,$EH2,COLUMNS($GF$2:GS2)),"") -> 1613 CT138 | GU2: =IFERROR(INDEX($DE$2:$EC$300,$EH2,COLUMNS($GF$2:GT2)),"") -> 0 | GV2: =IFERROR(INDEX($DE$2:$EC$300,$EH2,COLUMNS($GF$2:GU2)),"") -> 0 | GW2: =IFERROR(INDEX($DE$2:$EC$300,$EH2,COLUMNS($GF$2:GV2)),"") -> 0 | GX2: =IFERROR(INDEX($DE$2:$EC$300,$EH2,COLUMNS($GF$2:GW2)),"") -> S | GY2: =IFERROR(INDEX($DE$2:$EC$300,$EH2,COLUMNS($GF$2:GX2)),"") -> 6.4.1 | GZ2: =IFERROR(INDEX($DE$2:$EC$300,$EH2,COLUMNS($GF$2:GY2)),"") -> 30 | HA2: =IFERROR(INDEX($DE$2:$EC$300,$EH2,COLUMNS($GF$2:GZ2)),"") -> 16mm Cutter Replacement Super Premium | ... HE2: =IFERROR(INDEX($DE$2:$EC$300,$EH2,COLUMNS($GF$2:HD2)),"") -> 662 | HI2: =IF($CY$60<>0,IF($CY$60=DE2,EF2,""),"")
A3: Size | B3: 8 3/8" | D3: # | E3: Qty | F3: Cutter part # | G3: To Replace Cutter # | I3: Rerun by Engineer | N3: ENGINEER | O3: {=IF(AND('Eng. Cutter Entry'!C4<>"",COUNTIF(B7,"SAUDI ARAMCO")),'Eval & Quot-AR'!Z56:AB56,IF(OR(Data!B7="ARDTS",Data!B7="Halliburton Reg.",Data!B7="Halliburton"),0,IF('ARDT Cutter Entry'!AS112<>0,'ARDT Cutter Entry'!AS112," ")))} | DB3: 1039058 | DD3: 0 | DE3: 1163816 | DF3: 1010 CT156 0.018" | DG3: 1010 CT156 0.018" | DH3: 10 | DI3: 1010 | DJ3: CT156 | DL3: 0.018" | EF3: =ROWS($DE$2:DE3) -> 2 | EG3: =IF($CY$60<>0,IF($CY$60=DE3,EF3,""),"") | EJ3: =IF($CY$61<>0,IF($CY$61=DE3,EF3,""),"") | EM3: =IF($CY$62<>0,IF($CY$62=DE3,EF3,""),"") | EP3: =IF($CY$63<>0,IF($CY$63=DE3,EF3,""),"") | ES3: =IF($CY$64<>0,IF($CY$64=DE3,EF3,""),"") | EV3: =IF($CY$65<>0,IF($CY$65=DE3,EF3,""),"") | EY3: =IF($CY$66<>0,IF($CY$66=DE3,EF3,""),"") | FB3: =IF($CY$67<>0,IF($CY$67=DE3,EF3,""),"") | FE3: =IF($CY$68<>0,IF($CY$68=DE3,EF3,""),"") | FH3: =IF($CY$69<>0,IF($CY$69=DE3,EF3,""),"") | FK3: =IF($CY$70<>0, IF($CY$70=DE3, EF3, ""), "") | FN3: =IF($CY$71<>0, IF($CY$71=DE3, EF3, ""), "") | FQ3: =IF($CY$72<>0, IF($CY$72=DE3, EF3, ""), "") | FT3: =IF($CY$73<>0, IF($CY$73=DE3, EF3, ""), "") | FW3: =IF($CY$74<>0, IF($CY$74=DE3, EF3, ""), "") | FZ3: =IF($CY$75<>0, IF($CY$75=DE3, EF3, ""), "") | GC3: =IF($CY$76<>0, IF($CY$76=DE3, EF3, ""), "") | GG3: =IFERROR(INDEX($DE$2:$DR$500,$EK2,COLUMNS($GF$2:GF2)),"") -> 1130197 | GH3: =IFERROR(INDEX($DE$2:$DR$500,$EK2,COLUMNS($GF$2:GG2)),"") -> 1608 CT182 0.018" | GI3: =IFERROR(INDEX($DE$2:$DR$500,$EK2,COLUMNS($GF$2:GH2)),"") -> 1608 CT182 0.018" | GJ3: =IFERROR(INDEX($DE$2:$DR$500,$EK2,COLUMNS($GF$2:GI2)),"") -> 16 | GK3: =IFERROR(INDEX($DE$2:$DR$500,$EK2,COLUMNS($GF$2:GJ2)),"") -> 1608 | GL3: =IFERROR(INDEX($DE$2:$DR$500,$EK2,COLUMNS($GF$2:GK2)),"") -> CT182 | GM3: =IFERROR(INDEX($DE$2:$DR$500,$EK2,COLUMNS($GF$2:GL2)),"") -> 0 | GN3: =IFERROR(INDEX($DE$2:$DR$500,$EK2,COLUMNS($GF$2:GM2)),"") -> 0.018 | ... GP3: =IFERROR(INDEX($DE$2:$DR$500,$EK2,COLUMNS($GF$2:GO2)),"") -> 0 | GQ3: =IF($B$29=1,IFERROR(INDEX($DE$2:$DU$300,$EK2,COLUMNS($GF$2:GT2)),""),IF($B$29=2,IFERROR(INDEX($DE$2:$DU$300,$EK2,COLUMNS($GF$2:GV2)),""),IF($B$29=3,IFERROR(INDEX($DE$2:$DU$300,$EK2,COLUMNS($GF$2:GU2)),""),IF($B$29="",IFERROR(INDEX($DE$2:$DU$300,$EK2,COLUMNS($GF$2:GP2)),""),"")))) -> 497 | GR3: =IFERROR(INDEX($DE$2:$DR$500,$EK2,COLUMNS($GF$2:GQ2)),"") -> 0 | GS3: =IFERROR(INDEX($DE$2:$DR$500,$EK2,COLUMNS($GF$2:GR2)),"") -> 0 | GT3: =IFERROR(INDEX($DE$2:$EC$300,$EK2,COLUMNS($GF$2:GS2)),"") -> 1608 CT182 | GU3: =IFERROR(INDEX($DE$2:$EC$300,$EK2,COLUMNS($GF$2:GT2)),"") -> 0 | GV3: =IFERROR(INDEX($DE$2:$EC$300,$EK2,COLUMNS($GF$2:GU2)),"") -> 0 | GW3: =IFERROR(INDEX($DE$2:$EC$300,$EK2,COLUMNS($GF$2:GV2)),"") -> 0 | GX3: =IFERROR(INDEX($DE$2:$EC$300,$EK2,COLUMNS($GF$2:GW2)),"") -> S | GY3: =IFERROR(INDEX($DE$2:$EC$300,$EK2,COLUMNS($GF$2:GX2)),"") -> 6.4.1 | GZ3: =IFERROR(INDEX($DE$2:$EC$300,$EK2,COLUMNS($GF$2:GY2)),"") -> 30 | HA3: =IFERROR(INDEX($DE$2:$EC$300,$EK2,COLUMNS($GF$2:GZ2)),"") -> 16mm Cutter Replacement Super Premium | ... HE3: =IFERROR(INDEX($DE$2:$EC$300,$EK2,COLUMNS($GF$2:HD2)),"") -> 662
A4: Type | B4: MM65DH | D4: =IF(F4="","",IF(MAX(BI46:BI62)<>0,MAX(BI46:BI62)+1,"")) -> 4 | E4: 6 | F4: 643738 | G4: 2 | I4: Initial Bit Inspection | N4: RECLAIM | O4: =IF(COUNTIF(B7,"SAUDI ARAMCO"),"",IF(OR(Data!B7="ARDTS",Data!B7="Halliburton Reg.",Data!B7="Halliburton"),0,IF('Eng. Cutter Entry'!C4<>"",IF('ARDT Cutter Entry'!AS113<>"",'ARDT Cutter Entry'!AS113,""),IF(Quotation!Y58=O2,"",Quotation!Y58)))) | DB4: 1039060 | DD4: 0 | DE4: 1163818 | DF4: 1313 CT156 0.018" | DG4: 1313 CT156 0.018" | DH4: 13 | DI4: 1313 | DJ4: CT156 | DL4: 0.018" | EF4: =ROWS($DE$2:DE4) -> 3 | EG4: =IF($CY$60<>0,IF($CY$60=DE4,EF4,""),"") | EJ4: =IF($CY$61<>0,IF($CY$61=DE4,EF4,""),"") | EM4: =IF($CY$62<>0,IF($CY$62=DE4,EF4,""),"") | EP4: =IF($CY$63<>0,IF($CY$63=DE4,EF4,""),"") | ES4: =IF($CY$64<>0,IF($CY$64=DE4,EF4,""),"") | EV4: =IF($CY$65<>0,IF($CY$65=DE4,EF4,""),"") | EY4: =IF($CY$66<>0,IF($CY$66=DE4,EF4,""),"") | FB4: =IF($CY$67<>0,IF($CY$67=DE4,EF4,""),"") | FE4: =IF($CY$68<>0,IF($CY$68=DE4,EF4,""),"") | FH4: =IF($CY$69<>0,IF($CY$69=DE4,EF4,""),"") | FK4: =IF($CY$70<>0, IF($CY$70=DE4, EF4, ""), "") | FN4: =IF($CY$71<>0, IF($CY$71=DE4, EF4, ""), "") | FQ4: =IF($CY$72<>0, IF($CY$72=DE4, EF4, ""), "") | FT4: =IF($CY$73<>0, IF($CY$73=DE4, EF4, ""), "") | FW4: =IF($CY$74<>0, IF($CY$74=DE4, EF4, ""), "") | FZ4: =IF($CY$75<>0, IF($CY$75=DE4, EF4, ""), "") | GC4: =IF($CY$76<>0, IF($CY$76=DE4, EF4, ""), "") | GG4: =IFERROR(INDEX($DE$2:$DR$500,$EN2,COLUMNS($GF$2:GF2)),"") -> 418525 | GH4: =IFERROR(INDEX($DE$2:$DR$500,$EN2,COLUMNS($GF$2:GG2)),"") -> 1308 CT31 Drop in | GI4: =IFERROR(INDEX($DE$2:$DR$500,$EN2,COLUMNS($GF$2:GH2)),"") -> 1308 CT31 Drop in | GJ4: =IFERROR(INDEX($DE$2:$DR$500,$EN2,COLUMNS($GF$2:GI2)),"") -> 13 | GK4: =IFERROR(INDEX($DE$2:$DR$500,$EN2,COLUMNS($GF$2:GJ2)),"") -> 1308 | GL4: =IFERROR(INDEX($DE$2:$DR$500,$EN2,COLUMNS($GF$2:GK2)),"") -> CT31 | GM4: =IFERROR(INDEX($DE$2:$DR$500,$EN2,COLUMNS($GF$2:GL2)),"") -> Drop in | GN4: =IFERROR(INDEX($DE$2:$DR$500,$EN2,COLUMNS($GF$2:GM2)),"") -> 0 | ... GP4: =IFERROR(INDEX($DE$2:$DR$500,$EN2,COLUMNS($GF$2:GO2)),"") -> 0 | GQ4: =IF($B$29=1,IFERROR(INDEX($DE$2:$DU$300,$EN2,COLUMNS($GF$2:GT2)),""),IF($B$29=2,IFERROR(INDEX($DE$2:$DU$300,$EN2,COLUMNS($GF$2:GV2)),""),IF($B$29=3,IFERROR(INDEX($DE$2:$DU$300,$EN2,COLUMNS($GF$2:GU2)),""),IF($B$29="",IFERROR(INDEX($DE$2:$DU$300,$EN2,COLUMNS($GF$2:GP2)),""),"")))) -> 100 | GR4: =IFERROR(INDEX($DE$2:$DR$500,$EN2,COLUMNS($GF$2:GQ2)),"") -> 0 | GS4: =IFERROR(INDEX($DE$2:$DR$500,$EN2,COLUMNS($GF$2:GR2)),"") -> 0 | GT4: =IFERROR(INDEX($DE$2:$EC$300,$EN2,COLUMNS($GF$2:GS2)),"") -> 1308 CT31 Drop in | GU4: =IFERROR(INDEX($DE$2:$EC$300,$EN2,COLUMNS($GF$2:GT2)),"") -> 26.981067 | GV4: =IFERROR(INDEX($DE$2:$EC$300,$EN2,COLUMNS($GF$2:GU2)),"") -> 20.754667 | GW4: =IFERROR(INDEX($DE$2:$EC$300,$EN2,COLUMNS($GF$2:GV2)),"") -> 100 | GX4: =IFERROR(INDEX($DE$2:$EC$300,$EN2,COLUMNS($GF$2:GW2)),"") -> B | GY4: =IFERROR(INDEX($DE$2:$EC$300,$EN2,COLUMNS($GF$2:GX2)),"") -> 6.3.1 | GZ4: =IFERROR(INDEX($DE$2:$EC$300,$EN2,COLUMNS($GF$2:GY2)),"") -> 10 | HA4: =IFERROR(INDEX($DE$2:$EC$300,$EN2,COLUMNS($GF$2:GZ2)),"") -> 13mm Cutter Replacement Standard | ... HE4: =IFERROR(INDEX($DE$2:$EC$300,$EN2,COLUMNS($GF$2:HD2)),"") -> 345
A5: LV5 Mat # | B5: 1061407M | C5: =IF(F4<>"",IF(COUNTIF(B5,"*M*"),"","Add M"),"") | D5: =IF(F5="","",IFERROR(D4+1,"")) -> 5 | E5: 21 | F5: 1126402 | G5: 1 | I5: Scrap | N5: Rework | O5: =IF(COUNTIF(B7,"SAUDI ARAMCO"),"",IF(OR(Data!B7="ARDTS",Data!B7="Halliburton Reg.",Data!B7="Halliburton"),0,IF(L9<>"",IF('ARDT Cutter Entry'!AS114<>0,'ARDT Cutter Entry'!AS114," "),""))) | DB5: 1039064 | DD5: 0 | DE5: 1100695 | DF5: 1308 CT418 0.018" | DG5: 1308 CT418 0.018" | DH5: 13 | DI5: 1308 | DJ5: CT418 | DL5: 0.018" | EF5: =ROWS($DE$2:DE5) -> 4 | EG5: =IF($CY$60<>0,IF($CY$60=DE5,EF5,""),"") | EJ5: =IF($CY$61<>0,IF($CY$61=DE5,EF5,""),"") | EM5: =IF($CY$62<>0,IF($CY$62=DE5,EF5,""),"") | EP5: =IF($CY$63<>0,IF($CY$63=DE5,EF5,""),"") | ES5: =IF($CY$64<>0,IF($CY$64=DE5,EF5,""),"") | EV5: =IF($CY$65<>0,IF($CY$65=DE5,EF5,""),"") | EY5: =IF($CY$66<>0,IF($CY$66=DE5,EF5,""),"") | FB5: =IF($CY$67<>0,IF($CY$67=DE5,EF5,""),"") | FE5: =IF($CY$68<>0,IF($CY$68=DE5,EF5,""),"") | FH5: =IF($CY$69<>0,IF($CY$69=DE5,EF5,""),"") | FK5: =IF($CY$70<>0, IF($CY$70=DE5, EF5, ""), "") | FN5: =IF($CY$71<>0, IF($CY$71=DE5, EF5, ""), "") | FQ5: =IF($CY$72<>0, IF($CY$72=DE5, EF5, ""), "") | FT5: =IF($CY$73<>0, IF($CY$73=DE5, EF5, ""), "") | FW5: =IF($CY$74<>0, IF($CY$74=DE5, EF5, ""), "") | FZ5: =IF($CY$75<>0, IF($CY$75=DE5, EF5, ""), "") | GC5: =IF($CY$76<>0, IF($CY$76=DE5, EF5, ""), "") | GG5: =IFERROR(INDEX($DE$2:$DR$500,$EQ2,COLUMNS($GF$2:GF2)),"") -> 643738 | GH5: =IFERROR(INDEX($DE$2:$DR$500,$EQ2,COLUMNS($GF$2:GG2)),"") -> 1608 CT70 0.018" | GI5: =IFERROR(INDEX($DE$2:$DR$500,$EQ2,COLUMNS($GF$2:GH2)),"") -> 1608 CT70 0.018" | GJ5: =IFERROR(INDEX($DE$2:$DR$500,$EQ2,COLUMNS($GF$2:GI2)),"") -> 16 | GK5: =IFERROR(INDEX($DE$2:$DR$500,$EQ2,COLUMNS($GF$2:GJ2)),"") -> 1608 | GL5: =IFERROR(INDEX($DE$2:$DR$500,$EQ2,COLUMNS($GF$2:GK2)),"") -> CT70 | GM5: =IFERROR(INDEX($DE$2:$DR$500,$EQ2,COLUMNS($GF$2:GL2)),"") -> 0 | GN5: =IFERROR(INDEX($DE$2:$DR$500,$EQ2,COLUMNS($GF$2:GM2)),"") -> 0.018" | ... GP5: =IFERROR(INDEX($DE$2:$DR$500,$EQ2,COLUMNS($GF$2:GO2)),"") -> 0 | GQ5: =IF($B$29=1,IFERROR(INDEX($DE$2:$DU$300,$EQ2,COLUMNS($GF$2:GT2)),""),IF($B$29=2,IFERROR(INDEX($DE$2:$DU$300,$EQ2,COLUMNS($GF$2:GV2)),""),IF($B$29=3,IFERROR(INDEX($DE$2:$DU$300,$EQ2,COLUMNS($GF$2:GU2)),""),IF($B$29="",IFERROR(INDEX($DE$2:$DU$300,$EQ2,COLUMNS($GF$2:GP2)),""),"")))) -> 497 | GR5: =IFERROR(INDEX($DE$2:$DR$500,$EQ2,COLUMNS($GF$2:GQ2)),"") -> 0 | GS5: =IFERROR(INDEX($DE$2:$DR$500,$EQ2,COLUMNS($GF$2:GR2)),"") -> 0 | GT5: =IFERROR(INDEX($DE$2:$EC$300,$EQ2,COLUMNS($GF$2:GS2)),"") -> 1608 CT70 | GU5: =IFERROR(INDEX($DE$2:$EC$300,$EQ2,COLUMNS($GF$2:GT2)),"") -> 0 | GV5: =IFERROR(INDEX($DE$2:$EC$300,$EQ2,COLUMNS($GF$2:GU2)),"") -> 0 | GW5: =IFERROR(INDEX($DE$2:$EC$300,$EQ2,COLUMNS($GF$2:GV2)),"") -> 0 | GX5: =IFERROR(INDEX($DE$2:$EC$300,$EQ2,COLUMNS($GF$2:GW2)),"") -> S | GY5: =IFERROR(INDEX($DE$2:$EC$300,$EQ2,COLUMNS($GF$2:GX2)),"") -> 6.4.1 | GZ5: =IFERROR(INDEX($DE$2:$EC$300,$EQ2,COLUMNS($GF$2:GY2)),"") -> 30 | HA5: =IFERROR(INDEX($DE$2:$EC$300,$EQ2,COLUMNS($GF$2:GZ2)),"") -> 16mm Cutter Replacement Super Premium | ... HE5: =IFERROR(INDEX($DE$2:$EC$300,$EQ2,COLUMNS($GF$2:HD2)),"") -> 662
A6: Bit Date Received (MM/DD/YYYY) | B6: 46002 | D6: =IF(F6="","",IFERROR(D5+1,"")) | I6: Approved for Quot: 1 OK, 2 NOT OK | DB6: 177778 | DD6: 0 | DE6: 1217967 | DF6: 1308 CT158 0.010" | DG6: 1308 CT158 0.010" | DH6: 13 | DI6: 1308 | DJ6: CT158 | DL6: 0.010" | EF6: =ROWS($DE$2:DE6) -> 5 | EG6: =IF($CY$60<>0,IF($CY$60=DE6,EF6,""),"") | EJ6: =IF($CY$61<>0,IF($CY$61=DE6,EF6,""),"") | EM6: =IF($CY$62<>0,IF($CY$62=DE6,EF6,""),"") | EP6: =IF($CY$63<>0,IF($CY$63=DE6,EF6,""),"") | ES6: =IF($CY$64<>0,IF($CY$64=DE6,EF6,""),"") | EV6: =IF($CY$65<>0,IF($CY$65=DE6,EF6,""),"") | EY6: =IF($CY$66<>0,IF($CY$66=DE6,EF6,""),"") | FB6: =IF($CY$67<>0,IF($CY$67=DE6,EF6,""),"") | FE6: =IF($CY$68<>0,IF($CY$68=DE6,EF6,""),"") | FH6: =IF($CY$69<>0,IF($CY$69=DE6,EF6,""),"") | FK6: =IF($CY$70<>0, IF($CY$70=DE6, EF6, ""), "") | FN6: =IF($CY$71<>0, IF($CY$71=DE6, EF6, ""), "") | FQ6: =IF($CY$72<>0, IF($CY$72=DE6, EF6, ""), "") | FT6: =IF($CY$73<>0, IF($CY$73=DE6, EF6, ""), "") | FW6: =IF($CY$74<>0, IF($CY$74=DE6, EF6, ""), "") | FZ6: =IF($CY$75<>0, IF($CY$75=DE6, EF6, ""), "") | GC6: =IF($CY$76<>0, IF($CY$76=DE6, EF6, ""), "") | GG6: =IFERROR(INDEX($DE$2:$DR$500,$ET2,COLUMNS($GF$2:GF2)),"") -> 1126402 | GH6: =IFERROR(INDEX($DE$2:$DR$500,$ET2,COLUMNS($GF$2:GG2)),"") -> 1613 CT421 18-60 | GI6: =IFERROR(INDEX($DE$2:$DR$500,$ET2,COLUMNS($GF$2:GH2)),"") -> 1613 CT421 18-60 | GJ6: =IFERROR(INDEX($DE$2:$DR$500,$ET2,COLUMNS($GF$2:GI2)),"") -> 16 | GK6: =IFERROR(INDEX($DE$2:$DR$500,$ET2,COLUMNS($GF$2:GJ2)),"") -> 1613 | GL6: =IFERROR(INDEX($DE$2:$DR$500,$ET2,COLUMNS($GF$2:GK2)),"") -> CT421 | GM6: =IFERROR(INDEX($DE$2:$DR$500,$ET2,COLUMNS($GF$2:GL2)),"") -> 0 | GN6: =IFERROR(INDEX($DE$2:$DR$500,$ET2,COLUMNS($GF$2:GM2)),"") -> 18-60 | ... GP6: =IFERROR(INDEX($DE$2:$DR$500,$ET2,COLUMNS($GF$2:GO2)),"") -> 0 | GQ6: =IF($B$29=1,IFERROR(INDEX($DE$2:$DU$300,$ET2,COLUMNS($GF$2:GT2)),""),IF($B$29=2,IFERROR(INDEX($DE$2:$DU$300,$ET2,COLUMNS($GF$2:GV2)),""),IF($B$29=3,IFERROR(INDEX($DE$2:$DU$300,$ET2,COLUMNS($GF$2:GU2)),""),IF($B$29="",IFERROR(INDEX($DE$2:$DU$300,$ET2,COLUMNS($GF$2:GP2)),""),"")))) -> 497 | GR6: =IFERROR(INDEX($DE$2:$DR$500,$ET2,COLUMNS($GF$2:GQ2)),"") -> 0 | GS6: =IFERROR(INDEX($DE$2:$DR$500,$ET2,COLUMNS($GF$2:GR2)),"") -> 0 | GT6: =IFERROR(INDEX($DE$2:$EC$300,$ET2,COLUMNS($GF$2:GS2)),"") -> 1613 CT421 | GU6: =IFERROR(INDEX($DE$2:$EC$300,$ET2,COLUMNS($GF$2:GT2)),"") -> 0 | GV6: =IFERROR(INDEX($DE$2:$EC$300,$ET2,COLUMNS($GF$2:GU2)),"") -> 0 | GW6: =IFERROR(INDEX($DE$2:$EC$300,$ET2,COLUMNS($GF$2:GV2)),"") -> 0 | GX6: =IFERROR(INDEX($DE$2:$EC$300,$ET2,COLUMNS($GF$2:GW2)),"") -> 0 | GY6: =IFERROR(INDEX($DE$2:$EC$300,$ET2,COLUMNS($GF$2:GX2)),"") -> 0 | GZ6: =IFERROR(INDEX($DE$2:$EC$300,$ET2,COLUMNS($GF$2:GY2)),"") -> 0 | HA6: =IFERROR(INDEX($DE$2:$EC$300,$ET2,COLUMNS($GF$2:GZ2)),"") -> 0 | ... HE6: =IFERROR(INDEX($DE$2:$EC$300,$ET2,COLUMNS($GF$2:HD2)),"") -> 0
A7: From | B7: SAUDI ARAMCO | D7: =IF(F7="","",IFERROR(D6+1,"")) | I7: =IF(COUNTIF(Data!B4,"S*"),"ARDT Hardfacing","ARDT Matrix Build up") -> ARDT Matrix Build up | M7: ARAMCO BIT SETUP CHARGE TYPE | O7: 7"-8 7/8" Matrix Body PDC Bit Set-up Charge | DB7: 375538 | DD7: 0 | DE7: 107348 | DF7: OBS 13MM STEEL R3 CT221 | DG7: OBS 13MM STEEL R3 CT221 | DH7: 13 | DI7: 13 | DJ7: CT221 | EF7: =ROWS($DE$2:DE7) -> 6 | EG7: =IF($CY$60<>0,IF($CY$60=DE7,EF7,""),"") | EJ7: =IF($CY$61<>0,IF($CY$61=DE7,EF7,""),"") | EM7: =IF($CY$62<>0,IF($CY$62=DE7,EF7,""),"") | EP7: =IF($CY$63<>0,IF($CY$63=DE7,EF7,""),"") | ES7: =IF($CY$64<>0,IF($CY$64=DE7,EF7,""),"") | EV7: =IF($CY$65<>0,IF($CY$65=DE7,EF7,""),"") | EY7: =IF($CY$66<>0,IF($CY$66=DE7,EF7,""),"") | FB7: =IF($CY$67<>0,IF($CY$67=DE7,EF7,""),"") | FE7: =IF($CY$68<>0,IF($CY$68=DE7,EF7,""),"") | FH7: =IF($CY$69<>0,IF($CY$69=DE7,EF7,""),"") | FK7: =IF($CY$70<>0, IF($CY$70=DE7, EF7, ""), "") | FN7: =IF($CY$71<>0, IF($CY$71=DE7, EF7, ""), "") | FQ7: =IF($CY$72<>0, IF($CY$72=DE7, EF7, ""), "") | FT7: =IF($CY$73<>0, IF($CY$73=DE7, EF7, ""), "") | FW7: =IF($CY$74<>0, IF($CY$74=DE7, EF7, ""), "") | FZ7: =IF($CY$75<>0, IF($CY$75=DE7, EF7, ""), "") | GC7: =IF($CY$76<>0, IF($CY$76=DE7, EF7, ""), "") | GG7: =IFERROR(INDEX($DE$2:$DR$500,$EW2,COLUMNS($GF$2:GF2)),"") | GH7: =IFERROR(INDEX($DE$2:$DR$500,$EW2,COLUMNS($GF$2:GG2)),"") | GI7: =IFERROR(INDEX($DE$2:$DR$500,$EW2,COLUMNS($GF$2:GH2)),"") | GJ7: =IFERROR(INDEX($DE$2:$DR$500,$EW2,COLUMNS($GF$2:GI2)),"") | GK7: =IFERROR(INDEX($DE$2:$DR$500,$EW2,COLUMNS($GF$2:GJ2)),"") | GL7: =IFERROR(INDEX($DE$2:$DR$500,$EW2,COLUMNS($GF$2:GK2)),"") | GM7: =IFERROR(INDEX($DE$2:$DR$500,$EW2,COLUMNS($GF$2:GL2)),"") | GN7: =IFERROR(INDEX($DE$2:$DR$500,$EW2,COLUMNS($GF$2:GM2)),"") | ... GP7: =IFERROR(INDEX($DE$2:$DR$500,$EW2,COLUMNS($GF$2:GO2)),"") | GQ7: =IF($B$29=1,IFERROR(INDEX($DE$2:$DU$300,$EW2,COLUMNS($GF$2:GT2)),""),IF($B$29=2,IFERROR(INDEX($DE$2:$DU$300,$EW2,COLUMNS($GF$2:GV2)),""),IF($B$29=3,IFERROR(INDEX($DE$2:$DU$300,$EW2,COLUMNS($GF$2:GU2)),""),IF($B$29="",IFERROR(INDEX($DE$2:$DU$300,$EW2,COLUMNS($GF$2:GP2)),""),"")))) | GR7: =IFERROR(INDEX($DE$2:$DR$500,$EW2,COLUMNS($GF$2:GQ2)),"") | GS7: =IFERROR(INDEX($DE$2:$DR$500,$EW2,COLUMNS($GF$2:GR2)),"") | GT7: =IFERROR(INDEX($DE$2:$EC$300,$EW2,COLUMNS($GF$2:GS2)),"") | GU7: =IFERROR(INDEX($DE$2:$EC$300,$EW2,COLUMNS($GF$2:GT2)),"") | GV7: =IFERROR(INDEX($DE$2:$EC$300,$EW2,COLUMNS($GF$2:GU2)),"") | GW7: =IFERROR(INDEX($DE$2:$EC$300,$EW2,COLUMNS($GF$2:GV2)),"") | GX7: =IFERROR(INDEX($DE$2:$EC$300,$EW2,COLUMNS($GF$2:GW2)),"") | GY7: =IFERROR(INDEX($DE$2:$EC$300,$EW2,COLUMNS($GF$2:GX2)),"") | GZ7: =IFERROR(INDEX($DE$2:$EC$300,$EW2,COLUMNS($GF$2:GY2)),"") | HA7: =IFERROR(INDEX($DE$2:$EC$300,$EW2,COLUMNS($GF$2:GZ2)),"") | ... HE7: =IFERROR(INDEX($DE$2:$EC$300,$EW2,COLUMNS($GF$2:HD2)),"")
A8: LV3 or LV4 Mat # | D8: =IF(F8="","",IFERROR(D7+1,"")) | I8: =IF(COUNTIF(Data!B4,"S*"),"Engineer Hardfacing","Engineer Matrix Build up") -> Engineer Matrix Build up | M8: Additional ARAMCO Remark | DB8: 376826 | DD8: 0 | DE8: 1165788 | DF8: 1913 PMT 0.018" | DG8: 1913 PMT 0.018" | DH8: 19 | DI8: 1913 | DJ8: PMT | DL8: 0.018" | EF8: =ROWS($DE$2:DE8) -> 7 | EG8: =IF($CY$60<>0,IF($CY$60=DE8,EF8,""),"") | EJ8: =IF($CY$61<>0,IF($CY$61=DE8,EF8,""),"") | EM8: =IF($CY$62<>0,IF($CY$62=DE8,EF8,""),"") | EP8: =IF($CY$63<>0,IF($CY$63=DE8,EF8,""),"") | ES8: =IF($CY$64<>0,IF($CY$64=DE8,EF8,""),"") | EV8: =IF($CY$65<>0,IF($CY$65=DE8,EF8,""),"") | EY8: =IF($CY$66<>0,IF($CY$66=DE8,EF8,""),"") | FB8: =IF($CY$67<>0,IF($CY$67=DE8,EF8,""),"") | FE8: =IF($CY$68<>0,IF($CY$68=DE8,EF8,""),"") | FH8: =IF($CY$69<>0,IF($CY$69=DE8,EF8,""),"") | FK8: =IF($CY$70<>0, IF($CY$70=DE8, EF8, ""), "") | FN8: =IF($CY$71<>0, IF($CY$71=DE8, EF8, ""), "") | FQ8: =IF($CY$72<>0, IF($CY$72=DE8, EF8, ""), "") | FT8: =IF($CY$73<>0, IF($CY$73=DE8, EF8, ""), "") | FW8: =IF($CY$74<>0, IF($CY$74=DE8, EF8, ""), "") | FZ8: =IF($CY$75<>0, IF($CY$75=DE8, EF8, ""), "") | GC8: =IF($CY$76<>0, IF($CY$76=DE8, EF8, ""), "") | GG8: =IFERROR(INDEX($DE$2:$DR$500,$EZ2,COLUMNS($GF$2:GF2)),"") | GH8: =IFERROR(INDEX($DE$2:$DR$500,$EZ2,COLUMNS($GF$2:GG2)),"") | GI8: =IFERROR(INDEX($DE$2:$DR$500,$EZ2,COLUMNS($GF$2:GH2)),"") | GJ8: =IFERROR(INDEX($DE$2:$DR$500,$EZ2,COLUMNS($GF$2:GI2)),"") | GK8: =IFERROR(INDEX($DE$2:$DR$500,$EZ2,COLUMNS($GF$2:GJ2)),"") | GL8: =IFERROR(INDEX($DE$2:$DR$500,$EZ2,COLUMNS($GF$2:GK2)),"") | GM8: =IFERROR(INDEX($DE$2:$DR$500,$EZ2,COLUMNS($GF$2:GL2)),"") | GN8: =IFERROR(INDEX($DE$2:$DR$500,$EZ2,COLUMNS($GF$2:GM2)),"") | ... GP8: =IFERROR(INDEX($DE$2:$DR$500,$EZ2,COLUMNS($GF$2:GO2)),"") | GQ8: =IF($B$29=1,IFERROR(INDEX($DE$2:$DU$300,$EZ2,COLUMNS($GF$2:GT2)),""),IF($B$29=2,IFERROR(INDEX($DE$2:$DU$300,$EZ2,COLUMNS($GF$2:GV2)),""),IF($B$29=3,IFERROR(INDEX($DE$2:$DU$300,$EZ2,COLUMNS($GF$2:GU2)),""),IF($B$29="",IFERROR(INDEX($DE$2:$DU$300,$EZ2,COLUMNS($GF$2:GP2)),""),"")))) | GR8: =IFERROR(INDEX($DE$2:$DR$500,$EZ2,COLUMNS($GF$2:GQ2)),"") | GS8: =IFERROR(INDEX($DE$2:$DR$500,$EZ2,COLUMNS($GF$2:GR2)),"") | GT8: =IFERROR(INDEX($DE$2:$EC$300,$EZ2,COLUMNS($GF$2:GS2)),"") | GU8: =IFERROR(INDEX($DE$2:$EC$300,$EZ2,COLUMNS($GF$2:GT2)),"") | GV8: =IFERROR(INDEX($DE$2:$EC$300,$EZ2,COLUMNS($GF$2:GU2)),"") | GW8: =IFERROR(INDEX($DE$2:$EC$300,$EZ2,COLUMNS($GF$2:GV2)),"") | GX8: =IFERROR(INDEX($DE$2:$EC$300,$EZ2,COLUMNS($GF$2:GW2)),"") | GY8: =IFERROR(INDEX($DE$2:$EC$300,$EZ2,COLUMNS($GF$2:GX2)),"") | GZ8: =IFERROR(INDEX($DE$2:$EC$300,$EZ2,COLUMNS($GF$2:GY2)),"") | HA8: =IFERROR(INDEX($DE$2:$EC$300,$EZ2,COLUMNS($GF$2:GZ2)),"") | ... HE8: =IFERROR(INDEX($DE$2:$EC$300,$EZ2,COLUMNS($GF$2:HD2)),"")
A9: LV3 or LV4 Remark | I9: Add charge for rework | DB9: 399930 | DD9: 69 | DE9: 1039058 | DF9: 1608 CT138 0.018 | DG9: =DR9 & " " & DL9 -> 1608 CT138 0.018" | DH9: 16 | DI9: 1608 | DJ9: CT138 | DL9: 0.018" | DM9: 11 | DN9: 0 | DO9: 497 | DR9: =DI9 & " " & DJ9 & " " & DK9 -> 1608 CT138 | DV9: S | DW9: 6.4.1 | DX9: 30 | DY9: 16mm Cutter Replacement Super Premium | DZ9: 16mm | EA9: 1 | EB9: EA | EC9: 662 | ED9: 6.4.1 30 | EE9: =SUMIF($G$12:$G$21,$DE9,$E$12:$E$21) -> 0 | EF9: =ROWS($DE$2:DE9) -> 8 | EG9: =IF($CY$60<>0,IF($CY$60=DE9,EF9,""),"") | EJ9: =IF($CY$61<>0,IF($CY$61=DE9,EF9,""),"") | EM9: =IF($CY$62<>0,IF($CY$62=DE9,EF9,""),"") | EP9: =IF($CY$63<>0,IF($CY$63=DE9,EF9,""),"") | ES9: =IF($CY$64<>0,IF($CY$64=DE9,EF9,""),"") | EV9: =IF($CY$65<>0,IF($CY$65=DE9,EF9,""),"") | EY9: =IF($CY$66<>0,IF($CY$66=DE9,EF9,""),"") | FB9: =IF($CY$67<>0,IF($CY$67=DE9,EF9,""),"") | FE9: =IF($CY$68<>0,IF($CY$68=DE9,EF9,""),"") | FH9: =IF($CY$69<>0,IF($CY$69=DE9,EF9,""),"") | FK9: =IF($CY$70<>0, IF($CY$70=DE9, EF9, ""), "") | FN9: =IF($CY$71<>0, IF($CY$71=DE9, EF9, ""), "") | FQ9: =IF($CY$72<>0, IF($CY$72=DE9, EF9, ""), "") | FT9: =IF($CY$73<>0, IF($CY$73=DE9, EF9, ""), "") | FW9: =IF($CY$74<>0, IF($CY$74=DE9, EF9, ""), "") | FZ9: =IF($CY$75<>0, IF($CY$75=DE9, EF9, ""), "") | GC9: =IF($CY$76<>0, IF($CY$76=DE9, EF9, ""), "") | GG9: =IFERROR(INDEX($DE$2:$DR$500,$FC2,COLUMNS($GF$2:GF2)),"") | GH9: =IFERROR(INDEX($DE$2:$DR$500,$FC2,COLUMNS($GF$2:GG2)),"") | GI9: =IFERROR(INDEX($DE$2:$DR$500,$FC2,COLUMNS($GF$2:GH2)),"") | GJ9: =IFERROR(INDEX($DE$2:$DR$500,$FC2,COLUMNS($GF$2:GI2)),"") | GK9: =IFERROR(INDEX($DE$2:$DR$500,$FC2,COLUMNS($GF$2:GJ2)),"") | GL9: =IFERROR(INDEX($DE$2:$DR$500,$FC2,COLUMNS($GF$2:GK2)),"") | GM9: =IFERROR(INDEX($DE$2:$DR$500,$FC2,COLUMNS($GF$2:GL2)),"") | GN9: =IFERROR(INDEX($DE$2:$DR$500,$FC2,COLUMNS($GF$2:GM2)),"") | ... GP9: =IFERROR(INDEX($DE$2:$DR$500,$FC2,COLUMNS($GF$2:GO2)),"") | GQ9: =IF($B$29=1,IFERROR(INDEX($DE$2:$DU$300,$FC2,COLUMNS($GF$2:GT2)),""),IF($B$29=2,IFERROR(INDEX($DE$2:$DU$300,$FC2,COLUMNS($GF$2:GV2)),""),IF($B$29=3,IFERROR(INDEX($DE$2:$DU$300,$FC2,COLUMNS($GF$2:GU2)),""),IF($B$29="",IFERROR(INDEX($DE$2:$DU$300,$FC2,COLUMNS($GF$2:GP2)),""),"")))) | GR9: =IFERROR(INDEX($DE$2:$DR$500,$FC2,COLUMNS($GF$2:GQ2)),"") | GS9: =IFERROR(INDEX($DE$2:$DR$500,$FC2,COLUMNS($GF$2:GR2)),"") | GT9: =IFERROR(INDEX($DE$2:$EC$300,$FC2,COLUMNS($GF$2:GS2)),"") | GU9: =IFERROR(INDEX($DE$2:$EC$300,$FC2,COLUMNS($GF$2:GT2)),"") | GV9: =IFERROR(INDEX($DE$2:$EC$300,$FC2,COLUMNS($GF$2:GU2)),"") | GW9: =IFERROR(INDEX($DE$2:$EC$300,$FC2,COLUMNS($GF$2:GV2)),"") | GX9: =IFERROR(INDEX($DE$2:$EC$300,$FC2,COLUMNS($GF$2:GW2)),"") | GY9: =IFERROR(INDEX($DE$2:$EC$300,$FC2,COLUMNS($GF$2:GX2)),"") | GZ9: =IFERROR(INDEX($DE$2:$EC$300,$FC2,COLUMNS($GF$2:GY2)),"") | HA9: =IFERROR(INDEX($DE$2:$EC$300,$FC2,COLUMNS($GF$2:GZ2)),"") | ... HE9: =IFERROR(INDEX($DE$2:$EC$300,$FC2,COLUMNS($GF$2:HD2)),"")
A10: New Type | B10: - | D10: Cutter quantities changed after Engineer cutter entry filled | K10: Remarks | N10: Total cutters in BOM | S10: 738227 | DB10: 418525 | DD10: 68 | DE10: 1039060 | DF10: 1613 CT138 0.018 | DG10: =DR10 & " " & DL10 -> 1613 CT138 0.018" | DH10: 16 | DI10: 1613 | DJ10: CT138 | DL10: 0.018" | DM10: 33 | DN10: 0 | DO10: 497 | DR10: =DI10 & " " & DJ10 & " " & DK10 -> 1613 CT138 | DV10: S | DW10: 6.4.1 | DX10: 30 | DY10: 16mm Cutter Replacement Super Premium | DZ10: 16mm | EA10: 1 | EB10: EA | EC10: 662 | ED10: 6.4.1 30 | EE10: =SUMIF($G$12:$G$21,$DE10,$E$12:$E$21) -> 0 | EF10: =ROWS($DE$2:DE10) -> 9 | EG10: =IF($CY$60<>0,IF($CY$60=DE10,EF10,""),"") -> 9 | EJ10: =IF($CY$61<>0,IF($CY$61=DE10,EF10,""),"") | EM10: =IF($CY$62<>0,IF($CY$62=DE10,EF10,""),"") | EP10: =IF($CY$63<>0,IF($CY$63=DE10,EF10,""),"") | ES10: =IF($CY$64<>0,IF($CY$64=DE10,EF10,""),"") | EV10: =IF($CY$65<>0,IF($CY$65=DE10,EF10,""),"") | EY10: =IF($CY$66<>0,IF($CY$66=DE10,EF10,""),"") | FB10: =IF($CY$67<>0,IF($CY$67=DE10,EF10,""),"") | FE10: =IF($CY$68<>0,IF($CY$68=DE10,EF10,""),"") | FH10: =IF($CY$69<>0,IF($CY$69=DE10,EF10,""),"") | FK10: =IF($CY$70<>0, IF($CY$70=DE10, EF10, ""), "") | FN10: =IF($CY$71<>0, IF($CY$71=DE10, EF10, ""), "") | FQ10: =IF($CY$72<>0, IF($CY$72=DE10, EF10, ""), "") | FT10: =IF($CY$73<>0, IF($CY$73=DE10, EF10, ""), "") | FW10: =IF($CY$74<>0, IF($CY$74=DE10, EF10, ""), "") | FZ10: =IF($CY$75<>0, IF($CY$75=DE10, EF10, ""), "") | GC10: =IF($CY$76<>0, IF($CY$76=DE10, EF10, ""), "") | GG10: =IFERROR(INDEX($DE$2:$DR$500,$FF2,COLUMNS($GF$2:GF2)),"") | GH10: =IFERROR(INDEX($DE$2:$DR$500,$FF2,COLUMNS($GF$2:GG2)),"") | GI10: =IFERROR(INDEX($DE$2:$DR$500,$FF2,COLUMNS($GF$2:GH2)),"") | GJ10: =IFERROR(INDEX($DE$2:$DR$500,$FF2,COLUMNS($GF$2:GI2)),"") | GK10: =IFERROR(INDEX($DE$2:$DR$500,$FF2,COLUMNS($GF$2:GJ2)),"") | GL10: =IFERROR(INDEX($DE$2:$DR$500,$FF2,COLUMNS($GF$2:GK2)),"") | GM10: =IFERROR(INDEX($DE$2:$DR$500,$FF2,COLUMNS($GF$2:GL2)),"") | GN10: =IFERROR(INDEX($DE$2:$DR$500,$FF2,COLUMNS($GF$2:GM2)),"") | ... GP10: =IFERROR(INDEX($DE$2:$DR$500,$FF2,COLUMNS($GF$2:GO2)),"") | GQ10: =IF($B$29=1,IFERROR(INDEX($DE$2:$DU$300,$FF2,COLUMNS($GF$2:GT2)),""),IF($B$29=2,IFERROR(INDEX($DE$2:$DU$300,$FF2,COLUMNS($GF$2:GV2)),""),IF($B$29=3,IFERROR(INDEX($DE$2:$DU$300,$FF2,COLUMNS($GF$2:GU2)),""),IF($B$29="",IFERROR(INDEX($DE$2:$DU$300,$FF2,COLUMNS($GF$2:GP2)),""),"")))) | GR10: =IFERROR(INDEX($DE$2:$DR$500,$FF2,COLUMNS($GF$2:GQ2)),"") | GS10: =IFERROR(INDEX($DE$2:$DR$500,$FF2,COLUMNS($GF$2:GR2)),"") | GT10: =IFERROR(INDEX($DE$2:$EC$300,$FF2,COLUMNS($GF$2:GS2)),"") | GU10: =IFERROR(INDEX($DE$2:$EC$300,$FF2,COLUMNS($GF$2:GT2)),"") | GV10: =IFERROR(INDEX($DE$2:$EC$300,$FF2,COLUMNS($GF$2:GU2)),"") | GW10: =IFERROR(INDEX($DE$2:$EC$300,$FF2,COLUMNS($GF$2:GV2)),"") | GX10: =IFERROR(INDEX($DE$2:$EC$300,$FF2,COLUMNS($GF$2:GW2)),"") | GY10: =IFERROR(INDEX($DE$2:$EC$300,$FF2,COLUMNS($GF$2:GX2)),"") | GZ10: =IFERROR(INDEX($DE$2:$EC$300,$FF2,COLUMNS($GF$2:GY2)),"") | HA10: =IFERROR(INDEX($DE$2:$EC$300,$FF2,COLUMNS($GF$2:GZ2)),"") | ... HE10: =IFERROR(INDEX($DE$2:$EC$300,$FF2,COLUMNS($GF$2:HD2)),"")
A11: Evaluated by | B11: Yakoob Alajawad | D11: # | E11: Quantity | F11: Cutter Size | G11: Cutters Part # | H11: Description | K11: New | L11: Reclaim | M11: Additional comment | N11: Cutters as BOM | O11: Qty as BOM | Q11: - | S11: 638559 | DB11: 467367 | DD11: 80 | DE11: 1039064 | DF11: 1913 CT138 TSP V 0.018 | DG11: =DR11 & " " & DL11 -> 1913 CT138 TSP V 0.018" | DH11: 19 | DI11: 1913 | DJ11: CT138 | DK11: TSP V | DL11: 0.018" | DM11: 27 | DN11: 0 | DO11: 660 | DR11: =DI11 & " " & DJ11 & " " & DK11 -> 1913 CT138 TSP V | DV11: S | DW11: 6.5.1 | DX11: 30 | DY11: 19mm Cutter Replacement Super Premium | DZ11: 19mm | EA11: 1 | EB11: EA | EC11: 836 | ED11: 6.5.1 30 | EE11: =SUMIF($G$12:$G$21,$DE11,$E$12:$E$21) -> 0 | EF11: =ROWS($DE$2:DE11) -> 10 | EG11: =IF($CY$60<>0,IF($CY$60=DE11,EF11,""),"") | EJ11: =IF($CY$61<>0,IF($CY$61=DE11,EF11,""),"") | EM11: =IF($CY$62<>0,IF($CY$62=DE11,EF11,""),"") | EP11: =IF($CY$63<>0,IF($CY$63=DE11,EF11,""),"") | ES11: =IF($CY$64<>0,IF($CY$64=DE11,EF11,""),"") | EV11: =IF($CY$65<>0,IF($CY$65=DE11,EF11,""),"") | EY11: =IF($CY$66<>0,IF($CY$66=DE11,EF11,""),"") | FB11: =IF($CY$67<>0,IF($CY$67=DE11,EF11,""),"") | FE11: =IF($CY$68<>0,IF($CY$68=DE11,EF11,""),"") | FH11: =IF($CY$69<>0,IF($CY$69=DE11,EF11,""),"") | FK11: =IF($CY$70<>0, IF($CY$70=DE11, EF11, ""), "") | FN11: =IF($CY$71<>0, IF($CY$71=DE11, EF11, ""), "") | FQ11: =IF($CY$72<>0, IF($CY$72=DE11, EF11, ""), "") | FT11: =IF($CY$73<>0, IF($CY$73=DE11, EF11, ""), "") | FW11: =IF($CY$74<>0, IF($CY$74=DE11, EF11, ""), "") | FZ11: =IF($CY$75<>0, IF($CY$75=DE11, EF11, ""), "") | GC11: =IF($CY$76<>0, IF($CY$76=DE11, EF11, ""), "") | GG11: =IFERROR(INDEX($DE$2:$DR$500,$FI2,COLUMNS($GF$2:GF2)),"") | GH11: =IFERROR(INDEX($DE$2:$DR$500,$FI2,COLUMNS($GF$2:GG2)),"") | GI11: =IFERROR(INDEX($DE$2:$DR$500,$FI2,COLUMNS($GF$2:GH2)),"") | GJ11: =IFERROR(INDEX($DE$2:$DR$500,$FI2,COLUMNS($GF$2:GI2)),"") | GK11: =IFERROR(INDEX($DE$2:$DR$500,$FI2,COLUMNS($GF$2:GJ2)),"") | GL11: =IFERROR(INDEX($DE$2:$DR$500,$FI2,COLUMNS($GF$2:GK2)),"") | GM11: =IFERROR(INDEX($DE$2:$DR$500,$FI2,COLUMNS($GF$2:GL2)),"") | GN11: =IFERROR(INDEX($DE$2:$DR$500,$FI2,COLUMNS($GF$2:GM2)),"") | ... GT11: =IFERROR(INDEX($DE$2:$DR$500,$FI2,COLUMNS($GF$2:GS2)),"") | GU11: =IFERROR(INDEX($DE$2:EC$200,$FI2,COLUMNS($GF$2:GT2)),"") | GV11: =IFERROR(INDEX($DE$2:EC$200,$FI2,COLUMNS($GF$2:GU2)),"") | GW11: =IFERROR(INDEX($DE$2:EC$200,$FI2,COLUMNS($GF$2:GV2)),"") | GX11: =IFERROR(INDEX($DE$2:EC$200,$FI2,COLUMNS($GF$2:GW2)),"") | GY11: =IFERROR(INDEX($DE$2:EC$200,$FI2,COLUMNS($GF$2:GX2)),"") | GZ11: =IFERROR(INDEX($DE$2:EC$200,$FI2,COLUMNS($GF$2:GY2)),"") | HA11: =IFERROR(INDEX($DE$2:EC$200,$FI2,COLUMNS($GF$2:GZ2)),"") | HB11: =IFERROR(INDEX($DE$2:$EC$300,$FI2,COLUMNS($GF$2:HA2)),"") | HC11: =IFERROR(INDEX($DE$2:$EC$300,$FI2,COLUMNS($GF$2:HB2)),"") | HD11: =IFERROR(INDEX($DE$2:$EC$300,$FI2,COLUMNS($GF$2:HC2)),"") | HE11: =IFERROR(INDEX($DE$2:$EC$300,$FI2,COLUMNS($GF$2:HD2)),"")
A12: QC By | B12: Ali Alhammad | D12: =IF(G12="","",IF(CX60>0,IF(CX60<>"", CX60, ""),"")) -> 1 | E12: =IF('Eng. Cutter Entry'!C4<>"",IF($L$9<>1,('ARDT Cutter Entry'!AQ$58+'ARDT Cutter Entry'!AQ$59+'ARDT Cutter Entry'!AQ$60+'ARDT Cutter Entry'!AQ$61),'ARDT Cutter Entry'!AQ$58+'ARDT Cutter Entry'!AQ$59+'ARDT Cutter Entry'!AQ$60+'ARDT Cutter Entry'!AQ$61+Rework!C73),'ARDT Cutter Entry'!AQ2+'ARDT Cutter Entry'!AQ3+'ARDT Cutter Entry'!AQ4+'ARDT Cutter Entry'!AQ5) -> 0 | F12: =IF(GK2>0,IF(GK2<>"",GK2," ")," ") -> 1613 | G12: =IF(B5<>"",IF(GG2>0,IF(GG2<>"",IF(GG2<>"Add the cutter in list",GG2,"Add the cutter"),""),""),"") -> 1039060 | H12: =IF(AND(GM2<>"",GM2<>0),GM2,"")&IF(AND(GL2<>"",GL2<>0)," "&GL2,"")&IF(AND(GN2<>"",GN2<>0)," "&GN2,"") -> CT138 0.018" | J12: =IF(AND(GR2<>"",GR2<>0),GR2,"") | K12: =IF(IFERROR(E12-L12,E12)=0,"",IFERROR(E12-L12,E12)) | N12: =BJ46 -> 1039060 | O12: =BO46 -> 33 | S12: 1162508 | DB12: 471108 | DD12: 24 | DE12: 177778 | DF12: 1303 CT200 DROPIN | DG12: =DR12 & " " & DL12 -> 1303 CT200 DROPIN | DH12: 13 | DI12: 1303 | DJ12: CT200 | DK12: DROPIN | DM12: 15 | DN12: 0 | DO12: 360 | DR12: =DI12 & " " & DJ12 & " " & DK12 -> 1303 CT200 DROPIN | DV12: B | DW12: 6.3.1 | DX12: 10 | DY12: 13mm Cutter Replacement Standard | DZ12: 13mm | EA12: 1 | EB12: EA | EC12: 345 | ED12: 6.3.1 10 | EE12: =SUMIF($G$12:$G$21,$DE12,$E$12:$E$21) -> 0 | EF12: =ROWS($DE$2:DE12) -> 11 | EG12: =IF($CY$60<>0,IF($CY$60=DE12,EF12,""),"") | EJ12: =IF($CY$61<>0,IF($CY$61=DE12,EF12,""),"") | EM12: =IF($CY$62<>0,IF($CY$62=DE12,EF12,""),"") | EP12: =IF($CY$63<>0,IF($CY$63=DE12,EF12,""),"") | ES12: =IF($CY$64<>0,IF($CY$64=DE12,EF12,""),"") | EV12: =IF($CY$65<>0,IF($CY$65=DE12,EF12,""),"") | EY12: =IF($CY$66<>0,IF($CY$66=DE12,EF12,""),"") | FB12: =IF($CY$67<>0,IF($CY$67=DE12,EF12,""),"") | FE12: =IF($CY$68<>0,IF($CY$68=DE12,EF12,""),"") | FH12: =IF($CY$69<>0,IF($CY$69=DE12,EF12,""),"") | FK12: =IF($CY$70<>0, IF($CY$70=DE12, EF12, ""), "") | FN12: =IF($CY$71<>0, IF($CY$71=DE12, EF12, ""), "") | FQ12: =IF($CY$72<>0, IF($CY$72=DE12, EF12, ""), "") | FT12: =IF($CY$73<>0, IF($CY$73=DE12, EF12, ""), "") | FW12: =IF($CY$74<>0, IF($CY$74=DE12, EF12, ""), "") | FZ12: =IF($CY$75<>0, IF($CY$75=DE12, EF12, ""), "") | GC12: =IF($CY$76<>0, IF($CY$76=DE12, EF12, ""), "") | GG12: =IFERROR(INDEX($DE$2:$DR$500,$FL2,COLUMNS($GF$2:GF2)),"") | GH12: =IFERROR(INDEX($DE$2:$DR$500,$FL2,COLUMNS($GF$2:GG2)),"") | GI12: =IFERROR(INDEX($DE$2:$DR$500,$FL2,COLUMNS($GF$2:GH2)),"") | GJ12: =IFERROR(INDEX($DE$2:$DR$500,$FL2,COLUMNS($GF$2:GI2)),"") | GK12: =IFERROR(INDEX($DE$2:$DR$500,$FL2,COLUMNS($GF$2:GJ2)),"") | GL12: =IFERROR(INDEX($DE$2:$DR$500,$FL2,COLUMNS($GF$2:GK2)),"") | GM12: =IFERROR(INDEX($DE$2:$DR$500,$FL2,COLUMNS($GF$2:GL2)),"") | GN12: =IFERROR(INDEX($DE$2:$DR$500,$FL2,COLUMNS($GF$2:GM2)),"") | ... HE12: =IFERROR(INDEX($DE$2:$DR$500,$FL2,COLUMNS($GF$2:HD2)),"")
A13: Date of Evaluation (MM/DD/YYYY) | B13: 46022 | D13: =IF(G13="","",IF(CX61>0,IF(CX61<>"", CX61, ""),"")) -> 2 | E13: =IF('Eng. Cutter Entry'!C4<>"",IF($L$9<>1,('ARDT Cutter Entry'!AR$58+'ARDT Cutter Entry'!AR$59+'ARDT Cutter Entry'!AR$60+'ARDT Cutter Entry'!AR$61),'ARDT Cutter Entry'!AR$58+'ARDT Cutter Entry'!AR$59+'ARDT Cutter Entry'!AR$60+'ARDT Cutter Entry'!AR$61+Rework!D73),'ARDT Cutter Entry'!AR2+'ARDT Cutter Entry'!AR3+'ARDT Cutter Entry'!AR4+'ARDT Cutter Entry'!AR5) -> 0 | F13: =IF(GK3>0,IF(GK3<>"",GK3," ")," ") -> 1608 | G13: =IF(B5<>"",IF(GG3>0,IF(GG3<>"",IF(GG3<>"Add the cutter in list",GG3,"Add the cutter"),""),""),"") -> 1130197 | H13: =IF(AND(GM3<>"",GM3<>0),GM3,"")&IF(AND(GL3<>"",GL3<>0)," "&GL3,"")&IF(AND(GN3<>"",GN3<>0)," "&GN3,"") -> CT182 0.018 | J13: =IF(AND(GR3<>"",GR3<>0),GR3,"") | K13: =IF(IFERROR(E13-L13,E13)=0,"",IFERROR(E13-L13,E13)) | N13: =BJ47 -> 1130197 | O13: =BO47 -> 23 | S13: 729688 | DB13: 471109 | DD13: 2 | DE13: 375538 | DF13: 13MM R1 PEP .012R LG BEVEL | DG13: =DR13 & " " & DL13 -> 13 R1 PEP .012R LG BEVEL | DH13: 13 | DI13: 13 | DK13: R1 PEP .012R LG BEVEL | DM13: 24 | DN13: 38 | DO13: 360 | DR13: =DI13 & " " & DJ13 & " " & DK13 -> 13 R1 PEP .012R LG BEVEL | DS13: =DT13*1.3 -> 140.764 | DT13: 108.28 | DV13: D | DW13: 6.3.1 | DX13: 10 | DY13: 13mm Cutter Replacement Standard | DZ13: 13mm | EA13: 1 | EB13: EA | EC13: 345 | ED13: 6.3.1 10 | EE13: =SUMIF($G$12:$G$21,$DE13,$E$12:$E$21) -> 0 | EF13: =ROWS($DE$2:DE13) -> 12 | EG13: =IF($CY$60<>0,IF($CY$60=DE13,EF13,""),"") | EJ13: =IF($CY$61<>0,IF($CY$61=DE13,EF13,""),"") | EM13: =IF($CY$62<>0,IF($CY$62=DE13,EF13,""),"") | EP13: =IF($CY$63<>0,IF($CY$63=DE13,EF13,""),"") | ES13: =IF($CY$64<>0,IF($CY$64=DE13,EF13,""),"") | EV13: =IF($CY$65<>0,IF($CY$65=DE13,EF13,""),"") | EY13: =IF($CY$66<>0,IF($CY$66=DE13,EF13,""),"") | FB13: =IF($CY$67<>0,IF($CY$67=DE13,EF13,""),"") | FE13: =IF($CY$68<>0,IF($CY$68=DE13,EF13,""),"") | FH13: =IF($CY$69<>0,IF($CY$69=DE13,EF13,""),"") | FK13: =IF($CY$70<>0, IF($CY$70=DE13, EF13, ""), "") | FN13: =IF($CY$71<>0, IF($CY$71=DE13, EF13, ""), "") | FQ13: =IF($CY$72<>0, IF($CY$72=DE13, EF13, ""), "") | FT13: =IF($CY$73<>0, IF($CY$73=DE13, EF13, ""), "") | FW13: =IF($CY$74<>0, IF($CY$74=DE13, EF13, ""), "") | FZ13: =IF($CY$75<>0, IF($CY$75=DE13, EF13, ""), "") | GC13: =IF($CY$76<>0, IF($CY$76=DE13, EF13, ""), "") | GG13: =IFERROR(INDEX($DE$2:$DR$500,$FO2,COLUMNS($GF$2:GF2)),"") | GH13: =IFERROR(INDEX($DE$2:$DR$500,$FO2,COLUMNS($GF$2:GG2)),"") | GI13: =IFERROR(INDEX($DE$2:$DR$500,$FO2,COLUMNS($GF$2:GH2)),"") | GJ13: =IFERROR(INDEX($DE$2:$DR$500,$FO2,COLUMNS($GF$2:GI2)),"") | GK13: =IFERROR(INDEX($DE$2:$DR$500,$FO2,COLUMNS($GF$2:GJ2)),"") | GL13: =IFERROR(INDEX($DE$2:$DR$500,$FO2,COLUMNS($GF$2:GK2)),"") | GM13: =IFERROR(INDEX($DE$2:$DR$500,$FO2,COLUMNS($GF$2:GL2)),"") | GN13: =IFERROR(INDEX($DE$2:$DR$500,$FO2,COLUMNS($GF$2:GM2)),"") | ... HE13: =IFERROR(INDEX($DE$2:$DR$500,$FO2,COLUMNS($GF$2:HD2)),"")
A14: =IF(Data!B7="SAUDI ARAMCO","DTD/TSSD:","Reviewed by Eng.:") -> DTD/TSSD: | D14: =IF(G14="","",IF(CX62>0,IF(CX62<>"", CX62, ""),"")) -> 3 | E14: =IF('Eng. Cutter Entry'!C4<>"",IF($L$9<>1,('ARDT Cutter Entry'!AS$58+'ARDT Cutter Entry'!AS$59+'ARDT Cutter Entry'!AS$60+'ARDT Cutter Entry'!AS$61),'ARDT Cutter Entry'!AS$58+'ARDT Cutter Entry'!AS$59+'ARDT Cutter Entry'!AS$60+'ARDT Cutter Entry'!AS$61+Rework!E73),'ARDT Cutter Entry'!AS2+'ARDT Cutter Entry'!AS3+'ARDT Cutter Entry'!AS4+'ARDT Cutter Entry'!AS5) -> 6 | F14: =IF(GK4>0,IF(GK4<>"",GK4," ")," ") -> 1308 | G14: =IF(B5<>"",IF(GG4>0,IF(GG4<>"",IF(GG4<>"Add the cutter in list",GG4,"Add the cutter"),""),""),"") -> 418525 | H14: =IF(AND(GM4<>"",GM4<>0),GM4,"")&IF(AND(GL4<>"",GL4<>0)," "&GL4,"")&IF(AND(GN4<>"",GN4<>0)," "&GN4,"") -> Drop in CT31 | J14: =IF(AND(GR4<>"",GR4<>0),GR4,"") | K14: =IF(IFERROR(E14-L14,E14)=0,"",IFERROR(E14-L14,E14)) -> 6 | N14: =BJ48 -> 418525 | O14: =BO48 -> 6 | DB14: 535656 | DD14: 15 | DE14: 376826 | DF14: 1325 Graphite for Rinho Cutter Plug | DG14: =DR14 & " " & DL14 -> 1325 Graphite for Rinho Cutter Plug | DH14: 13 | DI14: 1325 | DK14: Graphite for Rinho Cutter Plug | DM14: 0 | DN14: 3 | DO14: 360 | DR14: =DI14 & " " & DJ14 & " " & DK14 -> 1325 Graphite for Rinho Cutter Plug | DS14: =DT14*1.3 -> 0 | EE14: =SUMIF($G$12:$G$21,$DE14,$E$12:$E$21) -> 0 | EF14: =ROWS($DE$2:DE14) -> 13 | EG14: =IF($CY$60<>0,IF($CY$60=DE14,EF14,""),"") | EJ14: =IF($CY$61<>0,IF($CY$61=DE14,EF14,""),"") | EM14: =IF($CY$62<>0,IF($CY$62=DE14,EF14,""),"") | EP14: =IF($CY$63<>0,IF($CY$63=DE14,EF14,""),"") | ES14: =IF($CY$64<>0,IF($CY$64=DE14,EF14,""),"") | EV14: =IF($CY$65<>0,IF($CY$65=DE14,EF14,""),"") | EY14: =IF($CY$66<>0,IF($CY$66=DE14,EF14,""),"") | FB14: =IF($CY$67<>0,IF($CY$67=DE14,EF14,""),"") | FE14: =IF($CY$68<>0,IF($CY$68=DE14,EF14,""),"") | FH14: =IF($CY$69<>0,IF($CY$69=DE14,EF14,""),"") | FK14: =IF($CY$70<>0, IF($CY$70=DE14, EF14, ""), "") | FN14: =IF($CY$71<>0, IF($CY$71=DE14, EF14, ""), "") | FQ14: =IF($CY$72<>0, IF($CY$72=DE14, EF14, ""), "") | FT14: =IF($CY$73<>0, IF($CY$73=DE14, EF14, ""), "") | FW14: =IF($CY$74<>0, IF($CY$74=DE14, EF14, ""), "") | FZ14: =IF($CY$75<>0, IF($CY$75=DE14, EF14, ""), "") | GC14: =IF($CY$76<>0, IF($CY$76=DE14, EF14, ""), "") | GG14: =IFERROR(INDEX($DE$2:$DR$500,$FR2,COLUMNS($GF$2:GF2)),"") | GH14: =IFERROR(INDEX($DE$2:$DR$500,$FR2,COLUMNS($GF$2:GG2)),"") | GI14: =IFERROR(INDEX($DE$2:$DR$500,$FR2,COLUMNS($GF$2:GH2)),"") | GJ14: =IFERROR(INDEX($DE$2:$DR$500,$FR2,COLUMNS($GF$2:GI2)),"") | GK14: =IFERROR(INDEX($DE$2:$DR$500,$FR2,COLUMNS($GF$2:GJ2)),"") | GL14: =IFERROR(INDEX($DE$2:$DR$500,$FR2,COLUMNS($GF$2:GK2)),"") | GM14: =IFERROR(INDEX($DE$2:$DR$500,$FR2,COLUMNS($GF$2:GL2)),"") | GN14: =IFERROR(INDEX($DE$2:$DR$500,$FR2,COLUMNS($GF$2:GM2)),"") | ... HE14: =IFERROR(INDEX($DE$2:$DR$500,$FR2,COLUMNS($GF$2:HD2)),"")
A15: Date of Review (MM/DD/YYYY) | D15: =IF(TRIM(G15)="","",IF(CX63>0,IF(CX63<>"", CX63, ""),"")) -> 4 | E15: =IF('Eng. Cutter Entry'!C4<>"",IF($L$9<>1,('ARDT Cutter Entry'!AT$58+'ARDT Cutter Entry'!AT$59+'ARDT Cutter Entry'!AT$60+'ARDT Cutter Entry'!AT$61),'ARDT Cutter Entry'!AT$58+'ARDT Cutter Entry'!AT$59+'ARDT Cutter Entry'!AT$60+'ARDT Cutter Entry'!AT$61+Rework!F73),'ARDT Cutter Entry'!AT2+'ARDT Cutter Entry'!AT3+'ARDT Cutter Entry'!AT4+'ARDT Cutter Entry'!AT5) -> 6 | F15: =IF(GK5>0,IF(GK5<>"",GK5," ")," ") -> 1608 | G15: =IF(B5<>"",IF(GG5>0,IF(GG5<>"",IF(GG5<>"Add the cutter in list",GG5,"Add the cutter"),""),""),"") -> 643738 | H15: =IF(AND(GM5<>"",GM5<>0),GM5,"")&IF(AND(GL5<>"",GL5<>0)," "&GL5,"")&IF(AND(GN5<>"",GN5<>0)," "&GN5,"") -> CT70 0.018" | J15: =IF(AND(GR5<>"",GR5<>0),GR5,"") | K15: =IF(IFERROR(E15-L15,E15)=0,"",IFERROR(E15-L15,E15)) -> 6 | M15: [ ENO GRD 6] | N15: =BJ49 -> 0 | O15: =BO49 -> 0 | DB15: 565884 | DD15: 3 | DE15: 399930 | DF15: 1919CT-27 BL .02 | DG15: =DR15 & " " & DL15 -> 1919 CT27 BL 0.020" | DH15: 19 | DI15: 1919 | DJ15: CT27 | DK15: BL | DL15: 0.020" | DM15: 1 | DN15: 24 | DO15: 660 | DR15: =DI15 & " " & DJ15 & " " & DK15 -> 1919 CT27 BL | DS15: =DT15*1.3 -> 0 | DV15: P | DW15: 6.5.1 | DX15: 20 | DY15: 19mm Cutter Replacement Premium | DZ15: 19mm | EA15: 1 | EB15: EA | EC15: 712 | ED15: 6.5.1 20 | EE15: =SUMIF($G$12:$G$21,$DE15,$E$12:$E$21) -> 0 | EF15: =ROWS($DE$2:DE15) -> 14 | EG15: =IF($CY$60<>0,IF($CY$60=DE15,EF15,""),"") | EJ15: =IF($CY$61<>0,IF($CY$61=DE15,EF15,""),"") | EM15: =IF($CY$62<>0,IF($CY$62=DE15,EF15,""),"") | EP15: =IF($CY$63<>0,IF($CY$63=DE15,EF15,""),"") | ES15: =IF($CY$64<>0,IF($CY$64=DE15,EF15,""),"") | EV15: =IF($CY$65<>0,IF($CY$65=DE15,EF15,""),"") | EY15: =IF($CY$66<>0,IF($CY$66=DE15,EF15,""),"") | FB15: =IF($CY$67<>0,IF($CY$67=DE15,EF15,""),"") | FE15: =IF($CY$68<>0,IF($CY$68=DE15,EF15,""),"") | FH15: =IF($CY$69<>0,IF($CY$69=DE15,EF15,""),"") | FK15: =IF($CY$70<>0, IF($CY$70=DE15, EF15, ""), "") | FN15: =IF($CY$71<>0, IF($CY$71=DE15, EF15, ""), "") | FQ15: =IF($CY$72<>0, IF($CY$72=DE15, EF15, ""), "") | FT15: =IF($CY$73<>0, IF($CY$73=DE15, EF15, ""), "") | FW15: =IF($CY$74<>0, IF($CY$74=DE15, EF15, ""), "") | FZ15: =IF($CY$75<>0, IF($CY$75=DE15, EF15, ""), "") | GC15: =IF($CY$76<>0, IF($CY$76=DE15, EF15, ""), "") | GG15: =IFERROR(INDEX($DE$2:$DR$500,$FU2,COLUMNS($GF$2:GF2)),"") | GH15: =IFERROR(INDEX($DE$2:$DR$500,$FU2,COLUMNS($GF$2:GG2)),"") | GI15: =IFERROR(INDEX($DE$2:$DR$500,$FU2,COLUMNS($GF$2:GH2)),"") | GJ15: =IFERROR(INDEX($DE$2:$DR$500,$FU2,COLUMNS($GF$2:GI2)),"") | GK15: =IFERROR(INDEX($DE$2:$DR$500,$FU2,COLUMNS($GF$2:GJ2)),"") | GL15: =IFERROR(INDEX($DE$2:$DR$500,$FU2,COLUMNS($GF$2:GK2)),"") | GM15: =IFERROR(INDEX($DE$2:$DR$500,$FU2,COLUMNS($GF$2:GL2)),"") | GN15: =IFERROR(INDEX($DE$2:$DR$500,$FU2,COLUMNS($GF$2:GM2)),"") | ... HE15: =IFERROR(INDEX($DE$2:$DR$500,$FU2,COLUMNS($GF$2:HD2)),"")
A16: Requested by | B16: =IF(Data!B7<>"", Data!B7, " ") -> SAUDI ARAMCO | D16: =IF(TRIM(G16)="","",IF(CX64>0,IF(CX64<>"", CX64, ""),"")) -> 5 | E16: =IF('Eng. Cutter Entry'!C4<>"",IF($L$9<>1,('ARDT Cutter Entry'!AU$58+'ARDT Cutter Entry'!AU$59+'ARDT Cutter Entry'!AU$60+'ARDT Cutter Entry'!AU$61),'ARDT Cutter Entry'!AU$58+'ARDT Cutter Entry'!AU$59+'ARDT Cutter Entry'!AU$60+'ARDT Cutter Entry'!AU$61+Rework!G73),'ARDT Cutter Entry'!AU2+'ARDT Cutter Entry'!AU3+'ARDT Cutter Entry'!AU4+'ARDT Cutter Entry'!AU5) -> 21 | F16: =IF(GK6>0,IF(GK6<>"",GK6," ")," ") -> 1613 | G16: =IF(B5<>"",IF(GG6>0,IF(GG6<>"",IF(GG6<>"Add the cutter in list",GG6,"Add the cutter"),""),""),"") -> 1126402 | H16: =IF(AND(GM6<>"",GM6<>0),GM6,"")&IF(AND(GL6<>"",GL6<>0)," "&GL6,"")&IF(AND(GN6<>"",GN6<>0)," "&GN6,"") -> CT421 18-60 | J16: =IF(AND(GR6<>"",GR6<>0),GR6,"") | K16: =IF(IFERROR(E16-L16,E16)=0,"",IFERROR(E16-L16,E16)) -> 21 | N16: =BJ50 -> 0 | O16: =BO50 -> 0 | DB16: 578502 | DD16: 38 | DE16: 418525 | DF16: 1308 CT31 Drop in | DG16: =DR16 & " " & DL16 -> 1308 CT31 Drop in | DH16: 13 | DI16: 1308 | DJ16: CT31 | DK16: Drop in | DM16: 381 | DN16: 0 | DO16: 100 | DR16: =DI16 & " " & DJ16 & " " & DK16 -> 1308 CT31 Drop in | DS16: =DT16*1.3 -> 26.981067 | DT16: 20.754667 | DU16: 100 | DV16: B | DW16: 6.3.1 | DX16: 10 | DY16: 13mm Cutter Replacement Standard | DZ16: 13mm | EA16: 1 | EB16: EA | EC16: 345 | ED16: 6.3.1 10 | EE16: =SUMIF($G$12:$G$21,$DE16,$E$12:$E$21) -> 6 | EF16: =ROWS($DE$2:DE16) -> 15 | EG16: =IF($CY$60<>0,IF($CY$60=DE16,EF16,""),"") | EJ16: =IF($CY$61<>0,IF($CY$61=DE16,EF16,""),"") | EM16: =IF($CY$62<>0,IF($CY$62=DE16,EF16,""),"") -> 15 | EP16: =IF($CY$63<>0,IF($CY$63=DE16,EF16,""),"") | ES16: =IF($CY$64<>0,IF($CY$64=DE16,EF16,""),"") | EV16: =IF($CY$65<>0,IF($CY$65=DE16,EF16,""),"") | EY16: =IF($CY$66<>0,IF($CY$66=DE16,EF16,""),"") | FB16: =IF($CY$67<>0,IF($CY$67=DE16,EF16,""),"") | FE16: =IF($CY$68<>0,IF($CY$68=DE16,EF16,""),"") | FH16: =IF($CY$69<>0,IF($CY$69=DE16,EF16,""),"") | FK16: =IF($CY$70<>0, IF($CY$70=DE16, EF16, ""), "") | FN16: =IF($CY$71<>0, IF($CY$71=DE16, EF16, ""), "") | FQ16: =IF($CY$72<>0, IF($CY$72=DE16, EF16, ""), "") | FT16: =IF($CY$73<>0, IF($CY$73=DE16, EF16, ""), "") | FW16: =IF($CY$74<>0, IF($CY$74=DE16, EF16, ""), "") | FZ16: =IF($CY$75<>0, IF($CY$75=DE16, EF16, ""), "") | GC16: =IF($CY$76<>0, IF($CY$76=DE16, EF16, ""), "") | GG16: =IFERROR(INDEX($DE$2:$DR$500,$FX2,COLUMNS($GF$2:GF2)),"") | GH16: =IFERROR(INDEX($DE$2:$DR$500,$FX2,COLUMNS($GF$2:GG2)),"") | GI16: =IFERROR(INDEX($DE$2:$DR$500,$FX2,COLUMNS($GF$2:GH2)),"") | GJ16: =IFERROR(INDEX($DE$2:$DR$500,$FX2,COLUMNS($GF$2:GI2)),"") | GK16: =IFERROR(INDEX($DE$2:$DR$500,$FX2,COLUMNS($GF$2:GJ2)),"") | GL16: =IFERROR(INDEX($DE$2:$DR$500,$FX2,COLUMNS($GF$2:GK2)),"") | GM16: =IFERROR(INDEX($DE$2:$DR$500,$FX2,COLUMNS($GF$2:GL2)),"") | GN16: =IFERROR(INDEX($DE$2:$DR$500,$FX2,COLUMNS($GF$2:GM2)),"") | ... HE16: =IFERROR(INDEX($DE$2:$DR$500,$FX2,COLUMNS($GF$2:HD2)),"")
A17: Department head | B17: Ramzi Kassab | D17: =IF(TRIM(G17)="","",IF(CX65>0,IF(CX65<>"", CX65, ""),"")) | E17: =IF('Eng. Cutter Entry'!C4<>"",IF($L$9<>1,('ARDT Cutter Entry'!AV$58+'ARDT Cutter Entry'!AV$59+'ARDT Cutter Entry'!AV$60+'ARDT Cutter Entry'!AV$61),'ARDT Cutter Entry'!AV$58+'ARDT Cutter Entry'!AV$59+'ARDT Cutter Entry'!AV$60+'ARDT Cutter Entry'!AV$61+Rework!H73),'ARDT Cutter Entry'!AV2+'ARDT Cutter Entry'!AV3+'ARDT Cutter Entry'!AV4+'ARDT Cutter Entry'!AV5) -> 0 | F17: =IF(GK7>0,IF(GK7<>"",GK7," ")," ") | G17: =IF(B5<>"",IF(GG7>0,IF(GG7<>"",IF(GG7<>"Add the cutter in list",GG7,"Add the cutter"),""),""),"") | H17: =IF(AND(GM7<>"",GM7<>0),GM7,"")&IF(AND(GL7<>"",GL7<>0)," "&GL7,"")&IF(AND(GN7<>"",GN7<>0)," "&GN7,"") | J17: =IF(AND(GR7<>"",GR7<>0),GR7,"") | K17: =IF(IFERROR(E17-L17,E17)=0,"",IFERROR(E17-L17,E17)) | N17: =BJ51 -> 0 | O17: =BO51 -> 0 | S17: 2002299 | DB17: 584832 | DD17: 5 | DE17: 467367 | DF17: 1613 CT-36 Round Cutter 0.020 | DG17: =DR17 & " " & DL17 -> 1613 CT36 Round Cutter 0.020" | DH17: 16 | DI17: 1613 | DJ17: CT36 | DK17: Round Cutter | DL17: 0.020" | DM17: 0 | DN17: 12 | DO17: 497 | DR17: =DI17 & " " & DJ17 & " " & DK17 -> 1613 CT36 Round Cutter | DS17: =DT17*1.3 -> 0 | DV17: S | DW17: 6.4.1 | DX17: 30 | DY17: 16mm Cutter Replacement Super Premium | DZ17: 16mm | EA17: 1 | EB17: EA | EC17: 662 | ED17: 6.4.1 30 | EE17: =SUMIF($G$12:$G$21,$DE17,$E$12:$E$21) -> 0 | EF17: =ROWS($DE$2:DE17) -> 16 | EG17: =IF($CY$60<>0,IF($CY$60=DE17,EF17,""),"") | EJ17: =IF($CY$61<>0,IF($CY$61=DE17,EF17,""),"") | EM17: =IF($CY$62<>0,IF($CY$62=DE17,EF17,""),"") | EP17: =IF($CY$63<>0,IF($CY$63=DE17,EF17,""),"") | ES17: =IF($CY$64<>0,IF($CY$64=DE17,EF17,""),"") | EV17: =IF($CY$65<>0,IF($CY$65=DE17,EF17,""),"") | EY17: =IF($CY$66<>0,IF($CY$66=DE17,EF17,""),"") | FB17: =IF($CY$67<>0,IF($CY$67=DE17,EF17,""),"") | FE17: =IF($CY$68<>0,IF($CY$68=DE17,EF17,""),"") | FH17: =IF($CY$69<>0,IF($CY$69=DE17,EF17,""),"") | FK17: =IF($CY$70<>0, IF($CY$70=DE17, EF17, ""), "") | FN17: =IF($CY$71<>0, IF($CY$71=DE17, EF17, ""), "") | FQ17: =IF($CY$72<>0, IF($CY$72=DE17, EF17, ""), "") | FT17: =IF($CY$73<>0, IF($CY$73=DE17, EF17, ""), "") | FW17: =IF($CY$74<>0, IF($CY$74=DE17, EF17, ""), "") | FZ17: =IF($CY$75<>0, IF($CY$75=DE17, EF17, ""), "") | GC17: =IF($CY$76<>0, IF($CY$76=DE17, EF17, ""), "") | GG17: =IFERROR(INDEX($DE$2:$DR$500,$GA2,COLUMNS($GF$2:GF2)),"") | GH17: =IFERROR(INDEX($DE$2:$DR$500,$GA2,COLUMNS($GF$2:GG2)),"") | GI17: =IFERROR(INDEX($DE$2:$DR$500,$GA2,COLUMNS($GF$2:GH2)),"") | GJ17: =IFERROR(INDEX($DE$2:$DR$500,$GA2,COLUMNS($GF$2:GI2)),"") | GK17: =IFERROR(INDEX($DE$2:$DR$500,$GA2,COLUMNS($GF$2:GJ2)),"") | GL17: =IFERROR(INDEX($DE$2:$DR$500,$GA2,COLUMNS($GF$2:GK2)),"") | GM17: =IFERROR(INDEX($DE$2:$DR$500,$GA2,COLUMNS($GF$2:GL2)),"") | GN17: =IFERROR(INDEX($DE$2:$DR$500,$GA2,COLUMNS($GF$2:GM2)),"") | ... HE17: =IFERROR(INDEX($DE$2:$DR$500,$GA2,COLUMNS($GF$2:HD2)),"")
A18: =IF('Eval-LSTK'!D64<>"","Repair Date",IF('Eval-LSTK'!D66<>"","Scrap Date","Rerun Date")) -> Repair Date | D18: =IF(TRIM(G18)="","",IF(CX66>0,IF(CX66<>"", CX66, ""),"")) | E18: =IF('Eng. Cutter Entry'!$C$4<>"",IF($L$9<>1,('ARDT Cutter Entry'!AW$58+'ARDT Cutter Entry'!AW$59+'ARDT Cutter Entry'!AW$60+'ARDT Cutter Entry'!AW$61),'ARDT Cutter Entry'!AW$58+'ARDT Cutter Entry'!AW$59+'ARDT Cutter Entry'!AW$60+'ARDT Cutter Entry'!AW$61+Rework!I73),'ARDT Cutter Entry'!AW$2+'ARDT Cutter Entry'!AW$3+'ARDT Cutter Entry'!AW$4+'ARDT Cutter Entry'!AW$5) -> 0 | F18: =IF(GK8>0,IF(GK8<>"",GK8," ")," ") | G18: =IF($B$5<>"",IF(GG8>0,IF(GG8<>"",IF(GG8<>"Add the cutter in list",GG8,"Add the cutter"),""),""),"") | H18: =IF(AND(GM8<>"",GM8<>0),GM8,"")&IF(AND(GL8<>"",GL8<>0)," "&GL8,"")&IF(AND(GN8<>"",GN8<>0)," "&GN8,"") | J18: =IF(AND(GR8<>"",GR8<>0),GR8,"") | K18: =IF(IFERROR(E18-L18,E18)=0,"",IFERROR(E18-L18,E18)) | N18: =BJ52 -> 0 | O18: =BO52 -> 0 | S18: 1255773 | DB18: 587493 | DD18: 7 | DE18: 471108 | DF18: 1313CT-36 PDC ROUND 0.010" | DG18: =DR18 & " " & DL18 -> 1313 CT36 PDC ROUND 0.010" | DH18: 13 | DI18: 1313 | DJ18: CT36 | DK18: PDC ROUND | DL18: 0.010" | DM18: 0 | DN18: 4 | DO18: 360 | DR18: =DI18 & " " & DJ18 & " " & DK18 -> 1313 CT36 PDC ROUND | DS18: =DT18*1.3 -> 0 | DV18: S | DW18: 6.3.1 | DX18: 30 | DY18: 13mm Cutter Replacement Super Premium | DZ18: 13mm | EA18: 1 | EB18: EA | EC18: 480 | ED18: 6.3.1 30 | EE18: =SUMIF($G$12:$G$21,$DE18,$E$12:$E$21) -> 0 | EF18: =ROWS($DE$2:DE18) -> 17 | EG18: =IF($CY$60<>0,IF($CY$60=DE18,EF18,""),"") | EJ18: =IF($CY$61<>0,IF($CY$61=DE18,EF18,""),"") | EM18: =IF($CY$62<>0,IF($CY$62=DE18,EF18,""),"") | EP18: =IF($CY$63<>0,IF($CY$63=DE18,EF18,""),"") | ES18: =IF($CY$64<>0,IF($CY$64=DE18,EF18,""),"") | EV18: =IF($CY$65<>0,IF($CY$65=DE18,EF18,""),"") | EY18: =IF($CY$66<>0,IF($CY$66=DE18,EF18,""),"") | FB18: =IF($CY$67<>0,IF($CY$67=DE18,EF18,""),"") | FE18: =IF($CY$68<>0,IF($CY$68=DE18,EF18,""),"") | FH18: =IF($CY$69<>0,IF($CY$69=DE18,EF18,""),"") | FK18: =IF($CY$70<>0, IF($CY$70=DE18, EF18, ""), "") | FN18: =IF($CY$71<>0, IF($CY$71=DE18, EF18, ""), "") | FQ18: =IF($CY$72<>0, IF($CY$72=DE18, EF18, ""), "") | FT18: =IF($CY$73<>0, IF($CY$73=DE18, EF18, ""), "") | FW18: =IF($CY$74<>0, IF($CY$74=DE18, EF18, ""), "") | FZ18: =IF($CY$75<>0, IF($CY$75=DE18, EF18, ""), "") | GC18: =IF($CY$76<>0, IF($CY$76=DE18, EF18, ""), "") | GG18: =IFERROR(INDEX($DE$2:$DR$500,$GD2,COLUMNS($GF$2:GF2)),"") | GH18: =IFERROR(INDEX($DE$2:$DR$500,$GD2,COLUMNS($GF$2:GG2)),"") | GI18: =IFERROR(INDEX($DE$2:$DR$500,$GD2,COLUMNS($GF$2:GH2)),"") | GJ18: =IFERROR(INDEX($DE$2:$DR$500,$GD2,COLUMNS($GF$2:GI2)),"") | GK18: =IFERROR(INDEX($DE$2:$DR$500,$GD2,COLUMNS($GF$2:GJ2)),"") | GL18: =IFERROR(INDEX($DE$2:$DR$500,$GD2,COLUMNS($GF$2:GK2)),"") | GM18: =IFERROR(INDEX($DE$2:$DR$500,$GD2,COLUMNS($GF$2:GL2)),"") | GN18: =IFERROR(INDEX($DE$2:$DR$500,$GD2,COLUMNS($GF$2:GM2)),"") | ... HE18: =IFERROR(INDEX($DE$2:$DR$500,$GD2,COLUMNS($GF$2:HD2)),"")
A19: Approved by | D19: =IF(TRIM(G19)="","",IF(CX67>0,IF(CX67<>"", CX67, ""),"")) | E19: =IF('Eng. Cutter Entry'!$C$4<>"",IF($L$9<>1,('ARDT Cutter Entry'!AX$58+'ARDT Cutter Entry'!AX$59+'ARDT Cutter Entry'!AX$60+'ARDT Cutter Entry'!AX$61),'ARDT Cutter Entry'!AX$58+'ARDT Cutter Entry'!AX$59+'ARDT Cutter Entry'!AX$60+'ARDT Cutter Entry'!AX$61+Rework!J73),'ARDT Cutter Entry'!AX$2+'ARDT Cutter Entry'!AX$3+'ARDT Cutter Entry'!AX$4+'ARDT Cutter Entry'!AX$5) -> 0 | F19: =IF(GK9>0,IF(GK9<>"",GK9," ")," ") | G19: =IF($B$5<>"",IF(GG9>0,IF(GG9<>"",IF(GG9<>"Add the cutter in list",GG9,"Add the cutter"),""),""),"") | H19: =IF(AND(GM9<>"",GM9<>0),GM9,"")&IF(AND(GL9<>"",GL9<>0)," "&GL9,"")&IF(AND(GN9<>"",GN9<>0)," "&GN9,"") | J19: =IF(AND(GR9<>"",GR9<>0),GR9,"") | K19: =IF(IFERROR(E19-L19,E19)=0,"",IFERROR(E19-L19,E19)) | N19: =BJ53 -> 0 | O19: =BO53 -> 0 | S19: 1130198 | DB19: 621152 | DD19: 8 | DE19: 471109 | DF19: 1613 CT36 0.010" | DG19: =DR19 & " " & DL19 -> 1613 CT36 0.010" | DH19: 16 | DI19: 1613 | DJ19: CT36 | DL19: 0.010" | DM19: 1 | DN19: 54 | DO19: 497 | DR19: =DI19 & " " & DJ19 & " " & DK19 -> 1613 CT36 | DS19: =DT19*1.3 -> 0 | DV19: S | DW19: 6.4.1 | DX19: 30 | DY19: 16mm Cutter Replacement Super Premium | DZ19: 16mm | EA19: 1 | EB19: EA | EC19: 662 | ED19: 6.4.1 30 | EE19: =SUMIF($G$12:$G$21,$DE19,$E$12:$E$21) -> 0 | EF19: =ROWS($DE$2:DE19) -> 18 | EG19: =IF($CY$60<>0,IF($CY$60=DE19,EF19,""),"") | EJ19: =IF($CY$61<>0,IF($CY$61=DE19,EF19,""),"") | EM19: =IF($CY$62<>0,IF($CY$62=DE19,EF19,""),"") | EP19: =IF($CY$63<>0,IF($CY$63=DE19,EF19,""),"") | ES19: =IF($CY$64<>0,IF($CY$64=DE19,EF19,""),"") | EV19: =IF($CY$65<>0,IF($CY$65=DE19,EF19,""),"") | EY19: =IF($CY$66<>0,IF($CY$66=DE19,EF19,""),"") | FB19: =IF($CY$67<>0,IF($CY$67=DE19,EF19,""),"") | FE19: =IF($CY$68<>0,IF($CY$68=DE19,EF19,""),"") | FH19: =IF($CY$69<>0,IF($CY$69=DE19,EF19,""),"") | FK19: =IF($CY$70<>0, IF($CY$70=DE19, EF19, ""), "") | FN19: =IF($CY$71<>0, IF($CY$71=DE19, EF19, ""), "") | FQ19: =IF($CY$72<>0, IF($CY$72=DE19, EF19, ""), "") | FT19: =IF($CY$73<>0, IF($CY$73=DE19, EF19, ""), "") | FW19: =IF($CY$74<>0, IF($CY$74=DE19, EF19, ""), "") | FZ19: =IF($CY$75<>0, IF($CY$75=DE19, EF19, ""), "") | GC19: =IF($CY$76<>0, IF($CY$76=DE19, EF19, ""), "") | GF19: SERV-ITEM- formated | GG19: SERV-ITEM | GH19: Service Number | GI19: ARAMCO Item Number | GJ19: ARAMCO Description | GK19: Size1 | GL19: PerUOM | GM19: Unit | GN19: ARAMCO Price (USD) | GO19: Quantity | GP19: Size2 | GQ19: Description2 | GV19: SERV-ITEM-FORMATED | GW19: SERV-ITEM | GX19: Service Number | GY19: ARAMCO Item Number | GZ19: ARAMCO Description | HA19: Size | HB19: PerUOM | HC19: Unit | HD19: ARAMCO Price (USD) | HE19: Quantity | HF19: SIZE2 | HG19: DESCRIPTION2
