Workbook

Sheet Cutters Inventory 12-30-2025
A1: # | B1: MN | C1: Product name | D1: Cutter | E1: Size | F1: Chamfer | G1: Family | H1: ENO As New Cutter | I1: ENO Ground Cutter | J1: ARDT Reclaim Cutter | K1: LSTK Reclaim Cutter | L1: New Stock | M1: Total New | N1: 6 months consumption | O1: 3 months consumption | P1: 2 months consumption | Q1: Safety Stock | R1: Category | S1: BOM requirement (12/30/2025) | T1: On Order (12/22/2025) | U1: Total Stock - Forcast | V1: Remarks | W1: Replacement | Y1: L3 & 4 | AB1: =IF(SUM(AB2:AB91)<>0,"THERE IS ERROR","ITS OKAY") -> ITS OKAY | AD1: Total Without LSTK Reclaim | AI1: Replacement Required Qty | AJ1: Replacement By Qty | AK1: Replacement By Qty (SUM)
A2: 1 | B2: 802065 | C2: 1313 CT97 10C | D2: CT97 | E2: 1313 | F2: 10C | G2: P - Premium | H2: =SUMIFS('Cutters Consumption Updates'!$F:$F,'Cutters Consumption Updates'!$D:$D,H$1,'Cutters Consumption Updates'!$B:$B,$B2)-SUMIFS('Cutters Consumption Updates'!$E:$E,'Cutters Consumption Updates'!$D:$D,H$1,'Cutters Consumption Updates'!$B:$B,$B2)+ SUMIF('Cutters Consumption Updates'!$AS:$AS,$B2,'Cutters Consumption Updates'!AT:AT) -> 0 | I2: =SUMIFS('Cutters Consumption Updates'!$F:$F,'Cutters Consumption Updates'!$D:$D,I$1,'Cutters Consumption Updates'!$B:$B,$B2)-SUMIFS('Cutters Consumption Updates'!$E:$E,'Cutters Consumption Updates'!$D:$D,I$1,'Cutters Consumption Updates'!$B:$B,$B2)+ SUMIF('Cutters Consumption Updates'!$AS:$AS,$B2,'Cutters Consumption Updates'!AU:AU) -> 0 | J2: =SUMIFS('Cutters Consumption Updates'!$F:$F,'Cutters Consumption Updates'!$D:$D,J$1,'Cutters Consumption Updates'!$B:$B,$B2)-SUMIFS('Cutters Consumption Updates'!$E:$E,'Cutters Consumption Updates'!$D:$D,J$1,'Cutters Consumption Updates'!$B:$B,$B2)+ SUMIF('Cutters Consumption Updates'!$AS:$AS,$B2,'Cutters Consumption Updates'!AV:AV) -> 0 | K2: =SUMIFS('Cutters Consumption Updates'!$F:$F,'Cutters Consumption Updates'!$D:$D,K$1,'Cutters Consumption Updates'!$B:$B,$B2)-SUMIFS('Cutters Consumption Updates'!$E:$E,'Cutters Consumption Updates'!$D:$D,K$1,'Cutters Consumption Updates'!$B:$B,$B2)+ SUMIF('Cutters Consumption Updates'!$AS:$AS,$B2,'Cutters Consumption Updates'!AW:AW) -> 2 | L2: =SUMIFS('Cutters Consumption Updates'!$F:$F,'Cutters Consumption Updates'!$D:$D,L$1,'Cutters Consumption Updates'!$B:$B,$B2)-SUMIFS('Cutters Consumption Updates'!$E:$E,'Cutters Consumption Updates'!$D:$D,$L$1,'Cutters Consumption Updates'!$B:$B,$B2)+SUMIFS('Cutters Consumption Updates'!$F:$F,'Cutters Consumption Updates'!$D:$D,"Retrofit",'Cutters Consumption Updates'!$B:$B,$B2)-SUMIFS('Cutters Consumption Updates'!$E:$E,'Cutters Consumption Updates'!$D:$D,"Retrofit",'Cutters Consumption Updates'!$B:$B,$B2)+ SUMIF('Cutters Consumption Updates'!$AS:$AS,$B2,'Cutters Consumption Updates'!AX:AX) -> 0 | M2: =L2+H2 -> 0 | N2: =SUMIFS('Cutters Consumption Updates'!E:E, 'Cutters Consumption Updates'!B:B, B2, 'Cutters Consumption Updates'!A:A, ">" & TODAY()-182) -> 11 | O2: =SUMIFS('Cutters Consumption Updates'!E:E, 'Cutters Consumption Updates'!B:B, B2, 'Cutters Consumption Updates'!A:A, ">" & TODAY()-91) -> 11 | P2: =IF(N2<>0,_xlfn.CEILING.MATH(N2/3),0) -> 4 | Q2: =IF(P2<=1, 0, CEILING( IF(P2>=300, P2+10, IF(P2>=200, P2+5, IF(P2>=100, P2+5, IF(P2>=50, P2+2, IF(P2>=20, P2+2, IF(P2>=10, P2+2, IF(P2>=5, P2+2, P2+1))))))), 5)) -> 5 | S2: =IFERROR(INDEX(Table5[],MATCH($B2,Table5[Component],0),2),0) -> 0 | T2: =SUMIFS(Table7[Balance],Table7[Cutter Mat'#],$B2) -> 0 | U2: =M2+T2-S2 -> 0 | Y2: =IFERROR(INDEX(Table5[],MATCH($B2,Table5[Component],0),2),0) -> 0 | Z2: =IFERROR(INDEX(Table5[],MATCH($B2,Table5[Component],0),1),0) -> 0 | AA2: =IF(Y2<>0,B2,"") | AB2: =IF(S2<>Y2,1,"") | AD2: =H2+I2+J2+L2 -> 0 | AI2: =IFERROR(INDEX($B$1:$AK$243,MATCH(W2,$B$1:$B$243,0),13),"") | AJ2: =IFERROR(INDEX($B$1:$AK$243,MATCH(W2,$B$1:$B$243,0),15),"") | AK2: =SUMIF($W$2:$W$243,B2,$S$2:$S$243) -> 0 | AP2: =T2 -> 0 | AR2: {=_xlfn._xlws.SORT(_xlfn.UNIQUE(B:B))} -> 177778 | AS2: =SUMIF($B:$B,AR2,$AP:$AP) -> 0
A3: 2 | B3: 179692 | C3: 1313 OBS ERC 18C | D3: OBS ERC | E3: 1313 | F3: 18C | G3: B - Standard ( Base ) | H3: =SUMIFS('Cutters Consumption Updates'!$F:$F,'Cutters Consumption Updates'!$D:$D,H$1,'Cutters Consumption Updates'!$B:$B,$B3)-SUMIFS('Cutters Consumption Updates'!$E:$E,'Cutters Consumption Updates'!$D:$D,H$1,'Cutters Consumption Updates'!$B:$B,$B3)+ SUMIF('Cutters Consumption Updates'!$AS:$AS,$B3,'Cutters Consumption Updates'!AT:AT) -> 0 | I3: =SUMIFS('Cutters Consumption Updates'!$F:$F,'Cutters Consumption Updates'!$D:$D,I$1,'Cutters Consumption Updates'!$B:$B,$B3)-SUMIFS('Cutters Consumption Updates'!$E:$E,'Cutters Consumption Updates'!$D:$D,I$1,'Cutters Consumption Updates'!$B:$B,$B3)+ SUMIF('Cutters Consumption Updates'!$AS:$AS,$B3,'Cutters Consumption Updates'!AU:AU) -> 12 | J3: =SUMIFS('Cutters Consumption Updates'!$F:$F,'Cutters Consumption Updates'!$D:$D,J$1,'Cutters Consumption Updates'!$B:$B,$B3)-SUMIFS('Cutters Consumption Updates'!$E:$E,'Cutters Consumption Updates'!$D:$D,J$1,'Cutters Consumption Updates'!$B:$B,$B3)+ SUMIF('Cutters Consumption Updates'!$AS:$AS,$B3,'Cutters Consumption Updates'!AV:AV) -> 0 | K3: =SUMIFS('Cutters Consumption Updates'!$F:$F,'Cutters Consumption Updates'!$D:$D,K$1,'Cutters Consumption Updates'!$B:$B,$B3)-SUMIFS('Cutters Consumption Updates'!$E:$E,'Cutters Consumption Updates'!$D:$D,K$1,'Cutters Consumption Updates'!$B:$B,$B3)+ SUMIF('Cutters Consumption Updates'!$AS:$AS,$B3,'Cutters Consumption Updates'!AW:AW) -> 0 | L3: =SUMIFS('Cutters Consumption Updates'!$F:$F,'Cutters Consumption Updates'!$D:$D,L$1,'Cutters Consumption Updates'!$B:$B,$B3)-SUMIFS('Cutters Consumption Updates'!$E:$E,'Cutters Consumption Updates'!$D:$D,$L$1,'Cutters Consumption Updates'!$B:$B,$B3)+SUMIFS('Cutters Consumption Updates'!$F:$F,'Cutters Consumption Updates'!$D:$D,"Retrofit",'Cutters Consumption Updates'!$B:$B,$B3)-SUMIFS('Cutters Consumption Updates'!$E:$E,'Cutters Consumption Updates'!$D:$D,"Retrofit",'Cutters Consumption Updates'!$B:$B,$B3)+ SUMIF('Cutters Consumption Updates'!$AS:$AS,$B3,'Cutters Consumption Updates'!AX:AX) -> 0 | M3: =L3+H3 -> 0 | N3: =SUMIFS('Cutters Consumption Updates'!E:E, 'Cutters Consumption Updates'!B:B, B3, 'Cutters Consumption Updates'!A:A, ">" & TODAY()-182) -> 0 | O3: =SUMIFS('Cutters Consumption Updates'!E:E, 'Cutters Consumption Updates'!B:B, B3, 'Cutters Consumption Updates'!A:A, ">" & TODAY()-91) -> 0 | P3: =IF(N3<>0,_xlfn.CEILING.MATH(N3/3),0) -> 0 | Q3: =IF(P3<=1, 0, CEILING( IF(P3>=300, P3+10, IF(P3>=200, P3+5, IF(P3>=100, P3+5, IF(P3>=50, P3+2, IF(P3>=20, P3+2, IF(P3>=10, P3+2, IF(P3>=5, P3+2, P3+1))))))), 5)) -> 0 | S3: =IFERROR(INDEX(Table5[],MATCH($B3,Table5[Component],0),2),0) -> 0 | T3: =SUMIFS(Table7[Balance],Table7[Cutter Mat'#],$B3) -> 0 | U3: =M3+T3-S3 -> 0 | Y3: =IFERROR(INDEX(Table5[],MATCH($B3,Table5[Component],0),2),0) -> 0 | Z3: =IFERROR(INDEX(Table5[],MATCH($B3,Table5[Component],0),1),0) -> 0 | AA3: =IF(Y3<>0,B3,"") | AB3: =IF(S3<>Y3,1,"") | AD3: =H3+I3+J3+L3 -> 12 | AI3: =IFERROR(INDEX($B$1:$AK$243,MATCH(W3,$B$1:$B$243,0),13),"") | AJ3: =IFERROR(INDEX($B$1:$AK$243,MATCH(W3,$B$1:$B$243,0),15),"") | AK3: =SUMIF($W$2:$W$243,B3,$S$2:$S$243) -> 0 | AP3: =T3 -> 0 | AR3: 179692 | AS3: =SUMIF($B:$B,AR3,$AP:$AP) -> 0
A4: 3 | B4: 179694 | C4: 1308 OBS ERC 18C | D4: OBS ERC | E4: 1308 | F4: 18C | G4: B - Standard ( Base ) | H4: =SUMIFS('Cutters Consumption Updates'!$F:$F,'Cutters Consumption Updates'!$D:$D,H$1,'Cutters Consumption Updates'!$B:$B,$B4)-SUMIFS('Cutters Consumption Updates'!$E:$E,'Cutters Consumption Updates'!$D:$D,H$1,'Cutters Consumption Updates'!$B:$B,$B4)+ SUMIF('Cutters Consumption Updates'!$AS:$AS,$B4,'Cutters Consumption Updates'!AT:AT) -> 0 | I4: =SUMIFS('Cutters Consumption Updates'!$F:$F,'Cutters Consumption Updates'!$D:$D,I$1,'Cutters Consumption Updates'!$B:$B,$B4)-SUMIFS('Cutters Consumption Updates'!$E:$E,'Cutters Consumption Updates'!$D:$D,I$1,'Cutters Consumption Updates'!$B:$B,$B4)+ SUMIF('Cutters Consumption Updates'!$AS:$AS,$B4,'Cutters Consumption Updates'!AU:AU) -> 8 | J4: =SUMIFS('Cutters Consumption Updates'!$F:$F,'Cutters Consumption Updates'!$D:$D,J$1,'Cutters Consumption Updates'!$B:$B,$B4)-SUMIFS('Cutters Consumption Updates'!$E:$E,'Cutters Consumption Updates'!$D:$D,J$1,'Cutters Consumption Updates'!$B:$B,$B4)+ SUMIF('Cutters Consumption Updates'!$AS:$AS,$B4,'Cutters Consumption Updates'!AV:AV) -> 0 | K4: =SUMIFS('Cutters Consumption Updates'!$F:$F,'Cutters Consumption Updates'!$D:$D,K$1,'Cutters Consumption Updates'!$B:$B,$B4)-SUMIFS('Cutters Consumption Updates'!$E:$E,'Cutters Consumption Updates'!$D:$D,K$1,'Cutters Consumption Updates'!$B:$B,$B4)+ SUMIF('Cutters Consumption Updates'!$AS:$AS,$B4,'Cutters Consumption Updates'!AW:AW) -> 0 | L4: =SUMIFS('Cutters Consumption Updates'!$F:$F,'Cutters Consumption Updates'!$D:$D,L$1,'Cutters Consumption Updates'!$B:$B,$B4)-SUMIFS('Cutters Consumption Updates'!$E:$E,'Cutters Consumption Updates'!$D:$D,$L$1,'Cutters Consumption Updates'!$B:$B,$B4)+SUMIFS('Cutters Consumption Updates'!$F:$F,'Cutters Consumption Updates'!$D:$D,"Retrofit",'Cutters Consumption Updates'!$B:$B,$B4)-SUMIFS('Cutters Consumption Updates'!$E:$E,'Cutters Consumption Updates'!$D:$D,"Retrofit",'Cutters Consumption Updates'!$B:$B,$B4)+ SUMIF('Cutters Consumption Updates'!$AS:$AS,$B4,'Cutters Consumption Updates'!AX:AX) -> 0 | M4: =L4+H4 -> 0 | N4: =SUMIFS('Cutters Consumption Updates'!E:E, 'Cutters Consumption Updates'!B:B, B4, 'Cutters Consumption Updates'!A:A, ">" & TODAY()-182) -> 0 | O4: =SUMIFS('Cutters Consumption Updates'!E:E, 'Cutters Consumption Updates'!B:B, B4, 'Cutters Consumption Updates'!A:A, ">" & TODAY()-91) -> 0 | P4: =IF(N4<>0,_xlfn.CEILING.MATH(N4/3),0) -> 0 | Q4: =IF(P4<=1, 0, CEILING( IF(P4>=300, P4+10, IF(P4>=200, P4+5, IF(P4>=100, P4+5, IF(P4>=50, P4+2, IF(P4>=20, P4+2, IF(P4>=10, P4+2, IF(P4>=5, P4+2, P4+1))))))), 5)) -> 0 | S4: =IFERROR(INDEX(Table5[],MATCH($B4,Table5[Component],0),2),0) -> 0 | T4: =SUMIFS(Table7[Balance],Table7[Cutter Mat'#],$B4) -> 0 | U4: =M4+T4-S4 -> 0 | Y4: =IFERROR(INDEX(Table5[],MATCH($B4,Table5[Component],0),2),0) -> 0 | Z4: =IFERROR(INDEX(Table5[],MATCH($B4,Table5[Component],0),1),0) -> 0 | AA4: =IF(Y4<>0,B4,"") | AB4: =IF(S4<>Y4,1,"") | AD4: =H4+I4+J4+L4 -> 8 | AI4: =IFERROR(INDEX($B$1:$AK$243,MATCH(W4,$B$1:$B$243,0),13),"") | AJ4: =IFERROR(INDEX($B$1:$AK$243,MATCH(W4,$B$1:$B$243,0),15),"") | AK4: =SUMIF($W$2:$W$243,B4,$S$2:$S$243) -> 0 | AP4: =T4 -> 0 | AR4: 179694 | AS4: =SUMIF($B:$B,AR4,$AP:$AP) -> 0
A5: 4 | B5: 179734 | C5: 13MM WC-MAT400 LONG M1 IA-STL | D5: M1 IA-STL | E5: 13MM | F5: N/A | G5: D - Depth of Cut Control Elements | H5: =SUMIFS('Cutters Consumption Updates'!$F:$F,'Cutters Consumption Updates'!$D:$D,H$1,'Cutters Consumption Updates'!$B:$B,$B5)-SUMIFS('Cutters Consumption Updates'!$E:$E,'Cutters Consumption Updates'!$D:$D,H$1,'Cutters Consumption Updates'!$B:$B,$B5)+ SUMIF('Cutters Consumption Updates'!$AS:$AS,$B5,'Cutters Consumption Updates'!AT:AT) -> 0 | I5: =SUMIFS('Cutters Consumption Updates'!$F:$F,'Cutters Consumption Updates'!$D:$D,I$1,'Cutters Consumption Updates'!$B:$B,$B5)-SUMIFS('Cutters Consumption Updates'!$E:$E,'Cutters Consumption Updates'!$D:$D,I$1,'Cutters Consumption Updates'!$B:$B,$B5)+ SUMIF('Cutters Consumption Updates'!$AS:$AS,$B5,'Cutters Consumption Updates'!AU:AU) -> 0 | J5: =SUMIFS('Cutters Consumption Updates'!$F:$F,'Cutters Consumption Updates'!$D:$D,J$1,'Cutters Consumption Updates'!$B:$B,$B5)-SUMIFS('Cutters Consumption Updates'!$E:$E,'Cutters Consumption Updates'!$D:$D,J$1,'Cutters Consumption Updates'!$B:$B,$B5)+ SUMIF('Cutters Consumption Updates'!$AS:$AS,$B5,'Cutters Consumption Updates'!AV:AV) -> 0 | K5: =SUMIFS('Cutters Consumption Updates'!$F:$F,'Cutters Consumption Updates'!$D:$D,K$1,'Cutters Consumption Updates'!$B:$B,$B5)-SUMIFS('Cutters Consumption Updates'!$E:$E,'Cutters Consumption Updates'!$D:$D,K$1,'Cutters Consumption Updates'!$B:$B,$B5)+ SUMIF('Cutters Consumption Updates'!$AS:$AS,$B5,'Cutters Consumption Updates'!AW:AW) -> 9 | L5: =SUMIFS('Cutters Consumption Updates'!$F:$F,'Cutters Consumption Updates'!$D:$D,L$1,'Cutters Consumption Updates'!$B:$B,$B5)-SUMIFS('Cutters Consumption Updates'!$E:$E,'Cutters Consumption Updates'!$D:$D,$L$1,'Cutters Consumption Updates'!$B:$B,$B5)+SUMIFS('Cutters Consumption Updates'!$F:$F,'Cutters Consumption Updates'!$D:$D,"Retrofit",'Cutters Consumption Updates'!$B:$B,$B5)-SUMIFS('Cutters Consumption Updates'!$E:$E,'Cutters Consumption Updates'!$D:$D,"Retrofit",'Cutters Consumption Updates'!$B:$B,$B5)+ SUMIF('Cutters Consumption Updates'!$AS:$AS,$B5,'Cutters Consumption Updates'!AX:AX) -> 137 | M5: =L5+H5 -> 137 | N5: =SUMIFS('Cutters Consumption Updates'!E:E, 'Cutters Consumption Updates'!B:B, B5, 'Cutters Consumption Updates'!A:A, ">" & TODAY()-182) -> 140 | O5: =SUMIFS('Cutters Consumption Updates'!E:E, 'Cutters Consumption Updates'!B:B, B5, 'Cutters Consumption Updates'!A:A, ">" & TODAY()-91) -> 70 | P5: =IF(N5<>0,_xlfn.CEILING.MATH(N5/3),0) -> 47 | Q5: =IF(P5<=1, 0, CEILING( IF(P5>=300, P5+10, IF(P5>=200, P5+5, IF(P5>=100, P5+5, IF(P5>=50, P5+2, IF(P5>=20, P5+2, IF(P5>=10, P5+2, IF(P5>=5, P5+2, P5+1))))))), 5)) -> 50 | S5: =IFERROR(INDEX(Table5[],MATCH($B5,Table5[Component],0),2),0) -> 342 | T5: =SUMIFS(Table7[Balance],Table7[Cutter Mat'#],$B5) -> 0 | U5: =M5+T5-S5 -> -205 | Y5: =IFERROR(INDEX(Table5[],MATCH($B5,Table5[Component],0),2),0) -> 342 | Z5: =IFERROR(INDEX(Table5[],MATCH($B5,Table5[Component],0),1),0) -> 179734 | AA5: =IF(Y5<>0,B5,"") -> 179734 | AB5: =IF(S5<>Y5,1,"") | AD5: =H5+I5+J5+L5 -> 137 | AI5: =IFERROR(INDEX($B$1:$AK$243,MATCH(W5,$B$1:$B$243,0),13),"") | AJ5: =IFERROR(INDEX($B$1:$AK$243,MATCH(W5,$B$1:$B$243,0),15),"") | AK5: =SUMIF($W$2:$W$243,B5,$S$2:$S$243) -> 0 | AP5: =T5 -> 0 | AR5: 179733 | AS5: =SUMIF($B:$B,AR5,$AP:$AP) -> 0
A6: 5 | B6: 179790 | C6: 1613 OBS ERC 18C | D6: OBS ERC | E6: 1613 | F6: 18C | G6: B - Standard ( Base ) | H6: =SUMIFS('Cutters Consumption Updates'!$F:$F,'Cutters Consumption Updates'!$D:$D,H$1,'Cutters Consumption Updates'!$B:$B,$B6)-SUMIFS('Cutters Consumption Updates'!$E:$E,'Cutters Consumption Updates'!$D:$D,H$1,'Cutters Consumption Updates'!$B:$B,$B6)+ SUMIF('Cutters Consumption Updates'!$AS:$AS,$B6,'Cutters Consumption Updates'!AT:AT) -> 21 | I6: =SUMIFS('Cutters Consumption Updates'!$F:$F,'Cutters Consumption Updates'!$D:$D,I$1,'Cutters Consumption Updates'!$B:$B,$B6)-SUMIFS('Cutters Consumption Updates'!$E:$E,'Cutters Consumption Updates'!$D:$D,I$1,'Cutters Consumption Updates'!$B:$B,$B6)+ SUMIF('Cutters Consumption Updates'!$AS:$AS,$B6,'Cutters Consumption Updates'!AU:AU) -> 0 | J6: =SUMIFS('Cutters Consumption Updates'!$F:$F,'Cutters Consumption Updates'!$D:$D,J$1,'Cutters Consumption Updates'!$B:$B,$B6)-SUMIFS('Cutters Consumption Updates'!$E:$E,'Cutters Consumption Updates'!$D:$D,J$1,'Cutters Consumption Updates'!$B:$B,$B6)+ SUMIF('Cutters Consumption Updates'!$AS:$AS,$B6,'Cutters Consumption Updates'!AV:AV) -> 0 | K6: =SUMIFS('Cutters Consumption Updates'!$F:$F,'Cutters Consumption Updates'!$D:$D,K$1,'Cutters Consumption Updates'!$B:$B,$B6)-SUMIFS('Cutters Consumption Updates'!$E:$E,'Cutters Consumption Updates'!$D:$D,K$1,'Cutters Consumption Updates'!$B:$B,$B6)+ SUMIF('Cutters Consumption Updates'!$AS:$AS,$B6,'Cutters Consumption Updates'!AW:AW) -> 0 | L6: =SUMIFS('Cutters Consumption Updates'!$F:$F,'Cutters Consumption Updates'!$D:$D,L$1,'Cutters Consumption Updates'!$B:$B,$B6)-SUMIFS('Cutters Consumption Updates'!$E:$E,'Cutters Consumption Updates'!$D:$D,$L$1,'Cutters Consumption Updates'!$B:$B,$B6)+SUMIFS('Cutters Consumption Updates'!$F:$F,'Cutters Consumption Updates'!$D:$D,"Retrofit",'Cutters Consumption Updates'!$B:$B,$B6)-SUMIFS('Cutters Consumption Updates'!$E:$E,'Cutters Consumption Updates'!$D:$D,"Retrofit",'Cutters Consumption Updates'!$B:$B,$B6)+ SUMIF('Cutters Consumption Updates'!$AS:$AS,$B6,'Cutters Consumption Updates'!AX:AX) -> 0 | M6: =L6+H6 -> 21 | N6: =SUMIFS('Cutters Consumption Updates'!E:E, 'Cutters Consumption Updates'!B:B, B6, 'Cutters Consumption Updates'!A:A, ">" & TODAY()-182) -> 1 | O6: =SUMIFS('Cutters Consumption Updates'!E:E, 'Cutters Consumption Updates'!B:B, B6, 'Cutters Consumption Updates'!A:A, ">" & TODAY()-91) -> 1 | P6: =IF(N6<>0,_xlfn.CEILING.MATH(N6/3),0) -> 1 | Q6: =IF(P6<=1, 0, CEILING( IF(P6>=300, P6+10, IF(P6>=200, P6+5, IF(P6>=100, P6+5, IF(P6>=50, P6+2, IF(P6>=20, P6+2, IF(P6>=10, P6+2, IF(P6>=5, P6+2, P6+1))))))), 5)) -> 0 | S6: =IFERROR(INDEX(Table5[],MATCH($B6,Table5[Component],0),2),0) -> 0 | T6: =SUMIFS(Table7[Balance],Table7[Cutter Mat'#],$B6) -> 0 | U6: =M6+T6-S6 -> 21 | Y6: =IFERROR(INDEX(Table5[],MATCH($B6,Table5[Component],0),2),0) -> 0 | Z6: =IFERROR(INDEX(Table5[],MATCH($B6,Table5[Component],0),1),0) -> 0 | AA6: =IF(Y6<>0,B6,"") | AB6: =IF(S6<>Y6,1,"") | AD6: =H6+I6+J6+L6 -> 21 | AI6: =IFERROR(INDEX($B$1:$AK$243,MATCH(W6,$B$1:$B$243,0),13),"") | AJ6: =IFERROR(INDEX($B$1:$AK$243,MATCH(W6,$B$1:$B$243,0),15),"") | AK6: =SUMIF($W$2:$W$243,B6,$S$2:$S$243) -> 0 | AP6: =T6 -> 0 | AR6: 179734 | AS6: =SUMIF($B:$B,AR6,$AP:$AP) -> 0
A7: 6 | B7: 375538 | C7: 13MM R1 .012R LG BVL | D7: R1 0.012R | E7: 13MM | F7: N/A | G7: D - Depth of Cut Control Elements | H7: =SUMIFS('Cutters Consumption Updates'!$F:$F,'Cutters Consumption Updates'!$D:$D,H$1,'Cutters Consumption Updates'!$B:$B,$B7)-SUMIFS('Cutters Consumption Updates'!$E:$E,'Cutters Consumption Updates'!$D:$D,H$1,'Cutters Consumption Updates'!$B:$B,$B7)+ SUMIF('Cutters Consumption Updates'!$AS:$AS,$B7,'Cutters Consumption Updates'!AT:AT) -> 26 | I7: =SUMIFS('Cutters Consumption Updates'!$F:$F,'Cutters Consumption Updates'!$D:$D,I$1,'Cutters Consumption Updates'!$B:$B,$B7)-SUMIFS('Cutters Consumption Updates'!$E:$E,'Cutters Consumption Updates'!$D:$D,I$1,'Cutters Consumption Updates'!$B:$B,$B7)+ SUMIF('Cutters Consumption Updates'!$AS:$AS,$B7,'Cutters Consumption Updates'!AU:AU) -> 0 | J7: =SUMIFS('Cutters Consumption Updates'!$F:$F,'Cutters Consumption Updates'!$D:$D,J$1,'Cutters Consumption Updates'!$B:$B,$B7)-SUMIFS('Cutters Consumption Updates'!$E:$E,'Cutters Consumption Updates'!$D:$D,J$1,'Cutters Consumption Updates'!$B:$B,$B7)+ SUMIF('Cutters Consumption Updates'!$AS:$AS,$B7,'Cutters Consumption Updates'!AV:AV) -> 0 | K7: =SUMIFS('Cutters Consumption Updates'!$F:$F,'Cutters Consumption Updates'!$D:$D,K$1,'Cutters Consumption Updates'!$B:$B,$B7)-SUMIFS('Cutters Consumption Updates'!$E:$E,'Cutters Consumption Updates'!$D:$D,K$1,'Cutters Consumption Updates'!$B:$B,$B7)+ SUMIF('Cutters Consumption Updates'!$AS:$AS,$B7,'Cutters Consumption Updates'!AW:AW) -> 33 | L7: =SUMIFS('Cutters Consumption Updates'!$F:$F,'Cutters Consumption Updates'!$D:$D,L$1,'Cutters Consumption Updates'!$B:$B,$B7)-SUMIFS('Cutters Consumption Updates'!$E:$E,'Cutters Consumption Updates'!$D:$D,$L$1,'Cutters Consumption Updates'!$B:$B,$B7)+SUMIFS('Cutters Consumption Updates'!$F:$F,'Cutters Consumption Updates'!$D:$D,"Retrofit",'Cutters Consumption Updates'!$B:$B,$B7)-SUMIFS('Cutters Consumption Updates'!$E:$E,'Cutters Consumption Updates'!$D:$D,"Retrofit",'Cutters Consumption Updates'!$B:$B,$B7)+ SUMIF('Cutters Consumption Updates'!$AS:$AS,$B7,'Cutters Consumption Updates'!AX:AX) -> 11 | M7: =L7+H7 -> 37 | N7: =SUMIFS('Cutters Consumption Updates'!E:E, 'Cutters Consumption Updates'!B:B, B7, 'Cutters Consumption Updates'!A:A, ">" & TODAY()-182) -> 0 | O7: =SUMIFS('Cutters Consumption Updates'!E:E, 'Cutters Consumption Updates'!B:B, B7, 'Cutters Consumption Updates'!A:A, ">" & TODAY()-91) -> 0 | P7: =IF(N7<>0,_xlfn.CEILING.MATH(N7/3),0) -> 0 | Q7: =IF(P7<=1, 0, CEILING( IF(P7>=300, P7+10, IF(P7>=200, P7+5, IF(P7>=100, P7+5, IF(P7>=50, P7+2, IF(P7>=20, P7+2, IF(P7>=10, P7+2, IF(P7>=5, P7+2, P7+1))))))), 5)) -> 0 | S7: =IFERROR(INDEX(Table5[],MATCH($B7,Table5[Component],0),2),0) -> 24 | T7: =SUMIFS(Table7[Balance],Table7[Cutter Mat'#],$B7) -> 0 | U7: =M7+T7-S7 -> 13 | Y7: =IFERROR(INDEX(Table5[],MATCH($B7,Table5[Component],0),2),0) -> 24 | Z7: =IFERROR(INDEX(Table5[],MATCH($B7,Table5[Component],0),1),0) -> 375538 | AA7: =IF(Y7<>0,B7,"") -> 375538 | AB7: =IF(S7<>Y7,1,"") | AD7: =H7+I7+J7+L7 -> 37 | AI7: =IFERROR(INDEX($B$1:$AK$243,MATCH(W7,$B$1:$B$243,0),13),"") | AJ7: =IFERROR(INDEX($B$1:$AK$243,MATCH(W7,$B$1:$B$243,0),15),"") | AK7: =SUMIF($W$2:$W$243,B7,$S$2:$S$243) -> 0 | AP7: =T7 -> 0 | AR7: 179790 | AS7: =SUMIF($B:$B,AR7,$AP:$AP) -> 0
A8: 7 | B8: 399930 | C8: 19MMS SHORT BULLET CT27 18C | D8: CT27 | E8: 19MMS | F8: 18C | G8: P - Premium | H8: =SUMIFS('Cutters Consumption Updates'!$F:$F,'Cutters Consumption Updates'!$D:$D,H$1,'Cutters Consumption Updates'!$B:$B,$B8)-SUMIFS('Cutters Consumption Updates'!$E:$E,'Cutters Consumption Updates'!$D:$D,H$1,'Cutters Consumption Updates'!$B:$B,$B8)+ SUMIF('Cutters Consumption Updates'!$AS:$AS,$B8,'Cutters Consumption Updates'!AT:AT) -> 0 | I8: =SUMIFS('Cutters Consumption Updates'!$F:$F,'Cutters Consumption Updates'!$D:$D,I$1,'Cutters Consumption Updates'!$B:$B,$B8)-SUMIFS('Cutters Consumption Updates'!$E:$E,'Cutters Consumption Updates'!$D:$D,I$1,'Cutters Consumption Updates'!$B:$B,$B8)+ SUMIF('Cutters Consumption Updates'!$AS:$AS,$B8,'Cutters Consumption Updates'!AU:AU) -> 0 | J8: =SUMIFS('Cutters Consumption Updates'!$F:$F,'Cutters Consumption Updates'!$D:$D,J$1,'Cutters Consumption Updates'!$B:$B,$B8)-SUMIFS('Cutters Consumption Updates'!$E:$E,'Cutters Consumption Updates'!$D:$D,J$1,'Cutters Consumption Updates'!$B:$B,$B8)+ SUMIF('Cutters Consumption Updates'!$AS:$AS,$B8,'Cutters Consumption Updates'!AV:AV) -> 0 | K8: =SUMIFS('Cutters Consumption Updates'!$F:$F,'Cutters Consumption Updates'!$D:$D,K$1,'Cutters Consumption Updates'!$B:$B,$B8)-SUMIFS('Cutters Consumption Updates'!$E:$E,'Cutters Consumption Updates'!$D:$D,K$1,'Cutters Consumption Updates'!$B:$B,$B8)+ SUMIF('Cutters Consumption Updates'!$AS:$AS,$B8,'Cutters Consumption Updates'!AW:AW) -> 24 | L8: =SUMIFS('Cutters Consumption Updates'!$F:$F,'Cutters Consumption Updates'!$D:$D,L$1,'Cutters Consumption Updates'!$B:$B,$B8)-SUMIFS('Cutters Consumption Updates'!$E:$E,'Cutters Consumption Updates'!$D:$D,$L$1,'Cutters Consumption Updates'!$B:$B,$B8)+SUMIFS('Cutters Consumption Updates'!$F:$F,'Cutters Consumption Updates'!$D:$D,"Retrofit",'Cutters Consumption Updates'!$B:$B,$B8)-SUMIFS('Cutters Consumption Updates'!$E:$E,'Cutters Consumption Updates'!$D:$D,"Retrofit",'Cutters Consumption Updates'!$B:$B,$B8)+ SUMIF('Cutters Consumption Updates'!$AS:$AS,$B8,'Cutters Consumption Updates'!AX:AX) -> 1 | M8: =L8+H8 -> 1 | N8: =SUMIFS('Cutters Consumption Updates'!E:E, 'Cutters Consumption Updates'!B:B, B8, 'Cutters Consumption Updates'!A:A, ">" & TODAY()-182) -> 0 | O8: =SUMIFS('Cutters Consumption Updates'!E:E, 'Cutters Consumption Updates'!B:B, B8, 'Cutters Consumption Updates'!A:A, ">" & TODAY()-91) -> 0 | P8: =IF(N8<>0,_xlfn.CEILING.MATH(N8/3),0) -> 0 | Q8: =IF(P8<=1, 0, CEILING( IF(P8>=300, P8+10, IF(P8>=200, P8+5, IF(P8>=100, P8+5, IF(P8>=50, P8+2, IF(P8>=20, P8+2, IF(P8>=10, P8+2, IF(P8>=5, P8+2, P8+1))))))), 5)) -> 0 | S8: =IFERROR(INDEX(Table5[],MATCH($B8,Table5[Component],0),2),0) -> 0 | T8: =SUMIFS(Table7[Balance],Table7[Cutter Mat'#],$B8) -> 0 | U8: =M8+T8-S8 -> 1 | Y8: =IFERROR(INDEX(Table5[],MATCH($B8,Table5[Component],0),2),0) -> 0 | Z8: =IFERROR(INDEX(Table5[],MATCH($B8,Table5[Component],0),1),0) -> 0 | AA8: =IF(Y8<>0,B8,"") | AB8: =IF(S8<>Y8,1,"") | AD8: =H8+I8+J8+L8 -> 1 | AI8: =IFERROR(INDEX($B$1:$AK$243,MATCH(W8,$B$1:$B$243,0),13),"") | AJ8: =IFERROR(INDEX($B$1:$AK$243,MATCH(W8,$B$1:$B$243,0),15),"") | AK8: =SUMIF($W$2:$W$243,B8,$S$2:$S$243) -> 0 | AP8: =T8 -> 0 | AR8: 375538 | AS8: =SUMIF($B:$B,AR8,$AP:$AP) -> 0
A9: 8 | B9: 584832 | C9: 1913 CT62 10C | D9: CT62 | E9: 1913 | F9: 10C | G9: B - Standard ( Base ) | H9: =SUMIFS('Cutters Consumption Updates'!$F:$F,'Cutters Consumption Updates'!$D:$D,H$1,'Cutters Consumption Updates'!$B:$B,$B9)-SUMIFS('Cutters Consumption Updates'!$E:$E,'Cutters Consumption Updates'!$D:$D,H$1,'Cutters Consumption Updates'!$B:$B,$B9)+ SUMIF('Cutters Consumption Updates'!$AS:$AS,$B9,'Cutters Consumption Updates'!AT:AT) -> 0 | I9: =SUMIFS('Cutters Consumption Updates'!$F:$F,'Cutters Consumption Updates'!$D:$D,I$1,'Cutters Consumption Updates'!$B:$B,$B9)-SUMIFS('Cutters Consumption Updates'!$E:$E,'Cutters Consumption Updates'!$D:$D,I$1,'Cutters Consumption Updates'!$B:$B,$B9)+ SUMIF('Cutters Consumption Updates'!$AS:$AS,$B9,'Cutters Consumption Updates'!AU:AU) -> 0 | J9: =SUMIFS('Cutters Consumption Updates'!$F:$F,'Cutters Consumption Updates'!$D:$D,J$1,'Cutters Consumption Updates'!$B:$B,$B9)-SUMIFS('Cutters Consumption Updates'!$E:$E,'Cutters Consumption Updates'!$D:$D,J$1,'Cutters Consumption Updates'!$B:$B,$B9)+ SUMIF('Cutters Consumption Updates'!$AS:$AS,$B9,'Cutters Consumption Updates'!AV:AV) -> 0 | K9: =SUMIFS('Cutters Consumption Updates'!$F:$F,'Cutters Consumption Updates'!$D:$D,K$1,'Cutters Consumption Updates'!$B:$B,$B9)-SUMIFS('Cutters Consumption Updates'!$E:$E,'Cutters Consumption Updates'!$D:$D,K$1,'Cutters Consumption Updates'!$B:$B,$B9)+ SUMIF('Cutters Consumption Updates'!$AS:$AS,$B9,'Cutters Consumption Updates'!AW:AW) -> 0 | L9: =SUMIFS('Cutters Consumption Updates'!$F:$F,'Cutters Consumption Updates'!$D:$D,L$1,'Cutters Consumption Updates'!$B:$B,$B9)-SUMIFS('Cutters Consumption Updates'!$E:$E,'Cutters Consumption Updates'!$D:$D,$L$1,'Cutters Consumption Updates'!$B:$B,$B9)+SUMIFS('Cutters Consumption Updates'!$F:$F,'Cutters Consumption Updates'!$D:$D,"Retrofit",'Cutters Consumption Updates'!$B:$B,$B9)-SUMIFS('Cutters Consumption Updates'!$E:$E,'Cutters Consumption Updates'!$D:$D,"Retrofit",'Cutters Consumption Updates'!$B:$B,$B9)+ SUMIF('Cutters Consumption Updates'!$AS:$AS,$B9,'Cutters Consumption Updates'!AX:AX) -> 19 | M9: =L9+H9 -> 19 | N9: =SUMIFS('Cutters Consumption Updates'!E:E, 'Cutters Consumption Updates'!B:B, B9, 'Cutters Consumption Updates'!A:A, ">" & TODAY()-182) -> 0 | O9: =SUMIFS('Cutters Consumption Updates'!E:E, 'Cutters Consumption Updates'!B:B, B9, 'Cutters Consumption Updates'!A:A, ">" & TODAY()-91) -> 0 | P9: =IF(N9<>0,_xlfn.CEILING.MATH(N9/3),0) -> 0 | Q9: =IF(P9<=1, 0, CEILING( IF(P9>=300, P9+10, IF(P9>=200, P9+5, IF(P9>=100, P9+5, IF(P9>=50, P9+2, IF(P9>=20, P9+2, IF(P9>=10, P9+2, IF(P9>=5, P9+2, P9+1))))))), 5)) -> 0 | S9: =IFERROR(INDEX(Table5[],MATCH($B9,Table5[Component],0),2),0) -> 0 | T9: =SUMIFS(Table7[Balance],Table7[Cutter Mat'#],$B9) -> 0 | U9: =M9+T9-S9 -> 19 | Y9: =IFERROR(INDEX(Table5[],MATCH($B9,Table5[Component],0),2),0) -> 0 | Z9: =IFERROR(INDEX(Table5[],MATCH($B9,Table5[Component],0),1),0) -> 0 | AA9: =IF(Y9<>0,B9,"") | AB9: =IF(S9<>Y9,1,"") | AD9: =H9+I9+J9+L9 -> 19 | AI9: =IFERROR(INDEX($B$1:$AK$243,MATCH(W9,$B$1:$B$243,0),13),"") | AJ9: =IFERROR(INDEX($B$1:$AK$243,MATCH(W9,$B$1:$B$243,0),15),"") | AK9: =SUMIF($W$2:$W$243,B9,$S$2:$S$243) -> 0 | AP9: =T9 -> 0 | AR9: 376826 | AS9: =SUMIF($B:$B,AR9,$AP:$AP) -> 0
A10: 9 | B10: 467367 | C10: 1613 CT36 18C | D10: CT36 | E10: 1613 | F10: 18C | G10: S - Super Premium | H10: =SUMIFS('Cutters Consumption Updates'!$F:$F,'Cutters Consumption Updates'!$D:$D,H$1,'Cutters Consumption Updates'!$B:$B,$B10)-SUMIFS('Cutters Consumption Updates'!$E:$E,'Cutters Consumption Updates'!$D:$D,H$1,'Cutters Consumption Updates'!$B:$B,$B10)+ SUMIF('Cutters Consumption Updates'!$AS:$AS,$B10,'Cutters Consumption Updates'!AT:AT) -> 0 | I10: =SUMIFS('Cutters Consumption Updates'!$F:$F,'Cutters Consumption Updates'!$D:$D,I$1,'Cutters Consumption Updates'!$B:$B,$B10)-SUMIFS('Cutters Consumption Updates'!$E:$E,'Cutters Consumption Updates'!$D:$D,I$1,'Cutters Consumption Updates'!$B:$B,$B10)+ SUMIF('Cutters Consumption Updates'!$AS:$AS,$B10,'Cutters Consumption Updates'!AU:AU) -> 0 | J10: =SUMIFS('Cutters Consumption Updates'!$F:$F,'Cutters Consumption Updates'!$D:$D,J$1,'Cutters Consumption Updates'!$B:$B,$B10)-SUMIFS('Cutters Consumption Updates'!$E:$E,'Cutters Consumption Updates'!$D:$D,J$1,'Cutters Consumption Updates'!$B:$B,$B10)+ SUMIF('Cutters Consumption Updates'!$AS:$AS,$B10,'Cutters Consumption Updates'!AV:AV) -> 0 | K10: =SUMIFS('Cutters Consumption Updates'!$F:$F,'Cutters Consumption Updates'!$D:$D,K$1,'Cutters Consumption Updates'!$B:$B,$B10)-SUMIFS('Cutters Consumption Updates'!$E:$E,'Cutters Consumption Updates'!$D:$D,K$1,'Cutters Consumption Updates'!$B:$B,$B10)+ SUMIF('Cutters Consumption Updates'!$AS:$AS,$B10,'Cutters Consumption Updates'!AW:AW) -> 10 | L10: =SUMIFS('Cutters Consumption Updates'!$F:$F,'Cutters Consumption Updates'!$D:$D,L$1,'Cutters Consumption Updates'!$B:$B,$B10)-SUMIFS('Cutters Consumption Updates'!$E:$E,'Cutters Consumption Updates'!$D:$D,$L$1,'Cutters Consumption Updates'!$B:$B,$B10)+SUMIFS('Cutters Consumption Updates'!$F:$F,'Cutters Consumption Updates'!$D:$D,"Retrofit",'Cutters Consumption Updates'!$B:$B,$B10)-SUMIFS('Cutters Consumption Updates'!$E:$E,'Cutters Consumption Updates'!$D:$D,"Retrofit",'Cutters Consumption Updates'!$B:$B,$B10)+ SUMIF('Cutters Consumption Updates'!$AS:$AS,$B10,'Cutters Consumption Updates'!AX:AX) -> 0 | M10: =L10+H10 -> 0 | N10: =SUMIFS('Cutters Consumption Updates'!E:E, 'Cutters Consumption Updates'!B:B, B10, 'Cutters Consumption Updates'!A:A, ">" & TODAY()-182) -> 0 | O10: =SUMIFS('Cutters Consumption Updates'!E:E, 'Cutters Consumption Updates'!B:B, B10, 'Cutters Consumption Updates'!A:A, ">" & TODAY()-91) -> 0 | P10: =IF(N10<>0,_xlfn.CEILING.MATH(N10/3),0) -> 0 | Q10: =IF(P10<=1, 0, CEILING( IF(P10>=300, P10+10, IF(P10>=200, P10+5, IF(P10>=100, P10+5, IF(P10>=50, P10+2, IF(P10>=20, P10+2, IF(P10>=10, P10+2, IF(P10>=5, P10+2, P10+1))))))), 5)) -> 0 | S10: =IFERROR(INDEX(Table5[],MATCH($B10,Table5[Component],0),2),0) -> 0 | T10: =SUMIFS(Table7[Balance],Table7[Cutter Mat'#],$B10) -> 0 | U10: =M10+T10-S10 -> 0 | Y10: =IFERROR(INDEX(Table5[],MATCH($B10,Table5[Component],0),2),0) -> 0 | Z10: =IFERROR(INDEX(Table5[],MATCH($B10,Table5[Component],0),1),0) -> 0 | AA10: =IF(Y10<>0,B10,"") | AB10: =IF(S10<>Y10,1,"") | AD10: =H10+I10+J10+L10 -> 0 | AI10: =IFERROR(INDEX($B$1:$AK$243,MATCH(W10,$B$1:$B$243,0),13),"") | AJ10: =IFERROR(INDEX($B$1:$AK$243,MATCH(W10,$B$1:$B$243,0),15),"") | AK10: =SUMIF($W$2:$W$243,B10,$S$2:$S$243) -> 0 | AP10: =T10 -> 0 | AR10: 397470 | AS10: =SUMIF($B:$B,AR10,$AP:$AP) -> 0
A11: 10 | B11: 535656 | C11: 1608 CT36 10C | D11: CT36 | E11: 1608 | F11: 10C | G11: S - Super Premium | H11: =SUMIFS('Cutters Consumption Updates'!$F:$F,'Cutters Consumption Updates'!$D:$D,H$1,'Cutters Consumption Updates'!$B:$B,$B11)-SUMIFS('Cutters Consumption Updates'!$E:$E,'Cutters Consumption Updates'!$D:$D,H$1,'Cutters Consumption Updates'!$B:$B,$B11)+ SUMIF('Cutters Consumption Updates'!$AS:$AS,$B11,'Cutters Consumption Updates'!AT:AT) -> 0 | I11: =SUMIFS('Cutters Consumption Updates'!$F:$F,'Cutters Consumption Updates'!$D:$D,I$1,'Cutters Consumption Updates'!$B:$B,$B11)-SUMIFS('Cutters Consumption Updates'!$E:$E,'Cutters Consumption Updates'!$D:$D,I$1,'Cutters Consumption Updates'!$B:$B,$B11)+ SUMIF('Cutters Consumption Updates'!$AS:$AS,$B11,'Cutters Consumption Updates'!AU:AU) -> 0 | J11: =SUMIFS('Cutters Consumption Updates'!$F:$F,'Cutters Consumption Updates'!$D:$D,J$1,'Cutters Consumption Updates'!$B:$B,$B11)-SUMIFS('Cutters Consumption Updates'!$E:$E,'Cutters Consumption Updates'!$D:$D,J$1,'Cutters Consumption Updates'!$B:$B,$B11)+ SUMIF('Cutters Consumption Updates'!$AS:$AS,$B11,'Cutters Consumption Updates'!AV:AV) -> 0 | K11: =SUMIFS('Cutters Consumption Updates'!$F:$F,'Cutters Consumption Updates'!$D:$D,K$1,'Cutters Consumption Updates'!$B:$B,$B11)-SUMIFS('Cutters Consumption Updates'!$E:$E,'Cutters Consumption Updates'!$D:$D,K$1,'Cutters Consumption Updates'!$B:$B,$B11)+ SUMIF('Cutters Consumption Updates'!$AS:$AS,$B11,'Cutters Consumption Updates'!AW:AW) -> 0 | L11: =SUMIFS('Cutters Consumption Updates'!$F:$F,'Cutters Consumption Updates'!$D:$D,L$1,'Cutters Consumption Updates'!$B:$B,$B11)-SUMIFS('Cutters Consumption Updates'!$E:$E,'Cutters Consumption Updates'!$D:$D,$L$1,'Cutters Consumption Updates'!$B:$B,$B11)+SUMIFS('Cutters Consumption Updates'!$F:$F,'Cutters Consumption Updates'!$D:$D,"Retrofit",'Cutters Consumption Updates'!$B:$B,$B11)-SUMIFS('Cutters Consumption Updates'!$E:$E,'Cutters Consumption Updates'!$D:$D,"Retrofit",'Cutters Consumption Updates'!$B:$B,$B11)+ SUMIF('Cutters Consumption Updates'!$AS:$AS,$B11,'Cutters Consumption Updates'!AX:AX) -> 28 | M11: =L11+H11 -> 28 | N11: =SUMIFS('Cutters Consumption Updates'!E:E, 'Cutters Consumption Updates'!B:B, B11, 'Cutters Consumption Updates'!A:A, ">" & TODAY()-182) -> 7 | O11: =SUMIFS('Cutters Consumption Updates'!E:E, 'Cutters Consumption Updates'!B:B, B11, 'Cutters Consumption Updates'!A:A, ">" & TODAY()-91) -> 5 | P11: =IF(N11<>0,_xlfn.CEILING.MATH(N11/3),0) -> 3 | Q11: =IF(P11<=1, 0, CEILING( IF(P11>=300, P11+10, IF(P11>=200, P11+5, IF(P11>=100, P11+5, IF(P11>=50, P11+2, IF(P11>=20, P11+2, IF(P11>=10, P11+2, IF(P11>=5, P11+2, P11+1))))))), 5)) -> 5 | S11: =IFERROR(INDEX(Table5[],MATCH($B11,Table5[Component],0),2),0) -> 0 | T11: =SUMIFS(Table7[Balance],Table7[Cutter Mat'#],$B11) -> 0 | U11: =M11+T11-S11 -> 28 | Y11: =IFERROR(INDEX(Table5[],MATCH($B11,Table5[Component],0),2),0) -> 0 | Z11: =IFERROR(INDEX(Table5[],MATCH($B11,Table5[Component],0),1),0) -> 0 | AA11: =IF(Y11<>0,B11,"") | AB11: =IF(S11<>Y11,1,"") | AD11: =H11+I11+J11+L11 -> 28 | AI11: =IFERROR(INDEX($B$1:$AK$243,MATCH(W11,$B$1:$B$243,0),13),"") | AJ11: =IFERROR(INDEX($B$1:$AK$243,MATCH(W11,$B$1:$B$243,0),15),"") | AK11: =SUMIF($W$2:$W$243,B11,$S$2:$S$243) -> 0 | AP11: =T11 -> 0 | AR11: 399930 | AS11: =SUMIF($B:$B,AR11,$AP:$AP) -> 0
A12: 11 | B12: 471108 | C12: 1313 CT36 10C | D12: CT36 | E12: 1313 | F12: 10C | G12: S - Super Premium | H12: =SUMIFS('Cutters Consumption Updates'!$F:$F,'Cutters Consumption Updates'!$D:$D,H$1,'Cutters Consumption Updates'!$B:$B,$B12)-SUMIFS('Cutters Consumption Updates'!$E:$E,'Cutters Consumption Updates'!$D:$D,H$1,'Cutters Consumption Updates'!$B:$B,$B12)+ SUMIF('Cutters Consumption Updates'!$AS:$AS,$B12,'Cutters Consumption Updates'!AT:AT) -> 0 | I12: =SUMIFS('Cutters Consumption Updates'!$F:$F,'Cutters Consumption Updates'!$D:$D,I$1,'Cutters Consumption Updates'!$B:$B,$B12)-SUMIFS('Cutters Consumption Updates'!$E:$E,'Cutters Consumption Updates'!$D:$D,I$1,'Cutters Consumption Updates'!$B:$B,$B12)+ SUMIF('Cutters Consumption Updates'!$AS:$AS,$B12,'Cutters Consumption Updates'!AU:AU) -> 0 | J12: =SUMIFS('Cutters Consumption Updates'!$F:$F,'Cutters Consumption Updates'!$D:$D,J$1,'Cutters Consumption Updates'!$B:$B,$B12)-SUMIFS('Cutters Consumption Updates'!$E:$E,'Cutters Consumption Updates'!$D:$D,J$1,'Cutters Consumption Updates'!$B:$B,$B12)+ SUMIF('Cutters Consumption Updates'!$AS:$AS,$B12,'Cutters Consumption Updates'!AV:AV) -> 0 | K12: =SUMIFS('Cutters Consumption Updates'!$F:$F,'Cutters Consumption Updates'!$D:$D,K$1,'Cutters Consumption Updates'!$B:$B,$B12)-SUMIFS('Cutters Consumption Updates'!$E:$E,'Cutters Consumption Updates'!$D:$D,K$1,'Cutters Consumption Updates'!$B:$B,$B12)+ SUMIF('Cutters Consumption Updates'!$AS:$AS,$B12,'Cutters Consumption Updates'!AW:AW) -> 1 | L12: =SUMIFS('Cutters Consumption Updates'!$F:$F,'Cutters Consumption Updates'!$D:$D,L$1,'Cutters Consumption Updates'!$B:$B,$B12)-SUMIFS('Cutters Consumption Updates'!$E:$E,'Cutters Consumption Updates'!$D:$D,$L$1,'Cutters Consumption Updates'!$B:$B,$B12)+SUMIFS('Cutters Consumption Updates'!$F:$F,'Cutters Consumption Updates'!$D:$D,"Retrofit",'Cutters Consumption Updates'!$B:$B,$B12)-SUMIFS('Cutters Consumption Updates'!$E:$E,'Cutters Consumption Updates'!$D:$D,"Retrofit",'Cutters Consumption Updates'!$B:$B,$B12)+ SUMIF('Cutters Consumption Updates'!$AS:$AS,$B12,'Cutters Consumption Updates'!AX:AX) -> 0 | M12: =L12+H12 -> 0 | N12: =SUMIFS('Cutters Consumption Updates'!E:E, 'Cutters Consumption Updates'!B:B, B12, 'Cutters Consumption Updates'!A:A, ">" & TODAY()-182) -> 0 | O12: =SUMIFS('Cutters Consumption Updates'!E:E, 'Cutters Consumption Updates'!B:B, B12, 'Cutters Consumption Updates'!A:A, ">" & TODAY()-91) -> 0 | P12: =IF(N12<>0,_xlfn.CEILING.MATH(N12/3),0) -> 0 | Q12: =IF(P12<=1, 0, CEILING( IF(P12>=300, P12+10, IF(P12>=200, P12+5, IF(P12>=100, P12+5, IF(P12>=50, P12+2, IF(P12>=20, P12+2, IF(P12>=10, P12+2, IF(P12>=5, P12+2, P12+1))))))), 5)) -> 0 | S12: =IFERROR(INDEX(Table5[],MATCH($B12,Table5[Component],0),2),0) -> 0 | T12: =SUMIFS(Table7[Balance],Table7[Cutter Mat'#],$B12) -> 0 | U12: =M12+T12-S12 -> 0 | Y12: =IFERROR(INDEX(Table5[],MATCH($B12,Table5[Component],0),2),0) -> 0 | Z12: =IFERROR(INDEX(Table5[],MATCH($B12,Table5[Component],0),1),0) -> 0 | AA12: =IF(Y12<>0,B12,"") | AB12: =IF(S12<>Y12,1,"") | AD12: =H12+I12+J12+L12 -> 0 | AI12: =IFERROR(INDEX($B$1:$AK$243,MATCH(W12,$B$1:$B$243,0),13),"") | AJ12: =IFERROR(INDEX($B$1:$AK$243,MATCH(W12,$B$1:$B$243,0),15),"") | AK12: =SUMIF($W$2:$W$243,B12,$S$2:$S$243) -> 0 | AP12: =T12 -> 0 | AR12: 409593 | AS12: =SUMIF($B:$B,AR12,$AP:$AP) -> 0
A13: 12 | B13: 471109 | C13: 1613 CT36 10C | D13: CT36 | E13: 1613 | F13: 10C | G13: S - Super Premium | H13: =SUMIFS('Cutters Consumption Updates'!$F:$F,'Cutters Consumption Updates'!$D:$D,H$1,'Cutters Consumption Updates'!$B:$B,$B13)-SUMIFS('Cutters Consumption Updates'!$E:$E,'Cutters Consumption Updates'!$D:$D,H$1,'Cutters Consumption Updates'!$B:$B,$B13)+ SUMIF('Cutters Consumption Updates'!$AS:$AS,$B13,'Cutters Consumption Updates'!AT:AT) -> 0 | I13: =SUMIFS('Cutters Consumption Updates'!$F:$F,'Cutters Consumption Updates'!$D:$D,I$1,'Cutters Consumption Updates'!$B:$B,$B13)-SUMIFS('Cutters Consumption Updates'!$E:$E,'Cutters Consumption Updates'!$D:$D,I$1,'Cutters Consumption Updates'!$B:$B,$B13)+ SUMIF('Cutters Consumption Updates'!$AS:$AS,$B13,'Cutters Consumption Updates'!AU:AU) -> 0 | J13: =SUMIFS('Cutters Consumption Updates'!$F:$F,'Cutters Consumption Updates'!$D:$D,J$1,'Cutters Consumption Updates'!$B:$B,$B13)-SUMIFS('Cutters Consumption Updates'!$E:$E,'Cutters Consumption Updates'!$D:$D,J$1,'Cutters Consumption Updates'!$B:$B,$B13)+ SUMIF('Cutters Consumption Updates'!$AS:$AS,$B13,'Cutters Consumption Updates'!AV:AV) -> 0 | K13: =SUMIFS('Cutters Consumption Updates'!$F:$F,'Cutters Consumption Updates'!$D:$D,K$1,'Cutters Consumption Updates'!$B:$B,$B13)-SUMIFS('Cutters Consumption Updates'!$E:$E,'Cutters Consumption Updates'!$D:$D,K$1,'Cutters Consumption Updates'!$B:$B,$B13)+ SUMIF('Cutters Consumption Updates'!$AS:$AS,$B13,'Cutters Consumption Updates'!AW:AW) -> 38 | L13: =SUMIFS('Cutters Consumption Updates'!$F:$F,'Cutters Consumption Updates'!$D:$D,L$1,'Cutters Consumption Updates'!$B:$B,$B13)-SUMIFS('Cutters Consumption Updates'!$E:$E,'Cutters Consumption Updates'!$D:$D,$L$1,'Cutters Consumption Updates'!$B:$B,$B13)+SUMIFS('Cutters Consumption Updates'!$F:$F,'Cutters Consumption Updates'!$D:$D,"Retrofit",'Cutters Consumption Updates'!$B:$B,$B13)-SUMIFS('Cutters Consumption Updates'!$E:$E,'Cutters Consumption Updates'!$D:$D,"Retrofit",'Cutters Consumption Updates'!$B:$B,$B13)+ SUMIF('Cutters Consumption Updates'!$AS:$AS,$B13,'Cutters Consumption Updates'!AX:AX) -> 1 | M13: =L13+H13 -> 1 | N13: =SUMIFS('Cutters Consumption Updates'!E:E, 'Cutters Consumption Updates'!B:B, B13, 'Cutters Consumption Updates'!A:A, ">" & TODAY()-182) -> 0 | O13: =SUMIFS('Cutters Consumption Updates'!E:E, 'Cutters Consumption Updates'!B:B, B13, 'Cutters Consumption Updates'!A:A, ">" & TODAY()-91) -> 0 | P13: =IF(N13<>0,_xlfn.CEILING.MATH(N13/3),0) -> 0 | Q13: =IF(P13<=1, 0, CEILING( IF(P13>=300, P13+10, IF(P13>=200, P13+5, IF(P13>=100, P13+5, IF(P13>=50, P13+2, IF(P13>=20, P13+2, IF(P13>=10, P13+2, IF(P13>=5, P13+2, P13+1))))))), 5)) -> 0 | S13: =IFERROR(INDEX(Table5[],MATCH($B13,Table5[Component],0),2),0) -> 0 | T13: =SUMIFS(Table7[Balance],Table7[Cutter Mat'#],$B13) -> 0 | U13: =M13+T13-S13 -> 1 | Y13: =IFERROR(INDEX(Table5[],MATCH($B13,Table5[Component],0),2),0) -> 0 | Z13: =IFERROR(INDEX(Table5[],MATCH($B13,Table5[Component],0),1),0) -> 0 | AA13: =IF(Y13<>0,B13,"") | AB13: =IF(S13<>Y13,1,"") | AD13: =H13+I13+J13+L13 -> 1 | AI13: =IFERROR(INDEX($B$1:$AK$243,MATCH(W13,$B$1:$B$243,0),13),"") | AJ13: =IFERROR(INDEX($B$1:$AK$243,MATCH(W13,$B$1:$B$243,0),15),"") | AK13: =SUMIF($W$2:$W$243,B13,$S$2:$S$243) -> 0 | AP13: =T13 -> 0 | AR13: 410851 | AS13: =SUMIF($B:$B,AR13,$AP:$AP) -> 0
A14: 13 | B14: 587493 | C14: 1908 CT62 18C | D14: CT62 | E14: 1908 | F14: 18C | G14: B - Standard ( Base ) | H14: =SUMIFS('Cutters Consumption Updates'!$F:$F,'Cutters Consumption Updates'!$D:$D,H$1,'Cutters Consumption Updates'!$B:$B,$B14)-SUMIFS('Cutters Consumption Updates'!$E:$E,'Cutters Consumption Updates'!$D:$D,H$1,'Cutters Consumption Updates'!$B:$B,$B14)+ SUMIF('Cutters Consumption Updates'!$AS:$AS,$B14,'Cutters Consumption Updates'!AT:AT) -> 0 | I14: =SUMIFS('Cutters Consumption Updates'!$F:$F,'Cutters Consumption Updates'!$D:$D,I$1,'Cutters Consumption Updates'!$B:$B,$B14)-SUMIFS('Cutters Consumption Updates'!$E:$E,'Cutters Consumption Updates'!$D:$D,I$1,'Cutters Consumption Updates'!$B:$B,$B14)+ SUMIF('Cutters Consumption Updates'!$AS:$AS,$B14,'Cutters Consumption Updates'!AU:AU) -> 0 | J14: =SUMIFS('Cutters Consumption Updates'!$F:$F,'Cutters Consumption Updates'!$D:$D,J$1,'Cutters Consumption Updates'!$B:$B,$B14)-SUMIFS('Cutters Consumption Updates'!$E:$E,'Cutters Consumption Updates'!$D:$D,J$1,'Cutters Consumption Updates'!$B:$B,$B14)+ SUMIF('Cutters Consumption Updates'!$AS:$AS,$B14,'Cutters Consumption Updates'!AV:AV) -> 0 | K14: =SUMIFS('Cutters Consumption Updates'!$F:$F,'Cutters Consumption Updates'!$D:$D,K$1,'Cutters Consumption Updates'!$B:$B,$B14)-SUMIFS('Cutters Consumption Updates'!$E:$E,'Cutters Consumption Updates'!$D:$D,K$1,'Cutters Consumption Updates'!$B:$B,$B14)+ SUMIF('Cutters Consumption Updates'!$AS:$AS,$B14,'Cutters Consumption Updates'!AW:AW) -> 0 | L14: =SUMIFS('Cutters Consumption Updates'!$F:$F,'Cutters Consumption Updates'!$D:$D,L$1,'Cutters Consumption Updates'!$B:$B,$B14)-SUMIFS('Cutters Consumption Updates'!$E:$E,'Cutters Consumption Updates'!$D:$D,$L$1,'Cutters Consumption Updates'!$B:$B,$B14)+SUMIFS('Cutters Consumption Updates'!$F:$F,'Cutters Consumption Updates'!$D:$D,"Retrofit",'Cutters Consumption Updates'!$B:$B,$B14)-SUMIFS('Cutters Consumption Updates'!$E:$E,'Cutters Consumption Updates'!$D:$D,"Retrofit",'Cutters Consumption Updates'!$B:$B,$B14)+ SUMIF('Cutters Consumption Updates'!$AS:$AS,$B14,'Cutters Consumption Updates'!AX:AX) -> 20 | M14: =L14+H14 -> 20 | N14: =SUMIFS('Cutters Consumption Updates'!E:E, 'Cutters Consumption Updates'!B:B, B14, 'Cutters Consumption Updates'!A:A, ">" & TODAY()-182) -> 0 | O14: =SUMIFS('Cutters Consumption Updates'!E:E, 'Cutters Consumption Updates'!B:B, B14, 'Cutters Consumption Updates'!A:A, ">" & TODAY()-91) -> 0 | P14: =IF(N14<>0,_xlfn.CEILING.MATH(N14/3),0) -> 0 | Q14: =IF(P14<=1, 0, CEILING( IF(P14>=300, P14+10, IF(P14>=200, P14+5, IF(P14>=100, P14+5, IF(P14>=50, P14+2, IF(P14>=20, P14+2, IF(P14>=10, P14+2, IF(P14>=5, P14+2, P14+1))))))), 5)) -> 0 | S14: =IFERROR(INDEX(Table5[],MATCH($B14,Table5[Component],0),2),0) -> 0 | T14: =SUMIFS(Table7[Balance],Table7[Cutter Mat'#],$B14) -> 0 | U14: =M14+T14-S14 -> 20 | Y14: =IFERROR(INDEX(Table5[],MATCH($B14,Table5[Component],0),2),0) -> 0 | Z14: =IFERROR(INDEX(Table5[],MATCH($B14,Table5[Component],0),1),0) -> 0 | AA14: =IF(Y14<>0,B14,"") | AB14: =IF(S14<>Y14,1,"") | AD14: =H14+I14+J14+L14 -> 20 | AI14: =IFERROR(INDEX($B$1:$AK$243,MATCH(W14,$B$1:$B$243,0),13),"") | AJ14: =IFERROR(INDEX($B$1:$AK$243,MATCH(W14,$B$1:$B$243,0),15),"") | AK14: =SUMIF($W$2:$W$243,B14,$S$2:$S$243) -> 0 | AP14: =T14 -> 0 | AR14: 418525 | AS14: =SUMIF($B:$B,AR14,$AP:$AP) -> 150
A15: 14 | B15: 565884 | C15: 1313 CT61 18C | D15: CT61 | E15: 1313 | F15: 18C | G15: B - Standard ( Base ) | H15: =SUMIFS('Cutters Consumption Updates'!$F:$F,'Cutters Consumption Updates'!$D:$D,H$1,'Cutters Consumption Updates'!$B:$B,$B15)-SUMIFS('Cutters Consumption Updates'!$E:$E,'Cutters Consumption Updates'!$D:$D,H$1,'Cutters Consumption Updates'!$B:$B,$B15)+ SUMIF('Cutters Consumption Updates'!$AS:$AS,$B15,'Cutters Consumption Updates'!AT:AT) -> 0 | I15: =SUMIFS('Cutters Consumption Updates'!$F:$F,'Cutters Consumption Updates'!$D:$D,I$1,'Cutters Consumption Updates'!$B:$B,$B15)-SUMIFS('Cutters Consumption Updates'!$E:$E,'Cutters Consumption Updates'!$D:$D,I$1,'Cutters Consumption Updates'!$B:$B,$B15)+ SUMIF('Cutters Consumption Updates'!$AS:$AS,$B15,'Cutters Consumption Updates'!AU:AU) -> 0 | J15: =SUMIFS('Cutters Consumption Updates'!$F:$F,'Cutters Consumption Updates'!$D:$D,J$1,'Cutters Consumption Updates'!$B:$B,$B15)-SUMIFS('Cutters Consumption Updates'!$E:$E,'Cutters Consumption Updates'!$D:$D,J$1,'Cutters Consumption Updates'!$B:$B,$B15)+ SUMIF('Cutters Consumption Updates'!$AS:$AS,$B15,'Cutters Consumption Updates'!AV:AV) -> 0 | K15: =SUMIFS('Cutters Consumption Updates'!$F:$F,'Cutters Consumption Updates'!$D:$D,K$1,'Cutters Consumption Updates'!$B:$B,$B15)-SUMIFS('Cutters Consumption Updates'!$E:$E,'Cutters Consumption Updates'!$D:$D,K$1,'Cutters Consumption Updates'!$B:$B,$B15)+ SUMIF('Cutters Consumption Updates'!$AS:$AS,$B15,'Cutters Consumption Updates'!AW:AW) -> 0 | L15: =SUMIFS('Cutters Consumption Updates'!$F:$F,'Cutters Consumption Updates'!$D:$D,L$1,'Cutters Consumption Updates'!$B:$B,$B15)-SUMIFS('Cutters Consumption Updates'!$E:$E,'Cutters Consumption Updates'!$D:$D,$L$1,'Cutters Consumption Updates'!$B:$B,$B15)+SUMIFS('Cutters Consumption Updates'!$F:$F,'Cutters Consumption Updates'!$D:$D,"Retrofit",'Cutters Consumption Updates'!$B:$B,$B15)-SUMIFS('Cutters Consumption Updates'!$E:$E,'Cutters Consumption Updates'!$D:$D,"Retrofit",'Cutters Consumption Updates'!$B:$B,$B15)+ SUMIF('Cutters Consumption Updates'!$AS:$AS,$B15,'Cutters Consumption Updates'!AX:AX) -> 0 | M15: =L15+H15 -> 0 | N15: =SUMIFS('Cutters Consumption Updates'!E:E, 'Cutters Consumption Updates'!B:B, B15, 'Cutters Consumption Updates'!A:A, ">" & TODAY()-182) -> 0 | O15: =SUMIFS('Cutters Consumption Updates'!E:E, 'Cutters Consumption Updates'!B:B, B15, 'Cutters Consumption Updates'!A:A, ">" & TODAY()-91) -> 0 | P15: =IF(N15<>0,_xlfn.CEILING.MATH(N15/3),0) -> 0 | Q15: =IF(P15<=1, 0, CEILING( IF(P15>=300, P15+10, IF(P15>=200, P15+5, IF(P15>=100, P15+5, IF(P15>=50, P15+2, IF(P15>=20, P15+2, IF(P15>=10, P15+2, IF(P15>=5, P15+2, P15+1))))))), 5)) -> 0 | S15: =IFERROR(INDEX(Table5[],MATCH($B15,Table5[Component],0),2),0) -> 0 | T15: =SUMIFS(Table7[Balance],Table7[Cutter Mat'#],$B15) -> 0 | U15: =M15+T15-S15 -> 0 | Y15: =IFERROR(INDEX(Table5[],MATCH($B15,Table5[Component],0),2),0) -> 0 | Z15: =IFERROR(INDEX(Table5[],MATCH($B15,Table5[Component],0),1),0) -> 0 | AA15: =IF(Y15<>0,B15,"") | AB15: =IF(S15<>Y15,1,"") | AD15: =H15+I15+J15+L15 -> 0 | AI15: =IFERROR(INDEX($B$1:$AK$243,MATCH(W15,$B$1:$B$243,0),13),"") | AJ15: =IFERROR(INDEX($B$1:$AK$243,MATCH(W15,$B$1:$B$243,0),15),"") | AK15: =SUMIF($W$2:$W$243,B15,$S$2:$S$243) -> 0 | AP15: =T15 -> 0 | AR15: 467367 | AS15: =SUMIF($B:$B,AR15,$AP:$AP) -> 0
A16: 15 | B16: 703670 | C16: 1313 CT200 10C | D16: CT200 | E16: 1313 | F16: 10C | G16: B - Standard ( Base ) | H16: =SUMIFS('Cutters Consumption Updates'!$F:$F,'Cutters Consumption Updates'!$D:$D,H$1,'Cutters Consumption Updates'!$B:$B,$B16)-SUMIFS('Cutters Consumption Updates'!$E:$E,'Cutters Consumption Updates'!$D:$D,H$1,'Cutters Consumption Updates'!$B:$B,$B16)+ SUMIF('Cutters Consumption Updates'!$AS:$AS,$B16,'Cutters Consumption Updates'!AT:AT) -> 0 | I16: =SUMIFS('Cutters Consumption Updates'!$F:$F,'Cutters Consumption Updates'!$D:$D,I$1,'Cutters Consumption Updates'!$B:$B,$B16)-SUMIFS('Cutters Consumption Updates'!$E:$E,'Cutters Consumption Updates'!$D:$D,I$1,'Cutters Consumption Updates'!$B:$B,$B16)+ SUMIF('Cutters Consumption Updates'!$AS:$AS,$B16,'Cutters Consumption Updates'!AU:AU) -> 0 | J16: =SUMIFS('Cutters Consumption Updates'!$F:$F,'Cutters Consumption Updates'!$D:$D,J$1,'Cutters Consumption Updates'!$B:$B,$B16)-SUMIFS('Cutters Consumption Updates'!$E:$E,'Cutters Consumption Updates'!$D:$D,J$1,'Cutters Consumption Updates'!$B:$B,$B16)+ SUMIF('Cutters Consumption Updates'!$AS:$AS,$B16,'Cutters Consumption Updates'!AV:AV) -> 0 | K16: =SUMIFS('Cutters Consumption Updates'!$F:$F,'Cutters Consumption Updates'!$D:$D,K$1,'Cutters Consumption Updates'!$B:$B,$B16)-SUMIFS('Cutters Consumption Updates'!$E:$E,'Cutters Consumption Updates'!$D:$D,K$1,'Cutters Consumption Updates'!$B:$B,$B16)+ SUMIF('Cutters Consumption Updates'!$AS:$AS,$B16,'Cutters Consumption Updates'!AW:AW) -> 29 | L16: =SUMIFS('Cutters Consumption Updates'!$F:$F,'Cutters Consumption Updates'!$D:$D,L$1,'Cutters Consumption Updates'!$B:$B,$B16)-SUMIFS('Cutters Consumption Updates'!$E:$E,'Cutters Consumption Updates'!$D:$D,$L$1,'Cutters Consumption Updates'!$B:$B,$B16)+SUMIFS('Cutters Consumption Updates'!$F:$F,'Cutters Consumption Updates'!$D:$D,"Retrofit",'Cutters Consumption Updates'!$B:$B,$B16)-SUMIFS('Cutters Consumption Updates'!$E:$E,'Cutters Consumption Updates'!$D:$D,"Retrofit",'Cutters Consumption Updates'!$B:$B,$B16)+ SUMIF('Cutters Consumption Updates'!$AS:$AS,$B16,'Cutters Consumption Updates'!AX:AX) -> 14 | M16: =L16+H16 -> 14 | N16: =SUMIFS('Cutters Consumption Updates'!E:E, 'Cutters Consumption Updates'!B:B, B16, 'Cutters Consumption Updates'!A:A, ">" & TODAY()-182) -> 49 | O16: =SUMIFS('Cutters Consumption Updates'!E:E, 'Cutters Consumption Updates'!B:B, B16, 'Cutters Consumption Updates'!A:A, ">" & TODAY()-91) -> 5 | P16: =IF(N16<>0,_xlfn.CEILING.MATH(N16/3),0) -> 17 | Q16: =IF(P16<=1, 0, CEILING( IF(P16>=300, P16+10, IF(P16>=200, P16+5, IF(P16>=100, P16+5, IF(P16>=50, P16+2, IF(P16>=20, P16+2, IF(P16>=10, P16+2, IF(P16>=5, P16+2, P16+1))))))), 5)) -> 20 | R16: 1313 V 18-60 | S16: =IFERROR(INDEX(Table5[],MATCH($B16,Table5[Component],0),2),0) -> 0 | T16: =SUMIFS(Table7[Balance],Table7[Cutter Mat'#],$B16) -> 0 | U16: =M16+T16-S16 -> 14 | Y16: =IFERROR(INDEX(Table5[],MATCH($B16,Table5[Component],0),2),0) -> 0 | Z16: =IFERROR(INDEX(Table5[],MATCH($B16,Table5[Component],0),1),0) -> 703670 | AA16: =IF(Y16<>0,B16,"") | AB16: =IF(S16<>Y16,1,"") | AD16: =H16+I16+J16+L16 -> 14 | AI16: =IFERROR(INDEX($B$1:$AK$243,MATCH(W16,$B$1:$B$243,0),13),"") | AJ16: =IFERROR(INDEX($B$1:$AK$243,MATCH(W16,$B$1:$B$243,0),15),"") | AK16: =SUMIF($W$2:$W$243,B16,$S$2:$S$243) -> 0 | AP16: =T16 -> 0 | AR16: 471108 | AS16: =SUMIF($B:$B,AR16,$AP:$AP) -> 0
A17: 16 | B17: 708305 | C17: 1913 CT200 10C | D17: CT200 | E17: 1913 | F17: 10C | G17: B - Standard ( Base ) | H17: =SUMIFS('Cutters Consumption Updates'!$F:$F,'Cutters Consumption Updates'!$D:$D,H$1,'Cutters Consumption Updates'!$B:$B,$B17)-SUMIFS('Cutters Consumption Updates'!$E:$E,'Cutters Consumption Updates'!$D:$D,H$1,'Cutters Consumption Updates'!$B:$B,$B17)+ SUMIF('Cutters Consumption Updates'!$AS:$AS,$B17,'Cutters Consumption Updates'!AT:AT) -> 0 | I17: =SUMIFS('Cutters Consumption Updates'!$F:$F,'Cutters Consumption Updates'!$D:$D,I$1,'Cutters Consumption Updates'!$B:$B,$B17)-SUMIFS('Cutters Consumption Updates'!$E:$E,'Cutters Consumption Updates'!$D:$D,I$1,'Cutters Consumption Updates'!$B:$B,$B17)+ SUMIF('Cutters Consumption Updates'!$AS:$AS,$B17,'Cutters Consumption Updates'!AU:AU) -> 0 | J17: =SUMIFS('Cutters Consumption Updates'!$F:$F,'Cutters Consumption Updates'!$D:$D,J$1,'Cutters Consumption Updates'!$B:$B,$B17)-SUMIFS('Cutters Consumption Updates'!$E:$E,'Cutters Consumption Updates'!$D:$D,J$1,'Cutters Consumption Updates'!$B:$B,$B17)+ SUMIF('Cutters Consumption Updates'!$AS:$AS,$B17,'Cutters Consumption Updates'!AV:AV) -> 0 | K17: =SUMIFS('Cutters Consumption Updates'!$F:$F,'Cutters Consumption Updates'!$D:$D,K$1,'Cutters Consumption Updates'!$B:$B,$B17)-SUMIFS('Cutters Consumption Updates'!$E:$E,'Cutters Consumption Updates'!$D:$D,K$1,'Cutters Consumption Updates'!$B:$B,$B17)+ SUMIF('Cutters Consumption Updates'!$AS:$AS,$B17,'Cutters Consumption Updates'!AW:AW) -> 0 | L17: =SUMIFS('Cutters Consumption Updates'!$F:$F,'Cutters Consumption Updates'!$D:$D,L$1,'Cutters Consumption Updates'!$B:$B,$B17)-SUMIFS('Cutters Consumption Updates'!$E:$E,'Cutters Consumption Updates'!$D:$D,$L$1,'Cutters Consumption Updates'!$B:$B,$B17)+SUMIFS('Cutters Consumption Updates'!$F:$F,'Cutters Consumption Updates'!$D:$D,"Retrofit",'Cutters Consumption Updates'!$B:$B,$B17)-SUMIFS('Cutters Consumption Updates'!$E:$E,'Cutters Consumption Updates'!$D:$D,"Retrofit",'Cutters Consumption Updates'!$B:$B,$B17)+ SUMIF('Cutters Consumption Updates'!$AS:$AS,$B17,'Cutters Consumption Updates'!AX:AX) -> 2 | M17: =L17+H17 -> 2 | N17: =SUMIFS('Cutters Consumption Updates'!E:E, 'Cutters Consumption Updates'!B:B, B17, 'Cutters Consumption Updates'!A:A, ">" & TODAY()-182) -> 0 | O17: =SUMIFS('Cutters Consumption Updates'!E:E, 'Cutters Consumption Updates'!B:B, B17, 'Cutters Consumption Updates'!A:A, ">" & TODAY()-91) -> 0 | P17: =IF(N17<>0,_xlfn.CEILING.MATH(N17/3),0) -> 0 | Q17: =IF(P17<=1, 0, CEILING( IF(P17>=300, P17+10, IF(P17>=200, P17+5, IF(P17>=100, P17+5, IF(P17>=50, P17+2, IF(P17>=20, P17+2, IF(P17>=10, P17+2, IF(P17>=5, P17+2, P17+1))))))), 5)) -> 0 | S17: =IFERROR(INDEX(Table5[],MATCH($B17,Table5[Component],0),2),0) -> 0 | T17: =SUMIFS(Table7[Balance],Table7[Cutter Mat'#],$B17) -> 0 | U17: =M17+T17-S17 -> 2 | Y17: =IFERROR(INDEX(Table5[],MATCH($B17,Table5[Component],0),2),0) -> 0 | Z17: =IFERROR(INDEX(Table5[],MATCH($B17,Table5[Component],0),1),0) -> 0 | AA17: =IF(Y17<>0,B17,"") | AB17: =IF(S17<>Y17,1,"") | AD17: =H17+I17+J17+L17 -> 2 | AI17: =IFERROR(INDEX($B$1:$AK$243,MATCH(W17,$B$1:$B$243,0),13),"") | AJ17: =IFERROR(INDEX($B$1:$AK$243,MATCH(W17,$B$1:$B$243,0),15),"") | AK17: =SUMIF($W$2:$W$243,B17,$S$2:$S$243) -> 0 | AP17: =T17 -> 0 | AR17: 471109 | AS17: =SUMIF($B:$B,AR17,$AP:$AP) -> 0
A18: 17 | B18: 717749 | C18: 1308 CT200 10C | D18: CT200 | E18: 1308 | F18: 10C | G18: B - Standard ( Base ) | H18: =SUMIFS('Cutters Consumption Updates'!$F:$F,'Cutters Consumption Updates'!$D:$D,H$1,'Cutters Consumption Updates'!$B:$B,$B18)-SUMIFS('Cutters Consumption Updates'!$E:$E,'Cutters Consumption Updates'!$D:$D,H$1,'Cutters Consumption Updates'!$B:$B,$B18)+ SUMIF('Cutters Consumption Updates'!$AS:$AS,$B18,'Cutters Consumption Updates'!AT:AT) -> 0 | I18: =SUMIFS('Cutters Consumption Updates'!$F:$F,'Cutters Consumption Updates'!$D:$D,I$1,'Cutters Consumption Updates'!$B:$B,$B18)-SUMIFS('Cutters Consumption Updates'!$E:$E,'Cutters Consumption Updates'!$D:$D,I$1,'Cutters Consumption Updates'!$B:$B,$B18)+ SUMIF('Cutters Consumption Updates'!$AS:$AS,$B18,'Cutters Consumption Updates'!AU:AU) -> 0 | J18: =SUMIFS('Cutters Consumption Updates'!$F:$F,'Cutters Consumption Updates'!$D:$D,J$1,'Cutters Consumption Updates'!$B:$B,$B18)-SUMIFS('Cutters Consumption Updates'!$E:$E,'Cutters Consumption Updates'!$D:$D,J$1,'Cutters Consumption Updates'!$B:$B,$B18)+ SUMIF('Cutters Consumption Updates'!$AS:$AS,$B18,'Cutters Consumption Updates'!AV:AV) -> 0 | K18: =SUMIFS('Cutters Consumption Updates'!$F:$F,'Cutters Consumption Updates'!$D:$D,K$1,'Cutters Consumption Updates'!$B:$B,$B18)-SUMIFS('Cutters Consumption Updates'!$E:$E,'Cutters Consumption Updates'!$D:$D,K$1,'Cutters Consumption Updates'!$B:$B,$B18)+ SUMIF('Cutters Consumption Updates'!$AS:$AS,$B18,'Cutters Consumption Updates'!AW:AW) -> 0 | L18: =SUMIFS('Cutters Consumption Updates'!$F:$F,'Cutters Consumption Updates'!$D:$D,L$1,'Cutters Consumption Updates'!$B:$B,$B18)-SUMIFS('Cutters Consumption Updates'!$E:$E,'Cutters Consumption Updates'!$D:$D,$L$1,'Cutters Consumption Updates'!$B:$B,$B18)+SUMIFS('Cutters Consumption Updates'!$F:$F,'Cutters Consumption Updates'!$D:$D,"Retrofit",'Cutters Consumption Updates'!$B:$B,$B18)-SUMIFS('Cutters Consumption Updates'!$E:$E,'Cutters Consumption Updates'!$D:$D,"Retrofit",'Cutters Consumption Updates'!$B:$B,$B18)+ SUMIF('Cutters Consumption Updates'!$AS:$AS,$B18,'Cutters Consumption Updates'!AX:AX) -> 0 | M18: =L18+H18 -> 0 | N18: =SUMIFS('Cutters Consumption Updates'!E:E, 'Cutters Consumption Updates'!B:B, B18, 'Cutters Consumption Updates'!A:A, ">" & TODAY()-182) -> 0 | O18: =SUMIFS('Cutters Consumption Updates'!E:E, 'Cutters Consumption Updates'!B:B, B18, 'Cutters Consumption Updates'!A:A, ">" & TODAY()-91) -> 0 | P18: =IF(N18<>0,_xlfn.CEILING.MATH(N18/3),0) -> 0 | Q18: =IF(P18<=1, 0, CEILING( IF(P18>=300, P18+10, IF(P18>=200, P18+5, IF(P18>=100, P18+5, IF(P18>=50, P18+2, IF(P18>=20, P18+2, IF(P18>=10, P18+2, IF(P18>=5, P18+2, P18+1))))))), 5)) -> 0 | S18: =IFERROR(INDEX(Table5[],MATCH($B18,Table5[Component],0),2),0) -> 0 | T18: =SUMIFS(Table7[Balance],Table7[Cutter Mat'#],$B18) -> 0 | U18: =M18+T18-S18 -> 0 | Y18: =IFERROR(INDEX(Table5[],MATCH($B18,Table5[Component],0),2),0) -> 0 | Z18: =IFERROR(INDEX(Table5[],MATCH($B18,Table5[Component],0),1),0) -> 0 | AA18: =IF(Y18<>0,B18,"") | AB18: =IF(S18<>Y18,1,"") | AD18: =H18+I18+J18+L18 -> 0 | AI18: =IFERROR(INDEX($B$1:$AK$243,MATCH(W18,$B$1:$B$243,0),13),"") | AJ18: =IFERROR(INDEX($B$1:$AK$243,MATCH(W18,$B$1:$B$243,0),15),"") | AK18: =SUMIF($W$2:$W$243,B18,$S$2:$S$243) -> 0 | AP18: =T18 -> 0 | AR18: 535656 | AS18: =SUMIF($B:$B,AR18,$AP:$AP) -> 0
